Workbook
Name Xперемен: #REF!
Name Yперемен: #REF!

Sheet Базовый сценарий >>

Sheet ОПУ БС
B2: Отчёт о прибылях и убытках за год, тыс. руб. | K2: Сезонность >>
C3: 2025 | D3: 2026 | E3: 2027 | F3: 2028 | G3: 2029 | H3: 2030 | I3: 2031 | L3: Янв | M3: Фев | N3: Мар | O3: Апр | P3: Май | Q3: Июн | R3: Июл | S3: Авг | T3: Сен | U3: Окт | V3: Ноя | W3: Дек
B4: Выручка от реализации | C4: =C5+C33+C35+C37+C39 -> 848093.51 | D4: =D5+D33+D35+D37+D39 -> 1029160.5 | E4: =E5+E33+E35+E37+E39 -> 1337307.8 | F4: =F5+F33+F35+F37+F39 -> 1750307.9 | G4: =G5+G33+G35+G37+G39 -> 2314273.9 | H4: =H5+H33+H35+H37+H39 -> 3061607.5 | I4: =I5+I33+I35+I37+I39 -> 4051713.8
B5: Готовая продукция | C5: =C6+C19+C32 -> 825093.51 | D5: =D6+D19+D32 -> 1005125.5 | E5: =E6+E19+E32 -> 1312311.4 | F5: =F6+F19+F32 -> 1724311.7 | G5: =G6+G19+G32 -> 2287237.8 | H5: =H6+H19+H32 -> 3033490 | I5: =I6+I19+I32 -> 4022471.5
B6: МАГАЗИНЫ | C6: =C7+C11 -> 536737.92 | D6: =D7+D11 -> 617702.66 | E6: =E7+E11 -> 762435.39 | F6: =F7+F11 -> 975440.83 | G6: =G7+G11 -> 1296452.5 | H6: =H7+H11 -> 1766359.9 | I6: =I7+I11 -> 2432435.5
B7: Сухари | C7: =SUM(C8:C10) -> 431286.58 | D7: =SUM(D8:D10) -> 499957.61 | E7: =SUM(E8:E10) -> 620323.12 | F7: =SUM(F8:F10) -> 803774.19 | G7: =SUM(G8:G10) -> 1080616.8 | H7: =SUM(H8:H10) -> 1488114.3 | I7: =SUM(I8:I10) -> 2067087.6
B8: Классика | C8: 213143.11 | D8: 250999.85 | E8: 315949.42 | F8: 415333.41 | G8: 566503.83 | H8: 791484.92 | I8: 1115405.8 | L8: 0.76 | M8: 0.83 | N8: 0.93 | O8: 0.93 | P8: 0.95 | Q8: 1.01 | R8: 1.16 | S8: 1.13 | T8: 1.05 | U8: 0.99 | V8: 1.01 | W8: 1.25
B9: Острые | C9: 168540.3 | D9: 192462.27 | E9: 235433.99 | F9: 300569.75 | G9: 397904.99 | H9: 539255.08 | I9: 736757.15 | L9: 0.76 | M9: 0.86 | N9: 0.93 | O9: 0.93 | P9: 0.95 | Q9: 1.01 | R9: 1.16 | S9: 1.13 | T9: 1.05 | U9: 0.99 | V9: 0.98 | W9: 1.25
B10: ЭкстраХруст | C10: 49603.174 | D10: 56495.492 | E10: 68939.71 | F10: 87871.026 | G10: 116207.94 | H10: 157374.34 | I10: 214924.63 | L10: 0.76 | M10: 0.83 | N10: 0.95 | O10: 0.93 | P10: 0.95 | Q10: 1.01 | R10: 1.16 | S10: 1.13 | T10: 1.05 | U10: 0.99 | V10: 0.99 | W10: 1.25
B11: Соусы | C11: =SUM(C12:C18) -> 105451.34 | D11: =SUM(D12:D18) -> 117745.05 | E11: =SUM(E12:E18) -> 142112.27 | F11: =SUM(F12:F18) -> 171666.64 | G11: =SUM(G12:G18) -> 215835.71 | H11: =SUM(H12:H18) -> 278245.53 | I11: =SUM(I12:I18) -> 365347.95
B12: Кетчуп | C12: 35955.672 | D12: 41326.004 | E12: 49287.659 | F12: 61118.917 | G12: 78530.264 | H12: 103233.34 | I12: 136925.63 | L12: 0.76 | M12: 0.83 | N12: 0.93 | O12: 0.93 | P12: 0.84 | Q12: 1.01 | R12: 1.16 | S12: 1.13 | T12: 1.05 | U12: 0.99 | V12: 1.12 | W12: 1.25
B13: Горчица | C13: 18859.743 | D13: 21872.28 | E13: 27513.339 | F13: 36222.164 | G13: 49499.643 | H13: 69502.33 | I13: 97827.769 | L13: 0.76 | M13: 0.83 | N13: 0.93 | O13: 0.93 | P13: 0.95 | Q13: 0.73 | R13: 1.16 | S13: 1.13 | T13: 1.05 | U13: 0.99 | V13: 1.29 | W13: 1.25
B14: Сырный | C14: 30906.192 | D14: 32789.261 | E14: 40128.51 | F14: 43846 | G14: 49428.26 | H14: 56041.056 | I14: 65864.64 | L14: 0.76 | M14: 0.83 | N14: 0.93 | O14: 0.93 | P14: 0.95 | Q14: 1.01 | R14: 1.18 | S14: 1.13 | T14: 1.05 | U14: 0.99 | V14: 0.99 | W14: 1.25
B15: Кисло-сладкий | C15: 8274.8802 | D15: 9202.7589 | E15: 10683.105 | F15: 12944.522 | G15: 16292.428 | H15: 20974.209 | I15: 27382.164 | L15: 0.76 | M15: 0.83 | N15: 0.93 | O15: 0.93 | P15: 0.95 | Q15: 1.01 | R15: 1.16 | S15: 0.89 | T15: 1.05 | U15: 0.99 | V15: 1.25 | W15: 1.25
B16: Чесночный | C16: 5067.1018 | D16: 5587.2302 | E16: 6541.1412 | F16: 8025.1043 | G16: 10250.603 | H16: 13409.065 | I16: 17788.246 | L16: 0.76 | M16: 0.83 | N16: 0.93 | O16: 0.93 | P16: 0.95 | Q16: 1.01 | R16: 1.16 | S16: 1.13 | T16: 0.91 | U16: 0.99 | V16: 1.15 | W16: 1.25
B17: Коктейльный | C17: 5737.9697 | D17: 6298.1548 | E17: 7274.0341 | F17: 8790.4503 | G17: 11053.702 | H17: 14233.764 | I17: 18594.078 | L17: 0.76 | M17: 0.83 | N17: 0.93 | O17: 0.93 | P17: 0.95 | Q17: 1.01 | R17: 1.16 | S17: 1.13 | T17: 1.05 | U17: 0.95 | V17: 1.05 | W17: 1.25
B18: Медовая горчица | C18: 649.78131 | D18: 669.3575 | E18: 684.47688 | F18: 719.47949 | G18: 780.80758 | H18: 851.76668 | I18: 965.42644 | L18: 0.76 | M18: 0.83 | N18: 0.93 | O18: 0.93 | P18: 0.95 | Q18: 1.01 | R18: 1.16 | S18: 1.13 | T18: 1.05 | U18: 0.99 | V18: 1.01 | W18: 1.25
B19: РЕСТОРАНЫ | C19: =C20+C24 -> 288355.59 | D19: =D20+D24 -> 387422.86 | E19: =E20+E24 -> 549875.99 | F19: =F20+F24 -> 748870.82 | G19: =G20+G24 -> 990785.34 | H19: =H20+H24 -> 1267130.1 | I19: =I20+I24 -> 1590036
B20: Сухари | C20: =SUM(C21:C23) -> 242066.69 | D20: =SUM(D21:D23) -> 333984.13 | E20: =SUM(E21:E23) -> 478821.7 | F20: =SUM(F21:F23) -> 657923.12 | G20: =SUM(G21:G23) -> 875729.66 | H20: =SUM(H21:H23) -> 1125376.7 | I20: =SUM(I21:I23) -> 1416140.9
B21: Классика | C21: 114234.52 | D21: 158773.58 | E21: 234946.57 | F21: 331811.84 | G21: 452080.13 | H21: 592906.56 | I21: 760015.7 | L21: 0.76 | M21: 0.83 | N21: 0.93 | O21: 0.93 | P21: 0.95 | Q21: 1.01 | R21: 1.16 | S21: 1.13 | T21: 1.05 | U21: 0.99 | V21: 1.01 | W21: 1.25
B22: Острые | C22: 99489.426 | D22: 131998.03 | E22: 177753.59 | F22: 230708.41 | G22: 292182.89 | H22: 359006.98 | I22: 436038.83 | L22: 0.76 | M22: 0.83 | N22: 0.93 | O22: 0.93 | P22: 0.95 | Q22: 1.01 | R22: 1.16 | S22: 1.13 | T22: 1.05 | U22: 0.89 | V22: 1.11 | W22: 1.25
B23: ЭкстраХруст | C23: 28342.744 | D23: 43212.523 | E23: 66121.546 | F23: 95402.872 | G23: 131466.64 | H23: 173463.17 | I23: 220086.39 | L23: 0.76 | M23: 0.83 | N23: 0.93 | O23: 0.93 | P23: 0.95 | Q23: 1.01 | R23: 1.16 | S23: 1.13 | T23: 0.67 | U23: 0.99 | V23: 1.39 | W23: 1.25
B24: Соусы | C24: =SUM(C25:C31) -> 46288.904 | D24: =SUM(D25:D31) -> 53438.728 | E24: =SUM(E25:E31) -> 71054.291 | F24: =SUM(F25:F31) -> 90947.706 | G24: =SUM(G25:G31) -> 115055.68 | H24: =SUM(H25:H31) -> 141753.4 | I24: =SUM(I25:I31) -> 173895.11
B25: Кетчуп | C25: 19270.215 | D25: 23470.152 | E25: 32272.751 | F25: 42908.759 | G25: 55478.312 | H25: 69218.867 | I25: 85290.054 | L25: 0.57 | M25: 0.83 | N25: 0.93 | O25: 0.93 | P25: 0.95 | Q25: 1.01 | R25: 0.91 | S25: 1.13 | T25: 1.05 | U25: 0.99 | V25: 1.45 | W25: 1.25
B26: Горчица | C26: 8095.0354 | D26: 6947.5664 | E26: 8218.9423 | F26: 9815.9527 | G26: 11730.837 | H26: 13764.371 | I26: 16315.872 | L26: 0.76 | M26: 0.87 | N26: 0.93 | O26: 0.93 | P26: 0.95 | Q26: 1.01 | R26: 1.16 | S26: 1.13 | T26: 1.05 | U26: 0.99 | V26: 0.97 | W26: 1.25
B27: Сырный | C27: 9427.5003 | D27: 10001.904 | E27: 12240.639 | F27: 13374.607 | G27: 15077.397 | H27: 17094.538 | I27: 20091.085 | L27: 0.76 | M27: 0.83 | N27: 0.95 | O27: 0.93 | P27: 0.95 | Q27: 1.01 | R27: 1.16 | S27: 1.13 | T27: 1.05 | U27: 0.99 | V27: 0.99 | W27: 1.25
B28: Кисло-сладкий | C28: 3812.1718 | D28: 4359.0779 | E28: 5344.2174 | F28: 6434.4769 | G28: 7691.2539 | H28: 8984.0904 | I28: 10620.319 | L28: 0.76 | M28: 0.83 | N28: 0.93 | O28: 0.89 | P28: 0.95 | Q28: 1.01 | R28: 1.16 | S28: 1.13 | T28: 1.05 | U28: 0.99 | V28: 1.05 | W28: 1.25
B29: Чесночный | C29: 2309.7683 | D29: 3950.4806 | E29: 6427.7061 | F29: 9648.4778 | G29: 13682.324 | H29: 18409.146 | I29: 23915.533 | L29: 0.76 | M29: 0.83 | N29: 0.93 | O29: 0.93 | P29: 0.93 | Q29: 1.01 | R29: 1.16 | S29: 1.13 | T29: 1.05 | U29: 0.99 | V29: 1.03 | W29: 1.25
B30: Коктейльный | C30: 2412.4702 | D30: 3531.5393 | E30: 5147.0245 | F30: 7108.3836 | G30: 9437.6904 | H30: 12007.925 | I30: 14980.663 | L30: 0.76 | M30: 0.83 | N30: 0.93 | O30: 0.93 | P30: 0.95 | Q30: 1 | R30: 1.16 | S30: 1.13 | T30: 1.05 | U30: 0.99 | V30: 1.02 | W30: 1.25
B31: Медовая горчица | C31: 961.74303 | D31: 1178.0075 | E31: 1403.0099 | F31: 1657.0483 | G31: 1957.8691 | H31: 2274.4645 | I31: 2681.5827 | L31: 0.76 | M31: 0.83 | N31: 0.93 | O31: 0.93 | P31: 0.95 | Q31: 1.01 | R31: 1.01 | S31: 1.13 | T31: 1.05 | U31: 0.99 | V31: 1.16 | W31: 1.25
B32: ВНЕ НАПРАВЛЕНИЙ | C32: 0 | D32: 0 | E32: 0 | F32: 0 | G32: 0 | H32: 0 | I32: 0 | L32: 0.76 | M32: 0.83 | N32: 0.93 | O32: 0.93 | P32: 0.95 | Q32: 1.01 | R32: 1.16 | S32: 1.18 | T32: 1.05 | U32: 0.99 | V32: 0.96 | W32: 1.25
B33: Товары для перепродажи | C33: =C34 -> 2400 | D33: =D34 -> 2508 | E33: =E34 -> 2608.32 | F33: =F34 -> 2712.6528 | G33: =G34 -> 2821.1589 | H33: =H34 -> 2934.0053 | I33: =I34 -> 3051.3655
B34: ВНЕ НАПРАВЛЕНИЙ | C34: 2400 | D34: 2508 | E34: 2608.32 | F34: 2712.6528 | G34: 2821.1589 | H34: 2934.0053 | I34: 3051.3655 | L34: 0.76 | M34: 0.83 | N34: 0.93 | O34: 0.93 | P34: 0.95 | Q34: 1.01 | R34: 1.16 | S34: 1.13 | T34: 1.05 | U34: 0.99 | V34: 1.01 | W34: 1.25
B35: Услуги | C35: =C36 -> 8000 | D35: =D36 -> 8360 | E35: =E36 -> 8694.4 | F35: =F36 -> 9042.176 | G35: =G36 -> 9403.863 | H35: =H36 -> 9780.0176 | I35: =I36 -> 10171.218
B36: ВНЕ НАПРАВЛЕНИЙ | C36: 8000 | D36: 8360 | E36: 8694.4 | F36: 9042.176 | G36: 9403.863 | H36: 9780.0176 | I36: 10171.218 | L36: 0.76 | M36: 0.83 | N36: 0.93 | O36: 0.93 | P36: 0.95 | Q36: 1.01 | R36: 1.16 | S36: 1.13 | T36: 1.05 | U36: 0.99 | V36: 1.01 | W36: 1.25
B37: Субаренда | C37: =C38 -> 5600 | D37: =D38 -> 5852 | E37: =E38 -> 6086.08 | F37: =F38 -> 6329.5232 | G37: =G38 -> 6582.7041 | H37: =H38 -> 6846.0123 | I37: =I38 -> 7119.8528
B38: ВНЕ НАПРАВЛЕНИЙ | C38: 5600 | D38: 5852 | E38: 6086.08 | F38: 6329.5232 | G38: 6582.7041 | H38: 6846.0123 | I38: 7119.8528 | L38: 0.76 | M38: 0.83 | N38: 0.93 | O38: 0.93 | P38: 0.95 | Q38: 1.01 | R38: 1.16 | S38: 1.13 | T38: 1.05 | U38: 0.99 | V38: 1.01 | W38: 1.25
B39: Прочая реализация | C39: =C40 -> 7000 | D39: =D40 -> 7315 | E39: =E40 -> 7607.6 | F39: =F40 -> 7911.904 | G39: =G40 -> 8228.3802 | H39: =H40 -> 8557.5154 | I39: =I40 -> 8899.816
B40: ВНЕ НАПРАВЛЕНИЙ | C40: 7000 | D40: 7315 | E40: 7607.6 | F40: 7911.904 | G40: 8228.3802 | H40: 8557.5154 | I40: 8899.816 | L40: 0.76 | M40: 0.83 | N40: 0.93 | O40: 0.93 | P40: 0.95 | Q40: 1.01 | R40: 1.16 | S40: 1.13 | T40: 1.05 | U40: 0.99 | V40: 1.01 | W40: 1.25
B41: Себестоимость реализации: | C41: =C42+C70+C72+C74+C76 -> 597965.46 | D41: =D42+D70+D72+D74+D76 -> 724905.86 | E41: =E42+E70+E72+E74+E76 -> 940788.69 | F41: =F42+F70+F72+F74+F76 -> 1195589.5 | G41: =G42+G70+G72+G74+G76 -> 1487812.1 | H41: =H42+H70+H72+H74+H76 -> 1845033 | I41: =I42+I70+I72+I74+I76 -> 2198071.2
...

Sheet Негативный сценарий >>

Sheet Вводные
B2: Рисковые события:
L3: Да
B4: 1 | C4: В июне 2027 года планируется смена поставщика растительного масла «Юг-17», которое используется для производства соусов всей линейки «Микси», с ростом закупочных цен: – доля расходов на растительное масло в себестоимости производства соусов составляет 8%; – в июне 2027 года есть риск смены поставщика с ростом цен на данный компонент в размере 11%, и далее с увеличением цен ещё на 3% с начала каждого следующего года от текущих расходов на себестоимость; – доля расходов на растительное масло в себестоимости производства соусов у данного поставщика начнёт сокращаться на 2 процентных пункта каждый год, начиная с 2029 года.
L5: Да
B6: 2 | C6: К 2028 году существует риск сдвигов сроков получения оплат от контрагента — магазина «ПроВкусно», которому «Микси» поставляет часть сухарей: – данному контрагенту поставляют сухари линейки «Классика» и «ЭкстраХруст»; – доля продаж «ПроВкусно» в общей доле реализации по начислениям (вы можете использовать данные из ОПУ для выполнения своих расчётов) сухарей составляет 60% в линейне «Классика» и 75% в линейке «ЭкстраХруст»; – резерв под сомнительную дебиторскую задолженность начисляется в следующем порядке: просрочка оплат от 0 до 15 дней в размере 5% от суммы неполученного платежа, 16–30 дней в размере 15%, 31–60 дней в размере 30%, свыше 60 дней в размере 60%; – резерв начисляется вне направлений в прочие внереализационные расходы; – график сдигов платежей для начисления резерва под плохую дебиторскую задолженность следующий: в 2028 году в среднем «ПроВкусно» просрочит все платежи на 13 дней, начиная с сентября; в 2029 году весь год просрочки составят в среднем 27 дней; с 2030 года и далее просрочки составят 31 день.
L7: Да
B8: 3 | C8: Существует риск, что, начиная с 2028 года, прогнозный показатель инфляции на телевизионные маркетинговые расходы будет хуже на 4 процентных пункта: – базовый темп инфляции, который применён в исходной модели, составляет 3,5% для всех периодов; – телевизионная реклама откручивается только для линейки сухарей, поставляемых в магазины.
B9: 4 | C9: При расчете налога на прибыль важно помнить, что компания уплачивает его без привязки к направлениям бизнеса, поэтому убыток, образовавшийся по одному из направлений бизнеса уменьшает общую налогооблагаемую базу по всей компании.

Sheet Последовательность расчётов
B2: Последовательность расчётов
B3: [1] | C3: На вкладке «1. ОПУ НС» рассчитайте данные по месяцам, исходя из вводных по сезонности, которые даны на вкладке ОПУ БС в колонках L–W.
B4: [2] | C4: Проверьте, что ячейки Check в колонках CR–CX стали зелёными. Если ваши расчёты верны, можно двигаться дальше.
B5: [3] | C5: Внесите данные в колонки corrections по всем рисковым событиям.
B6: [4] | C6: Произведите необходимые расчёты в колонках negative scenario.
B7: [5] | C7: Проверьте, что ячейки Check в колонках JE–JK стали зелёными. Если ваши расчёты верны, можно двигаться дальше.
B8: [6] | C8: На вкладке «2. Факторы и выводы» внесите данные по накопленному итогу EBITDA за 2027–2031 гг., рассчитайте отклонение по статьям в абсолютах и в процентах.
B9: [7] | C9: Сверьте, что ваши данные сходятся с вкладкой «1.ОПУ НС».
B10: [8] | C10: Рассчитайте факторы рисков на накопленный показатель EBITDA за 2027–2031 гг.: в абсолютах вам необходимо выйти на разницу между базовым и негативным сценариями, в процентах — рассчитать вклад каждого фактора в общее изменение по абсолюту.
B11: [9] | C11: Рассчитайте факторы рисков на накопленный показатель EBITDA margin: в абсолютах вам необходимо выйти на разницу между базовым и негативным сценариями, в процентах — рассчитать вклад каждого фактора в общее изменение по показателю EBITDA margin.
B12: [10] | C12: Постройте «водопадные» (каскадные) графики напротив каждого факторного анализа: для обоих факторников постройте «водопады» по абсолютным отклонения, а для второго факторника также постройте «водопад» по отклонению показателя EBITDA margin.

Sheet 1. ОПУ НС
B2: Отчёт о прибылях и убытках за год, тыс. руб.
C3: Янв'25 | D3: Фев'25 | E3: Мар'25 | F3: Апр'25 | G3: Май'25 | H3: Июн'25 | I3: Июл'25 | J3: Авг'25 | K3: Сен'25 | L3: Окт'25 | M3: Ноя'25 | N3: Дек'25 | O3: 2025 | P3: Янв'26 | Q3: Фев'26 | R3: Мар'26 | S3: Апр'26 | T3: Май'26 | U3: Июн'26 | V3: Июл'26 | W3: Авг'26 | X3: Сен'26 | Y3: Окт'26 | Z3: Ноя'26 | AA3: Дек'26 | AB3: 2026 | AC3: Янв'27 | AD3: Фев'27 | AE3: Мар'27 | AF3: Апр'27 | AG3: Май'27 | AH3: Июн'27 | AI3: Июл'27 | AJ3: Авг'27 | AK3: Сен'27 | AL3: Окт'27 | AM3: Ноя'27 | AN3: Дек'27 | AO3: 2027 | AP3: Янв'28 | AQ3: Фев'28 | AR3: Мар'28 | AS3: Апр'28 | AT3: Май'28 | AU3: Июн'28 | AV3: Июл'28 | AW3: Авг'28 | AX3: Сен'28 | AY3: Окт'28 | AZ3: Ноя'28 | BA3: Дек'28 | BB3: 2028 | BC3: Янв'29 | BD3: Фев'29 | BE3: Мар'29 | BF3: Апр'29 | BG3: Май'29 | BH3: Июн'29 | BI3: Июл'29 | BJ3: Авг'29 | BK3: Сен'29 | BL3: Окт'29 | BM3: Ноя'29 | BN3: Дек'29 | BO3: 2029 | BP3: Янв'30 | BQ3: Фев'30 | BR3: Мар'30 | BS3: Апр'30 | BT3: Май'30 | BU3: Июн'30 | BV3: Июл'30 | BW3: Авг'30 | BX3: Сен'30 | BY3: Окт'30 | BZ3: Ноя'30 | CA3: Дек'30 | CB3: 2030 | CC3: Янв'31 | CD3: Фев'31 | CE3: Мар'31 | CF3: Апр'31 | CG3: Май'31 | CH3: Июн'31 | CI3: Июл'31 | CJ3: Авг'31 | CK3: Сен'31 | CL3: Окт'31 | CM3: Ноя'31 | CN3: Дек'31 | CO3: 2031 | CQ3: сheck >> | CR3: 2025 | CS3: 2026 | CT3: 2027 | CU3: 2028 | CV3: 2029 | CW3: 2030 | CX3: 2031 | CZ3: corrections >> | DA3: Янв'27 | DB3: Фев'27 | DC3: Мар'27 | DD3: Апр'27 | DE3: Май'27 | DF3: Июн'27 | DG3: Июл'27 | DH3: Авг'27 | DI3: Сен'27 | DJ3: Окт'27 | DK3: Ноя'27 | DL3: Дек'27 | DM3: 2027 | DN3: Янв'28 | DO3: Фев'28 | DP3: Мар'28 | DQ3: Апр'28 | DR3: Май'28 | DS3: Июн'28 | DT3: Июл'28 | DU3: Авг'28 | DV3: Сен'28 | DW3: Окт'28 | DX3: Ноя'28 | DY3: Дек'28 | DZ3: 2028 | EA3: Янв'29 | EB3: Фев'29 | EC3: Мар'29 | ED3: Апр'29 | EE3: Май'29 | EF3: Июн'29 | EG3: Июл'29 | EH3: Авг'29 | EI3: Сен'29 | EJ3: Окт'29 | EK3: Ноя'29 | EL3: Дек'29 | EM3: 2029 | EN3: Янв'30 | EO3: Фев'30 | EP3: Мар'30 | EQ3: Апр'30 | ER3: Май'30 | ES3: Июн'30 | ET3: Июл'30 | EU3: Авг'30 | EV3: Сен'30 | EW3: Окт'30 | EX3: Ноя'30 | EY3: Дек'30 | EZ3: 2030 | FA3: Янв'31 | FB3: Фев'31 | FC3: Мар'31 | FD3: Апр'31 | FE3: Май'31 | FF3: Июн'31 | FG3: Июл'31 | FH3: Авг'31 | FI3: Сен'31 | FJ3: Окт'31 | FK3: Ноя'31 | FL3: Дек'31 | FM3: 2031 | FO3: negative scenario > | FP3: Янв'25 | FQ3: Фев'25 | FR3: Мар'25 | FS3: Апр'25 | FT3: Май'25 | FU3: Июн'25 | FV3: Июл'25 | FW3: Авг'25 | FX3: Сен'25 | FY3: Окт'25 | FZ3: Ноя'25 | GA3: Дек'25 | GB3: 2025 | GC3: Янв'26 | GD3: Фев'26 | GE3: Мар'26 | GF3: Апр'26 | GG3: Май'26 | GH3: Июн'26 | GI3: Июл'26 | GJ3: Авг'26 | GK3: Сен'26 | GL3: Окт'26 | GM3: Ноя'26 | GN3: Дек'26 | GO3: 2026 | GP3: Янв'27 | GQ3: Фев'27 | GR3: Мар'27 | GS3: Апр'27 | GT3: Май'27 | GU3: Июн'27 | GV3: Июл'27 | GW3: Авг'27 | GX3: Сен'27 | GY3: Окт'27 | GZ3: Ноя'27 | HA3: Дек'27 | HB3: 2027 | HC3: Янв'28 | HD3: Фев'28 | HE3: Мар'28 | HF3: Апр'28 | HG3: Май'28 | HH3: Июн'28 | HI3: Июл'28 | HJ3: Авг'28 | HK3: Сен'28 | HL3: Окт'28 | HM3: Ноя'28 | HN3: Дек'28 | HO3: 2028 | HP3: Янв'29 | HQ3: Фев'29 | HR3: Мар'29 | HS3: Апр'29 | HT3: Май'29 | HU3: Июн'29 | HV3: Июл'29 | HW3: Авг'29 | HX3: Сен'29 | HY3: Окт'29 | HZ3: Ноя'29 | IA3: Дек'29 | IB3: 2029 | IC3: Янв'30 | ID3: Фев'30 | IE3: Мар'30 | IF3: Апр'30 | IG3: Май'30 | IH3: Июн'30 | II3: Июл'30 | IJ3: Авг'30 | IK3: Сен'30 | IL3: Окт'30 | IM3: Ноя'30 | IN3: Дек'30 | IO3: 2030 | IP3: Янв'31 | IQ3: Фев'31 | IR3: Мар'31 | IS3: Апр'31 | IT3: Май'31 | IU3: Июн'31 | IV3: Июл'31 | IW3: Авг'31 | IX3: Сен'31 | IY3: Окт'31 | IZ3: Ноя'31 | JA3: Дек'31 | JB3: 2031 | JD3: check >> | JE3: 2025 | JF3: 2026 | JG3: 2027 | JH3: 2028 | JI3: 2029 | JJ3: 2030 | JK3: 2031
B4: Выручка от реализации | C4: =C5+C33+C35+C37+C39 -> 53407.478 | D4: =D5+D33+D35+D37+D39 -> 59108.136 | E4: =E5+E33+E35+E37+E39 -> 65825.632 | F4: =F5+F33+F35+F37+F39 -> 65714.54 | G4: =G5+G33+G35+G37+G39 -> 66807.293 | H4: =H5+H33+H35+H37+H39 -> 70939.133 | I4: =I5+I33+I35+I37+I39 -> 81620.399 | J4: =J5+J33+J35+J37+J39 -> 79696.642 | ... N4: =N5+N33+N35+N37+N39 -> 88343.074 | O4: =SUM(C4:N4) -> 848093.51 | P4: =P5+P33+P35+P37+P39 -> 64808.555 | Q4: =Q5+Q33+Q35+Q37+Q39 -> 71687.917 | R4: =R5+R33+R35+R37+R39 -> 79870.769 | S4: =S5+S33+S35+S37+S39 -> 79745.41 | T4: =T5+T33+T35+T37+T39 -> 81089.802 | U4: =U5+U33+U35+U37+U39 -> 86107.714 | V4: =V5+V33+V35+V37+V39 -> 99036.479 | W4: =W5+W33+W35+W37+W39 -> 96728.56 | ... AA4: =AA5+AA33+AA35+AA37+AA39 -> 107204.22 | AB4: =SUM(P4:AA4) -> 1029160.5 | AC4: =AC5+AC33+AC35+AC37+AC39 -> 84185.174 | AD4: =AD5+AD33+AD35+AD37+AD39 -> 93113.103 | AE4: =AE5+AE33+AE35+AE37+AE39 -> 103776.65 | AF4: =AF5+AF33+AF35+AF37+AF39 -> 103623.54 | AG4: =AG5+AG33+AG35+AG37+AG39 -> 105407.68 | AH4: =AH5+AH33+AH35+AH37+AH39 -> 111910.47 | AI4: =AI5+AI33+AI35+AI37+AI39 -> 128650.08 | AJ4: =AJ5+AJ33+AJ35+AJ37+AJ39 -> 125716.15 | ... AN4: =AN5+AN33+AN35+AN37+AN39 -> 139302.89 | AO4: =SUM(AC4:AN4) -> 1337307.8 | AP4: =AP5+AP33+AP35+AP37+AP39 -> 110173.45 | AQ4: =AQ5+AQ33+AQ35+AQ37+AQ39 -> 121847.11 | AR4: =AR5+AR33+AR35+AR37+AR39 -> 135817.61 | AS4: =AS5+AS33+AS35+AS37+AS39 -> 135627.41 | AT4: =AT5+AT33+AT35+AT37+AT39 -> 137989.71 | AU4: =AU5+AU33+AU35+AU37+AU39 -> 146466.47 | AV4: =AV5+AV33+AV35+AV37+AV39 -> 168354.86 | AW4: =AW5+AW33+AW35+AW37+AW39 -> 164561.77 | ... BA4: =BA5+BA33+BA35+BA37+BA39 -> 182323.74 | BB4: =SUM(AP4:BA4) -> 1750307.9 | BC4: =BC5+BC33+BC35+BC37+BC39 -> 145692.28 | BD4: =BD5+BD33+BD35+BD37+BD39 -> 161104.48 | BE4: =BE5+BE33+BE35+BE37+BE39 -> 179575.04 | BF4: =BF5+BF33+BF35+BF37+BF39 -> 179330.59 | BG4: =BG5+BG33+BG35+BG37+BG39 -> 182470.69 | BH4: =BH5+BH33+BH35+BH37+BH39 -> 193621.87 | BI4: =BI5+BI33+BI35+BI37+BI39 -> 222615.25 | BJ4: =BJ5+BJ33+BJ35+BJ37+BJ39 -> 217601.61 | ... BN4: =BN5+BN33+BN35+BN37+BN39 -> 241070.2 | BO4: =SUM(BC4:BN4) -> 2314273.9 | BP4: =BP5+BP33+BP35+BP37+BP39 -> 192805.84 | BQ4: =BQ5+BQ33+BQ35+BQ37+BQ39 -> 213155.21 | BR4: =BR5+BR33+BR35+BR37+BR39 -> 237565.36 | BS4: =BS5+BS33+BS35+BS37+BS39 -> 237244.64 | BT4: =BT5+BT33+BT35+BT37+BT39 -> 241400.27 | BU4: =BU5+BU33+BU35+BU37+BU39 -> 256053.57 | BV4: =BV5+BV33+BV35+BV37+BV39 -> 294578.31 | BW4: =BW5+BW33+BW35+BW37+BW39 -> 287881.89 | ... CA4: =CA5+CA33+CA35+CA37+CA39 -> 318917.45 | CB4: =SUM(BP4:CA4) -> 3061607.5 | CC4: =CC5+CC33+CC35+CC37+CC39 -> 255258.11 | CD4: =CD5+CD33+CD35+CD37+CD39 -> 282139.82 | CE4: =CE5+CE33+CE35+CE37+CE39 -> 314399.51 | CF4: =CF5+CF33+CF35+CF37+CF39 -> 313972.42 | CG4: =CG5+CG33+CG35+CG37+CG39 -> 319465.66 | CH4: =CH5+CH33+CH35+CH37+CH39 -> 338724.11 | CI4: =CI5+CI33+CI35+CI37+CI39 -> 389965.05 | CJ4: =CJ5+CJ33+CJ35+CJ37+CJ39 -> 380988.74 | ... CN4: =CN5+CN33+CN35+CN37+CN39 -> 422053.52 | CO4: =SUM(CC4:CN4) -> 4051713.8 | CR4: =O4-'ОПУ БС'!C4 -> 0 | CS4: =AB4-'ОПУ БС'!D4 -> 0 | CT4: =AO4-'ОПУ БС'!E4 -> 0 | CU4: =BB4-'ОПУ БС'!F4 -> 0 | CV4: =BO4-'ОПУ БС'!G4 -> 0 | CW4: =CB4-'ОПУ БС'!H4 -> 0 | CX4: =CO4-'ОПУ БС'!I4 -> 0 | DA4: =DA5+DA33+DA35+DA37+DA39 -> 0 | DB4: =DB5+DB33+DB35+DB37+DB39 -> 0 | DC4: =DC5+DC33+DC35+DC37+DC39 -> 0 | DD4: =DD5+DD33+DD35+DD37+DD39 -> 0 | DE4: =DE5+DE33+DE35+DE37+DE39 -> 0 | DF4: =DF5+DF33+DF35+DF37+DF39 -> 0 | DG4: =DG5+DG33+DG35+DG37+DG39 -> 0 | DH4: =DH5+DH33+DH35+DH37+DH39 -> 0 | ... DL4: =DL5+DL33+DL35+DL37+DL39 -> 0 | DM4: =SUM(DA4:DL4) -> 0 | DN4: =DN5+DN33+DN35+DN37+DN39 -> 0 | DO4: =DO5+DO33+DO35+DO37+DO39 -> 0 | DP4: =DP5+DP33+DP35+DP37+DP39 -> 0 | DQ4: =DQ5+DQ33+DQ35+DQ37+DQ39 -> 0 | DR4: =DR5+DR33+DR35+DR37+DR39 -> 0 | DS4: =DS5+DS33+DS35+DS37+DS39 -> 0 | DT4: =DT5+DT33+DT35+DT37+DT39 -> 0 | DU4: =DU5+DU33+DU35+DU37+DU39 -> 0 | ... DY4: =DY5+DY33+DY35+DY37+DY39 -> 0 | DZ4: =SUM(DN4:DY4) -> 0 | EA4: =EA5+EA33+EA35+EA37+EA39 -> 0 | EB4: =EB5+EB33+EB35+EB37+EB39 -> 0 | EC4: =EC5+EC33+EC35+EC37+EC39 -> 0 | ED4: =ED5+ED33+ED35+ED37+ED39 -> 0 | EE4: =EE5+EE33+EE35+EE37+EE39 -> 0 | EF4: =EF5+EF33+EF35+EF37+EF39 -> 0 | EG4: =EG5+EG33+EG35+EG37+EG39 -> 0 | EH4: =EH5+EH33+EH35+EH37+EH39 -> 0 | ... EL4: =EL5+EL33+EL35+EL37+EL39 -> 0 | EM4: =SUM(EA4:EL4) -> 0 | EN4: =EN5+EN33+EN35+EN37+EN39 -> 0 | EO4: =EO5+EO33+EO35+EO37+EO39 -> 0 | EP4: =EP5+EP33+EP35+EP37+EP39 -> 0 | EQ4: =EQ5+EQ33+EQ35+EQ37+EQ39 -> 0 | ER4: =ER5+ER33+ER35+ER37+ER39 -> 0 | ES4: =ES5+ES33+ES35+ES37+ES39 -> 0 | ET4: =ET5+ET33+ET35+ET37+ET39 -> 0 | EU4: =EU5+EU33+EU35+EU37+EU39 -> 0 | ... EY4: =EY5+EY33+EY35+EY37+EY39 -> 0 | EZ4: =SUM(EN4:EY4) -> 0 | FA4: =FA5+FA33+FA35+FA37+FA39 -> 0 | FB4: =FB5+FB33+FB35+FB37+FB39 -> 0 | FC4: =FC5+FC33+FC35+FC37+FC39 -> 0 | FD4: =FD5+FD33+FD35+FD37+FD39 -> 0 | FE4: =FE5+FE33+FE35+FE37+FE39 -> 0 | FF4: =FF5+FF33+FF35+FF37+FF39 -> 0 | FG4: =FG5+FG33+FG35+FG37+FG39 -> 0 | FH4: =FH5+FH33+FH35+FH37+FH39 -> 0 | ... FL4: =FL5+FL33+FL35+FL37+FL39 -> 0 | FM4: =SUM(FA4:FL4) -> 0 | FP4: =FP5+FP33+FP35+FP37+FP39 -> 53407.478 | FQ4: =FQ5+FQ33+FQ35+FQ37+FQ39 -> 59108.136 | FR4: =FR5+FR33+FR35+FR37+FR39 -> 65825.632 | FS4: =FS5+FS33+FS35+FS37+FS39 -> 65714.54 | FT4: =FT5+FT33+FT35+FT37+FT39 -> 66807.293 | FU4: =FU5+FU33+FU35+FU37+FU39 -> 70939.133 | FV4: =FV5+FV33+FV35+FV37+FV39 -> 81620.399 | FW4: =FW5+FW33+FW35+FW37+FW39 -> 79696.642 | ... GA4: =GA5+GA33+GA35+GA37+GA39 -> 88343.074 | GB4: 0 | GC4: =GC5+GC33+GC35+GC37+GC39 -> 64808.555 | GD4: =GD5+GD33+GD35+GD37+GD39 -> 71687.917 | GE4: =GE5+GE33+GE35+GE37+GE39 -> 79870.769 | GF4: =GF5+GF33+GF35+GF37+GF39 -> 79745.41 | GG4: =GG5+GG33+GG35+GG37+GG39 -> 81089.802 | GH4: =GH5+GH33+GH35+GH37+GH39 -> 86107.714 | GI4: =GI5+GI33+GI35+GI37+GI39 -> 99036.479 | GJ4: =GJ5+GJ33+GJ35+GJ37+GJ39 -> 96728.56 | ... GN4: =GN5+GN33+GN35+GN37+GN39 -> 107204.22 | GO4: 0 | GP4: =GP5+GP33+GP35+GP37+GP39 -> 84185.174 | GQ4: =GQ5+GQ33+GQ35+GQ37+GQ39 -> 93113.103 | GR4: =GR5+GR33+GR35+GR37+GR39 -> 103776.65 | GS4: =GS5+GS33+GS35+GS37+GS39 -> 103623.54 | GT4: =GT5+GT33+GT35+GT37+GT39 -> 105407.68 | GU4: =GU5+GU33+GU35+GU37+GU39 -> 111910.47 | GV4: =GV5+GV33+GV35+GV37+GV39 -> 128650.08 | GW4: =GW5+GW33+GW35+GW37+GW39 -> 125716.15 | ... HA4: =HA5+HA33+HA35+HA37+HA39 -> 139302.89 | HB4: 0 | HC4: =HC5+HC33+HC35+HC37+HC39 -> 110173.45 | HD4: =HD5+HD33+HD35+HD37+HD39 -> 121847.11 | HE4: =HE5+HE33+HE35+HE37+HE39 -> 135817.61 | HF4: =HF5+HF33+HF35+HF37+HF39 -> 135627.41 | HG4: =HG5+HG33+HG35+HG37+HG39 -> 137989.71 | HH4: =HH5+HH33+HH35+HH37+HH39 -> 146466.47 | HI4: =HI5+HI33+HI35+HI37+HI39 -> 168354.86 | HJ4: =HJ5+HJ33+HJ35+HJ37+HJ39 -> 164561.77 | ... HN4: =HN5+HN33+HN35+HN37+HN39 -> 182323.74 | HO4: =SUM(HC4:HN4) -> 1750307.9 | HP4: =HP5+HP33+HP35+HP37+HP39 -> 145692.28 | HQ4: =HQ5+HQ33+HQ35+HQ37+HQ39 -> 161104.48 | HR4: =HR5+HR33+HR35+HR37+HR39 -> 179575.04 | HS4: =HS5+HS33+HS35+HS37+HS39 -> 179330.59 | HT4: =HT5+HT33+HT35+HT37+HT39 -> 182470.69 | HU4: =HU5+HU33+HU35+HU37+HU39 -> 193621.87 | HV4: =HV5+HV33+HV35+HV37+HV39 -> 222615.25 | HW4: =HW5+HW33+HW35+HW37+HW39 -> 217601.61 | ... IA4: =IA5+IA33+IA35+IA37+IA39 -> 241070.2 | IB4: =SUM(HP4:IA4) -> 2314273.9 | IC4: =IC5+IC33+IC35+IC37+IC39 -> 192805.84 | ID4: =ID5+ID33+ID35+ID37+ID39 -> 213155.21 | IE4: =IE5+IE33+IE35+IE37+IE39 -> 237565.36 | IF4: =IF5+IF33+IF35+IF37+IF39 -> 237244.64 | IG4: =IG5+IG33+IG35+IG37+IG39 -> 241400.27 | IH4: =IH5+IH33+IH35+IH37+IH39 -> 256053.57 | II4: =II5+II33+II35+II37+II39 -> 294578.31 | IJ4: =IJ5+IJ33+IJ35+IJ37+IJ39 -> 287881.89 | ... IN4: =IN5+IN33+IN35+IN37+IN39 -> 318917.45 | IO4: =SUM(IC4:IN4) -> 3061607.5 | IP4: =IP5+IP33+IP35+IP37+IP39 -> 255258.11 | IQ4: =IQ5+IQ33+IQ35+IQ37+IQ39 -> 282139.82 | IR4: =IR5+IR33+IR35+IR37+IR39 -> 314399.51 | IS4: =IS5+IS33+IS35+IS37+IS39 -> 313972.42 | IT4: =IT5+IT33+IT35+IT37+IT39 -> 319465.66 | IU4: =IU5+IU33+IU35+IU37+IU39 -> 338724.11 | IV4: =IV5+IV33+IV35+IV37+IV39 -> 389965.05 | IW4: =IW5+IW33+IW35+IW37+IW39 -> 380988.74 | ... JA4: =JA5+JA33+JA35+JA37+JA39 -> 422053.52 | JB4: =SUM(IP4:JA4) -> 4051713.8 | JE4: =O4-GB4 -> 848093.51 | JF4: =AB4-GO4 -> 1029160.5 | JG4: =AO4+DM4-HB4 -> 1337307.8 | JH4: =BB4+DZ4-HO4 -> 0 | JI4: =BO4+EM4-IB4 -> 0 | JJ4: =CB4+EZ4-IO4 -> 0 | JK4: =CO4+FM4-JB4 -> 0
B5: Готовая продукция | C5: =C6+C19+C32 -> 51950.811 | D5: =D6+D19+D32 -> 57517.302 | E5: =E6+E19+E32 -> 64043.132 | F5: =F6+F19+F32 -> 63932.04 | G5: =G6+G19+G32 -> 64986.46 | H5: =H6+H19+H32 -> 69003.3 | I5: =I6+I19+I32 -> 79397.065 | J5: =J6+J19+J32 -> 77530.808 | ... N5: =N6+N19+N32 -> 85947.241 | O5: =SUM(C5:N5) -> 825093.51 | P5: =P6+P19+P32 -> 63286.339 | Q5: =Q6+Q19+Q32 -> 70025.496 | R5: =R6+R19+R32 -> 78008.056 | S5: =S6+S19+S32 -> 77882.697 | T5: =T6+T19+T32 -> 79187.031 | U5: =U6+U19+U32 -> 84084.768 | V5: =V6+V19+V32 -> 96713.095 | W5: =W6+W19+W32 -> 94465.264 | ... AA5: =AA6+AA19+AA32 -> 104700.57 | AB5: =SUM(P5:AA5) -> 1005125.5 | AC5: =AC6+AC19+AC32 -> 82602.069 | AD5: =AD6+AD19+AD32 -> 91384.186 | AE5: =AE6+AE19+AE32 -> 101839.43 | AF5: =AF6+AF19+AF32 -> 101686.32 | AG5: =AG6+AG19+AG32 -> 103428.8 | AH5: =AH6+AH19+AH32 -> 109806.61 | AI5: =AI6+AI19+AI32 -> 126233.76 | AJ5: =AJ6+AJ19+AJ32 -> 123362.33 | ... AN5: =AN6+AN19+AN32 -> 136699.1 | AO5: =SUM(AC5:AN5) -> 1312311.4 | AP5: =AP6+AP19+AP32 -> 108527.02 | AQ5: =AQ6+AQ19+AQ32 -> 120049.03 | AR5: =AR6+AR19+AR32 -> 133802.9 | AS5: =AS6+AS19+AS32 -> 133612.7 | AT5: =AT6+AT19+AT32 -> 135931.67 | AU5: =AU6+AU19+AU32 -> 144278.46 | AV5: =AV6+AV19+AV32 -> 165841.89 | AW5: =AW6+AW19+AW32 -> 162113.79 | ... BA5: =BA6+BA19+BA32 -> 179615.8 | BB5: =SUM(AP5:BA5) -> 1724311.7 | BC5: =BC6+BC19+BC32 -> 143979.99 | BD5: =BD6+BD19+BD32 -> 159234.48 | BE5: =BE6+BE19+BE32 -> 177479.74 | BF5: =BF6+BF19+BF32 -> 177235.29 | BG5: =BG6+BG19+BG32 -> 180330.33 | BH5: =BH6+BH19+BH32 -> 191346.33 | BI5: =BI6+BI19+BI32 -> 220001.76 | BJ5: =BJ6+BJ19+BJ32 -> 215055.71 | ... BN5: =BN6+BN19+BN32 -> 238253.94 | BO5: =SUM(BC5:BN5) -> 2287237.8 | BP5: =BP6+BP19+BP32 -> 191025.07 | BQ5: =BQ6+BQ19+BQ32 -> 211210.41 | BR5: =BR6+BR19+BR32 -> 235386.25 | BS5: =BS6+BS19+BS32 -> 235065.53 | BT5: =BT6+BT19+BT32 -> 239174.3 | BU5: =BU6+BU19+BU32 -> 253687.01 | BV5: =BV6+BV19+BV32 -> 291860.28 | BW5: =BW6+BW19+BW32 -> 285234.16 | ... CA5: =CA6+CA19+CA32 -> 315988.54 | CB5: =SUM(BP5:CA5) -> 3033490 | CC5: =CC6+CC19+CC32 -> 253406.11 | CD5: =CD6+CD19+CD32 -> 280117.23 | CE5: =CE6+CE19+CE32 -> 312133.24 | CF5: =CF6+CF19+CF32 -> 311706.14 | CG5: =CG6+CG19+CG32 -> 317150.65 | CH5: =CH6+CH19+CH32 -> 336262.89 | CI5: =CI6+CI19+CI32 -> 387138.29 | CJ5: =CJ6+CJ19+CJ32 -> 378235.09 | ... CN5: =CN6+CN19+CN32 -> 419007.45 | CO5: =SUM(CC5:CN5) -> 4022471.5 | CR5: =O5-'ОПУ БС'!C5 -> 0 | CS5: =AB5-'ОПУ БС'!D5 -> 0 | CT5: =AO5-'ОПУ БС'!E5 -> 0 | CU5: =BB5-'ОПУ БС'!F5 -> 0 | CV5: =BO5-'ОПУ БС'!G5 -> 0 | CW5: =CB5-'ОПУ БС'!H5 -> 0 | CX5: =CO5-'ОПУ БС'!I5 -> 0 | DA5: =DA6+DA19+DA32 -> 0 | DB5: =DB6+DB19+DB32 -> 0 | DC5: =DC6+DC19+DC32 -> 0 | DD5: =DD6+DD19+DD32 -> 0 | DE5: =DE6+DE19+DE32 -> 0 | DF5: =DF6+DF19+DF32 -> 0 | DG5: =DG6+DG19+DG32 -> 0 | DH5: =DH6+DH19+DH32 -> 0 | ... DL5: =DL6+DL19+DL32 -> 0 | DM5: =SUM(DA5:DL5) -> 0 | DN5: =DN6+DN19+DN32 -> 0 | DO5: =DO6+DO19+DO32 -> 0 | DP5: =DP6+DP19+DP32 -> 0 | DQ5: =DQ6+DQ19+DQ32 -> 0 | DR5: =DR6+DR19+DR32 -> 0 | DS5: =DS6+DS19+DS32 -> 0 | DT5: =DT6+DT19+DT32 -> 0 | DU5: =DU6+DU19+DU32 -> 0 | ... DY5: =DY6+DY19+DY32 -> 0 | DZ5: =SUM(DN5:DY5) -> 0 | EA5: =EA6+EA19+EA32 -> 0 | EB5: =EB6+EB19+EB32 -> 0 | EC5: =EC6+EC19+EC32 -> 0 | ED5: =ED6+ED19+ED32 -> 0 | EE5: =EE6+EE19+EE32 -> 0 | EF5: =EF6+EF19+EF32 -> 0 | EG5: =EG6+EG19+EG32 -> 0 | EH5: =EH6+EH19+EH32 -> 0 | ... EL5: =EL6+EL19+EL32 -> 0 | EM5: =SUM(EA5:EL5) -> 0 | EN5: =EN6+EN19+EN32 -> 0 | EO5: =EO6+EO19+EO32 -> 0 | EP5: =EP6+EP19+EP32 -> 0 | EQ5: =EQ6+EQ19+EQ32 -> 0 | ER5: =ER6+ER19+ER32 -> 0 | ES5: =ES6+ES19+ES32 -> 0 | ET5: =ET6+ET19+ET32 -> 0 | EU5: =EU6+EU19+EU32 -> 0 | ... EY5: =EY6+EY19+EY32 -> 0 | EZ5: =SUM(EN5:EY5) -> 0 | FA5: =FA6+FA19+FA32 -> 0 | FB5: =FB6+FB19+FB32 -> 0 | FC5: =FC6+FC19+FC32 -> 0 | FD5: =FD6+FD19+FD32 -> 0 | FE5: =FE6+FE19+FE32 -> 0 | FF5: =FF6+FF19+FF32 -> 0 | FG5: =FG6+FG19+FG32 -> 0 | FH5: =FH6+FH19+FH32 -> 0 | ... FL5: =FL6+FL19+FL32 -> 0 | FM5: =SUM(FA5:FL5) -> 0 | FP5: =FP6+FP19+FP32 -> 51950.811 | FQ5: =FQ6+FQ19+FQ32 -> 57517.302 | FR5: =FR6+FR19+FR32 -> 64043.132 | FS5: =FS6+FS19+FS32 -> 63932.04 | FT5: =FT6+FT19+FT32 -> 64986.46 | FU5: =FU6+FU19+FU32 -> 69003.3 | FV5: =FV6+FV19+FV32 -> 79397.065 | FW5: =FW6+FW19+FW32 -> 77530.808 | ... GA5: =GA6+GA19+GA32 -> 85947.241 | GB5: =SUM(FP5:GA5) -> 825093.51 | GC5: =GC6+GC19+GC32 -> 63286.339 | GD5: =GD6+GD19+GD32 -> 70025.496 | GE5: =GE6+GE19+GE32 -> 78008.056 | GF5: =GF6+GF19+GF32 -> 77882.697 | GG5: =GG6+GG19+GG32 -> 79187.031 | GH5: =GH6+GH19+GH32 -> 84084.768 | GI5: =GI6+GI19+GI32 -> 96713.095 | GJ5: =GJ6+GJ19+GJ32 -> 94465.264 | ... GN5: =GN6+GN19+GN32 -> 104700.57 | GO5: =SUM(GC5:GN5) -> 1005125.5 | GP5: =GP6+GP19+GP32 -> 82602.069 | GQ5: =GQ6+GQ19+GQ32 -> 91384.186 | GR5: =GR6+GR19+GR32 -> 101839.43 | GS5: =GS6+GS19+GS32 -> 101686.32 | GT5: =GT6+GT19+GT32 -> 103428.8 | GU5: =GU6+GU19+GU32 -> 109806.61 | GV5: =GV6+GV19+GV32 -> 126233.76 | GW5: =GW6+GW19+GW32 -> 123362.33 | ... HA5: =HA6+HA19+HA32 -> 136699.1 | HB5: =SUM(GP5:HA5) -> 1312311.4 | HC5: =HC6+HC19+HC32 -> 108527.02 | HD5: =HD6+HD19+HD32 -> 120049.03 | HE5: =HE6+HE19+HE32 -> 133802.9 | HF5: =HF6+HF19+HF32 -> 133612.7 | HG5: =HG6+HG19+HG32 -> 135931.67 | HH5: =HH6+HH19+HH32 -> 144278.46 | HI5: =HI6+HI19+HI32 -> 165841.89 | HJ5: =HJ6+HJ19+HJ32 -> 162113.79 | ... HN5: =HN6+HN19+HN32 -> 179615.8 | HO5: =SUM(HC5:HN5) -> 1724311.7 | HP5: =HP6+HP19+HP32 -> 143979.99 | HQ5: =HQ6+HQ19+HQ32 -> 159234.48 | HR5: =HR6+HR19+HR32 -> 177479.74 | HS5: =HS6+HS19+HS32 -> 177235.29 | HT5: =HT6+HT19+HT32 -> 180330.33 | HU5: =HU6+HU19+HU32 -> 191346.33 | HV5: =HV6+HV19+HV32 -> 220001.76 | HW5: =HW6+HW19+HW32 -> 215055.71 | ... IA5: =IA6+IA19+IA32 -> 238253.94 | IB5: =SUM(HP5:IA5) -> 2287237.8 | IC5: =IC6+IC19+IC32 -> 191025.07 | ID5: =ID6+ID19+ID32 -> 211210.41 | IE5: =IE6+IE19+IE32 -> 235386.25 | IF5: =IF6+IF19+IF32 -> 235065.53 | IG5: =IG6+IG19+IG32 -> 239174.3 | IH5: =IH6+IH19+IH32 -> 253687.01 | II5: =II6+II19+II32 -> 291860.28 | IJ5: =IJ6+IJ19+IJ32 -> 285234.16 | ... IN5: =IN6+IN19+IN32 -> 315988.54 | IO5: =SUM(IC5:IN5) -> 3033490 | IP5: =IP6+IP19+IP32 -> 253406.11 | IQ5: =IQ6+IQ19+IQ32 -> 280117.23 | IR5: =IR6+IR19+IR32 -> 312133.24 | IS5: =IS6+IS19+IS32 -> 311706.14 | IT5: =IT6+IT19+IT32 -> 317150.65 | IU5: =IU6+IU19+IU32 -> 336262.89 | IV5: =IV6+IV19+IV32 -> 387138.29 | IW5: =IW6+IW19+IW32 -> 378235.09 | ... JA5: =JA6+JA19+JA32 -> 419007.45 | JB5: =SUM(IP5:JA5) -> 4022471.5 | JE5: =O5-GB5 -> 0 | JF5: =AB5-GO5 -> 0 | JG5: =AO5+DM5-HB5 -> 0 | JH5: =BB5+DZ5-HO5 -> 0 | JI5: =BO5+EM5-IB5 -> 0 | JJ5: =CB5+EZ5-IO5 -> 0 | JK5: =CO5+FM5-JB5 -> 0
B6: МАГАЗИНЫ | C6: =C7+C11 -> 33993.402 | D6: =D7+D11 -> 37545.724 | E6: =E7+E11 -> 41679.861 | F6: =F7+F11 -> 41597.189 | G6: =G7+G11 -> 42162.159 | H6: =H7+H11 -> 44735.381 | I6: =I7+I11 -> 51936.176 | J6: =J7+J11 -> 50377.323 | ... N6: =N7+N11 -> 55910.2 | O6: =SUM(C6:N6) -> 536737.92 | P6: =P7+P11 -> 39121.168 | Q6: =Q7+Q11 -> 43205.589 | R6: =R7+R11 -> 47966.115 | S6: =S7+S11 -> 47871.956 | T6: =T7+T11 -> 48522.639 | U6: =U7+U11 -> 51479.62 | V6: =V7+V11 -> 59765.906 | W6: =W7+W11 -> 57982.945 | ... AA6: =AA7+AA11 -> 64344.027 | AB6: =SUM(P6:AA6) -> 617702.66 | AC6: =AC7+AC11 -> 48287.575 | AD6: =AD7+AD11 -> 53323.699 | AE6: =AE7+AE11 -> 59203.642 | AF6: =AF7+AF11 -> 59088.743 | AG6: =AG7+AG11 -> 59907.665 | AH6: =AH7+AH11 -> 63529.667 | AI6: =AI7+AI11 -> 73768.969 | AJ6: =AJ7+AJ11 -> 71582.337 | ... AN6: =AN7+AN11 -> 79420.353 | AO6: =SUM(AC6:AN6) -> 762435.39 | AP6: =AP7+AP11 -> 61777.919 | AQ6: =AQ7+AQ11 -> 68219.415 | AR6: =AR7+AR11 -> 75743.116 | AS6: =AS7+AS11 -> 75596.664 | AT6: =AT7+AT11 -> 76662.142 | AU6: =AU7+AU11 -> 81254.419 | AV6: =AV7+AV11 -> 94365.69 | AW6: =AW7+AW11 -> 91595.121 | ... BA6: =BA7+BA11 -> 101608.42 | BB6: =SUM(AP6:BA6) -> 975440.83 | BC6: =BC7+BC11 -> 82108.656 | BD6: =BD7+BD11 -> 90666.058 | BE6: =BE7+BE11 -> 100668.75 | BF6: =BF7+BF11 -> 100475.07 | BG6: =BG7+BG11 -> 101915.96 | BH6: =BH7+BH11 -> 107963.09 | BI6: =BI7+BI11 -> 125406.12 | BJ6: =BJ7+BJ11 -> 121756.76 | ... BN6: =BN7+BN11 -> 135047.13 | BO6: =SUM(BC6:BN6) -> 1296452.5 | BP6: =BP7+BP11 -> 111869.46 | BQ6: =BQ7+BQ11 -> 123521.36 | BR6: =BR7+BR11 -> 137155.18 | BS6: =BS7+BS11 -> 136892.89 | BT6: =BT7+BT11 -> 138890.52 | BU6: =BU7+BU11 -> 147046.9 | BV6: =BV7+BV11 -> 170841.52 | BW6: =BW7+BW11 -> 165912.74 | ... CA6: =CA7+CA11 -> 183995.82 | CB6: =SUM(BP6:CA6) -> 1766359.9 | CC6: =CC7+CC11 -> 154054.25 | CD6: =CD7+CD11 -> 170085.35 | CE6: =CE7+CE11 -> 188871.96 | CF6: =CF7+CF11 -> 188513.75 | CG6: =CG7+CG11 -> 191312.66 | CH6: =CH7+CH11 -> 202447.34 | CI6: =CI7+CI11 -> 235245.21 | CJ6: =CJ7+CJ11 -> 228506.7 | ... CN6: =CN7+CN11 -> 253378.7 | CO6: =SUM(CC6:CN6) -> 2432435.5 | CR6: =O6-'ОПУ БС'!C6 -> 0 | CS6: =AB6-'ОПУ БС'!D6 -> 0 | CT6: =AO6-'ОПУ БС'!E6 -> 0 | CU6: =BB6-'ОПУ БС'!F6 -> 0 | CV6: =BO6-'ОПУ БС'!G6 -> 0 | CW6: =CB6-'ОПУ БС'!H6 -> 0 | CX6: =CO6-'ОПУ БС'!I6 -> 0 | DA6: =DA7+DA11 -> 0 | DB6: =DB7+DB11 -> 0 | DC6: =DC7+DC11 -> 0 | DD6: =DD7+DD11 -> 0 | DE6: =DE7+DE11 -> 0 | DF6: =DF7+DF11 -> 0 | DG6: =DG7+DG11 -> 0 | DH6: =DH7+DH11 -> 0 | ... DL6: =DL7+DL11 -> 0 | DM6: =SUM(DA6:DL6) -> 0 | DN6: =DN7+DN11 -> 0 | DO6: =DO7+DO11 -> 0 | DP6: =DP7+DP11 -> 0 | DQ6: =DQ7+DQ11 -> 0 | DR6: =DR7+DR11 -> 0 | DS6: =DS7+DS11 -> 0 | DT6: =DT7+DT11 -> 0 | DU6: =DU7+DU11 -> 0 | ... DY6: =DY7+DY11 -> 0 | DZ6: =SUM(DN6:DY6) -> 0 | EA6: =EA7+EA11 -> 0 | EB6: =EB7+EB11 -> 0 | EC6: =EC7+EC11 -> 0 | ED6: =ED7+ED11 -> 0 | EE6: =EE7+EE11 -> 0 | EF6: =EF7+EF11 -> 0 | EG6: =EG7+EG11 -> 0 | EH6: =EH7+EH11 -> 0 | ... EL6: =EL7+EL11 -> 0 | EM6: =SUM(EA6:EL6) -> 0 | EN6: =EN7+EN11 -> 0 | EO6: =EO7+EO11 -> 0 | EP6: =EP7+EP11 -> 0 | EQ6: =EQ7+EQ11 -> 0 | ER6: =ER7+ER11 -> 0 | ES6: =ES7+ES11 -> 0 | ET6: =ET7+ET11 -> 0 | EU6: =EU7+EU11 -> 0 | ... EY6: =EY7+EY11 -> 0 | EZ6: =SUM(EN6:EY6) -> 0 | FA6: =FA7+FA11 -> 0 | FB6: =FB7+FB11 -> 0 | FC6: =FC7+FC11 -> 0 | FD6: =FD7+FD11 -> 0 | FE6: =FE7+FE11 -> 0 | FF6: =FF7+FF11 -> 0 | FG6: =FG7+FG11 -> 0 | FH6: =FH7+FH11 -> 0 | ... FL6: =FL7+FL11 -> 0 | FM6: =SUM(FA6:FL6) -> 0 | FP6: =FP7+FP11 -> 33993.402 | FQ6: =FQ7+FQ11 -> 37545.724 | FR6: =FR7+FR11 -> 41679.861 | FS6: =FS7+FS11 -> 41597.189 | FT6: =FT7+FT11 -> 42162.159 | FU6: =FU7+FU11 -> 44735.381 | FV6: =FV7+FV11 -> 51936.176 | FW6: =FW7+FW11 -> 50377.323 | ... GA6: =GA7+GA11 -> 55910.2 | GB6: =SUM(FP6:GA6) -> 536737.92 | GC6: =GC7+GC11 -> 39121.168 | GD6: =GD7+GD11 -> 43205.589 | GE6: =GE7+GE11 -> 47966.115 | GF6: =GF7+GF11 -> 47871.956 | GG6: =GG7+GG11 -> 48522.639 | GH6: =GH7+GH11 -> 51479.62 | GI6: =GI7+GI11 -> 59765.906 | GJ6: =GJ7+GJ11 -> 57982.945 | ... GN6: =GN7+GN11 -> 64344.027 | GO6: =SUM(GC6:GN6) -> 617702.66 | GP6: =GP7+GP11 -> 48287.575 | GQ6: =GQ7+GQ11 -> 53323.699 | GR6: =GR7+GR11 -> 59203.642 | GS6: =GS7+GS11 -> 59088.743 | GT6: =GT7+GT11 -> 59907.665 | GU6: =GU7+GU11 -> 63529.667 | GV6: =GV7+GV11 -> 73768.969 | GW6: =GW7+GW11 -> 71582.337 | ... HA6: =HA7+HA11 -> 79420.353 | HB6: =SUM(GP6:HA6) -> 762435.39 | HC6: =HC7+HC11 -> 61777.919 | HD6: =HD7+HD11 -> 68219.415 | HE6: =HE7+HE11 -> 75743.116 | HF6: =HF7+HF11 -> 75596.664 | HG6: =HG7+HG11 -> 76662.142 | HH6: =HH7+HH11 -> 81254.419 | HI6: =HI7+HI11 -> 94365.69 | HJ6: =HJ7+HJ11 -> 91595.121 | ... HN6: =HN7+HN11 -> 101608.42 | HO6: =SUM(HC6:HN6) -> 975440.83 | HP6: =HP7+HP11 -> 82108.656 | HQ6: =HQ7+HQ11 -> 90666.058 | HR6: =HR7+HR11 -> 100668.75 | HS6: =HS7+HS11 -> 100475.07 | HT6: =HT7+HT11 -> 101915.96 | HU6: =HU7+HU11 -> 107963.09 | HV6: =HV7+HV11 -> 125406.12 | HW6: =HW7+HW11 -> 121756.76 | ... IA6: =IA7+IA11 -> 135047.13 | IB6: =SUM(HP6:IA6) -> 1296452.5 | IC6: =IC7+IC11 -> 111869.46 | ID6: =ID7+ID11 -> 123521.36 | IE6: =IE7+IE11 -> 137155.18 | IF6: =IF7+IF11 -> 136892.89 | IG6: =IG7+IG11 -> 138890.52 | IH6: =IH7+IH11 -> 147046.9 | II6: =II7+II11 -> 170841.52 | IJ6: =IJ7+IJ11 -> 165912.74 | ... IN6: =IN7+IN11 -> 183995.82 | IO6: =SUM(IC6:IN6) -> 1766359.9 | IP6: =IP7+IP11 -> 154054.25 | IQ6: =IQ7+IQ11 -> 170085.35 | IR6: =IR7+IR11 -> 188871.96 | IS6: =IS7+IS11 -> 188513.75 | IT6: =IT7+IT11 -> 191312.66 | IU6: =IU7+IU11 -> 202447.34 | IV6: =IV7+IV11 -> 235245.21 | IW6: =IW7+IW11 -> 228506.7 | ... JA6: =JA7+JA11 -> 253378.7 | JB6: =SUM(IP6:JA6) -> 2432435.5 | JE6: =O6-GB6 -> 0 | JF6: =AB6-GO6 -> 0 | JG6: =AO6+DM6-HB6 -> 0 | JH6: =BB6+DZ6-HO6 -> 0 | JI6: =BO6+EM6-IB6 -> 0 | JJ6: =CB6+EZ6-IO6 -> 0 | JK6: =CO6+FM6-JB6 -> 0
B7: Сухари | C7: =SUM(C8:C10) -> 27314.817 | D7: =SUM(D8:D10) -> 30252.006 | E7: =SUM(E8:E10) -> 33507.382 | F7: =SUM(F8:F10) -> 33424.71 | G7: =SUM(G8:G10) -> 34143.521 | H7: =SUM(H8:H10) -> 36299.954 | I7: =SUM(I8:I10) -> 41691.036 | J7: =SUM(J8:J10) -> 40612.82 | ... N7: =SUM(N8:N10) -> 44925.686 | O7: =SUM(C7:N7) -> 431286.58 | P7: =SUM(P8:P10) -> 31663.982 | Q7: =SUM(Q8:Q10) -> 35061.557 | R7: =SUM(R8:R10) -> 38840.874 | S7: =SUM(S8:S10) -> 38746.715 | T7: =SUM(T8:T10) -> 39579.978 | U7: =SUM(U8:U10) -> 42079.766 | V7: =SUM(V8:V10) -> 48329.236 | W7: =SUM(W8:W10) -> 47079.342 | ... AA7: =SUM(AA8:AA10) -> 52078.918 | AB7: =SUM(P7:AA7) -> 499957.61 | AC7: =SUM(AC8:AC10) -> 39287.131 | AD7: =SUM(AD8:AD10) -> 43494.268 | AE7: =SUM(AE8:AE10) -> 48189.942 | AF7: =SUM(AF8:AF10) -> 48075.042 | AG7: =SUM(AG8:AG10) -> 49108.914 | AH7: =SUM(AH8:AH10) -> 52210.53 | AI7: =SUM(AI8:AI10) -> 59964.569 | AJ7: =SUM(AJ8:AJ10) -> 58413.761 | ... AN7: =SUM(AN8:AN10) -> 64616.992 | AO7: =SUM(AC7:AN7) -> 620323.12 | AP7: =SUM(AP8:AP10) -> 50905.699 | AQ7: =SUM(AQ8:AQ10) -> 56345.806 | AR7: =SUM(AR8:AR10) -> 62438.951 | AS7: =SUM(AS8:AS10) -> 62292.5 | AT7: =SUM(AT8:AT10) -> 63632.123 | AU7: =SUM(AU8:AU10) -> 67650.994 | AV7: =SUM(AV8:AV10) -> 77698.172 | AW7: =SUM(AW8:AW10) -> 75688.736 | ... BA7: =SUM(BA8:BA10) -> 83726.478 | BB7: =SUM(AP7:BA7) -> 803774.19 | BC7: =SUM(BC8:BC10) -> 68439.062 | BD7: =SUM(BD8:BD10) -> 75737.422 | BE7: =SUM(BE8:BE10) -> 83941.479 | BF7: =SUM(BF8:BF10) -> 83747.799 | BG7: =SUM(BG8:BG10) -> 85548.827 | BH7: =SUM(BH8:BH10) -> 90951.911 | BI7: =SUM(BI8:BI10) -> 104459.62 | BJ7: =SUM(BJ8:BJ10) -> 101758.08 | ... BN7: =SUM(BN8:BN10) -> 112564.25 | BO7: =SUM(BC7:BN7) -> 1080616.8 | BP7: =SUM(BP8:BP10) -> 94247.241 | BQ7: =SUM(BQ8:BQ10) -> 104276.05 | BR7: =SUM(BR8:BR10) -> 115591.15 | BS7: =SUM(BS8:BS10) -> 115328.86 | BT7: =SUM(BT8:BT10) -> 117809.05 | BU7: =SUM(BU8:BU10) -> 125249.62 | BV7: =SUM(BV8:BV10) -> 143851.05 | BW7: =SUM(BW8:BW10) -> 140130.77 | ... CA7: =SUM(CA8:CA10) -> 155011.91 | CB7: =SUM(BP7:CA7) -> 1488114.3 | CC7: =SUM(CC8:CC10) -> 130915.55 | CD7: =SUM(CD8:CD10) -> 144815.45 | CE7: =SUM(CE8:CE10) -> 160557.49 | CF7: =SUM(CF8:CF10) -> 160199.29 | CG7: =SUM(CG8:CG10) -> 163644.43 | CH7: =SUM(CH8:CH10) -> 173979.87 | CI7: =SUM(CI8:CI10) -> 199818.47 | CJ7: =SUM(CJ8:CJ10) -> 194650.75 | ... CN7: =SUM(CN8:CN10) -> 215321.62 | CO7: =SUM(CC7:CN7) -> 2067087.6 | CR7: =O7-'ОПУ БС'!C7 -> 0 | CS7: =AB7-'ОПУ БС'!D7 -> 0 | CT7: =AO7-'ОПУ БС'!E7 -> 0 | CU7: =BB7-'ОПУ БС'!F7 -> 0 | CV7: =BO7-'ОПУ БС'!G7 -> 0 | CW7: =CB7-'ОПУ БС'!H7 -> 0 | CX7: =CO7-'ОПУ БС'!I7 -> 0 | DA7: =SUM(DA8:DA10) -> 0 | DB7: =SUM(DB8:DB10) -> 0 | DC7: =SUM(DC8:DC10) -> 0 | DD7: =SUM(DD8:DD10) -> 0 | DE7: =SUM(DE8:DE10) -> 0 | DF7: =SUM(DF8:DF10) -> 0 | DG7: =SUM(DG8:DG10) -> 0 | DH7: =SUM(DH8:DH10) -> 0 | ... DL7: =SUM(DL8:DL10) -> 0 | DM7: =SUM(DA7:DL7) -> 0 | DN7: =SUM(DN8:DN10) -> 0 | DO7: =SUM(DO8:DO10) -> 0 | DP7: =SUM(DP8:DP10) -> 0 | DQ7: =SUM(DQ8:DQ10) -> 0 | DR7: =SUM(DR8:DR10) -> 0 | DS7: =SUM(DS8:DS10) -> 0 | DT7: =SUM(DT8:DT10) -> 0 | DU7: =SUM(DU8:DU10) -> 0 | ... DY7: =SUM(DY8:DY10) -> 0 | DZ7: =SUM(DN7:DY7) -> 0 | EA7: =SUM(EA8:EA10) -> 0 | EB7: =SUM(EB8:EB10) -> 0 | EC7: =SUM(EC8:EC10) -> 0 | ED7: =SUM(ED8:ED10) -> 0 | EE7: =SUM(EE8:EE10) -> 0 | EF7: =SUM(EF8:EF10) -> 0 | EG7: =SUM(EG8:EG10) -> 0 | EH7: =SUM(EH8:EH10) -> 0 | ... EL7: =SUM(EL8:EL10) -> 0 | EM7: =SUM(EA7:EL7) -> 0 | EN7: =SUM(EN8:EN10) -> 0 | EO7: =SUM(EO8:EO10) -> 0 | EP7: =SUM(EP8:EP10) -> 0 | EQ7: =SUM(EQ8:EQ10) -> 0 | ER7: =SUM(ER8:ER10) -> 0 | ES7: =SUM(ES8:ES10) -> 0 | ET7: =SUM(ET8:ET10) -> 0 | EU7: =SUM(EU8:EU10) -> 0 | ... EY7: =SUM(EY8:EY10) -> 0 | EZ7: =SUM(EN7:EY7) -> 0 | FA7: =SUM(FA8:FA10) -> 0 | FB7: =SUM(FB8:FB10) -> 0 | FC7: =SUM(FC8:FC10) -> 0 | FD7: =SUM(FD8:FD10) -> 0 | FE7: =SUM(FE8:FE10) -> 0 | FF7: =SUM(FF8:FF10) -> 0 | FG7: =SUM(FG8:FG10) -> 0 | FH7: =SUM(FH8:FH10) -> 0 | ... FL7: =SUM(FL8:FL10) -> 0 | FM7: =SUM(FA7:FL7) -> 0 | FP7: =SUM(FP8:FP10) -> 27314.817 | FQ7: =SUM(FQ8:FQ10) -> 30252.006 | FR7: =SUM(FR8:FR10) -> 33507.382 | FS7: =SUM(FS8:FS10) -> 33424.71 | FT7: =SUM(FT8:FT10) -> 34143.521 | FU7: =SUM(FU8:FU10) -> 36299.954 | FV7: =SUM(FV8:FV10) -> 41691.036 | FW7: =SUM(FW8:FW10) -> 40612.82 | ... GA7: =SUM(GA8:GA10) -> 44925.686 | GB7: =SUM(FP7:GA7) -> 431286.58 | GC7: =SUM(GC8:GC10) -> 31663.982 | GD7: =SUM(GD8:GD10) -> 35061.557 | GE7: =SUM(GE8:GE10) -> 38840.874 | GF7: =SUM(GF8:GF10) -> 38746.715 | GG7: =SUM(GG8:GG10) -> 39579.978 | GH7: =SUM(GH8:GH10) -> 42079.766 | GI7: =SUM(GI8:GI10) -> 48329.236 | GJ7: =SUM(GJ8:GJ10) -> 47079.342 | ... GN7: =SUM(GN8:GN10) -> 52078.918 | GO7: =SUM(GC7:GN7) -> 499957.61 | GP7: =SUM(GP8:GP10) -> 39287.131 | GQ7: =SUM(GQ8:GQ10) -> 43494.268 | GR7: =SUM(GR8:GR10) -> 48189.942 | GS7: =SUM(GS8:GS10) -> 48075.042 | GT7: =SUM(GT8:GT10) -> 49108.914 | GU7: =SUM(GU8:GU10) -> 52210.53 | GV7: =SUM(GV8:GV10) -> 59964.569 | GW7: =SUM(GW8:GW10) -> 58413.761 | ... HA7: =SUM(HA8:HA10) -> 64616.992 | HB7: =SUM(GP7:HA7) -> 620323.12 | HC7: =SUM(HC8:HC10) -> 50905.699 | HD7: =SUM(HD8:HD10) -> 56345.806 | HE7: =SUM(HE8:HE10) -> 62438.951 | HF7: =SUM(HF8:HF10) -> 62292.5 | HG7: =SUM(HG8:HG10) -> 63632.123 | HH7: =SUM(HH8:HH10) -> 67650.994 | HI7: =SUM(HI8:HI10) -> 77698.172 | HJ7: =SUM(HJ8:HJ10) -> 75688.736 | ... HN7: =SUM(HN8:HN10) -> 83726.478 | HO7: =SUM(HC7:HN7) -> 803774.19 | HP7: =SUM(HP8:HP10) -> 68439.062 | HQ7: =SUM(HQ8:HQ10) -> 75737.422 | HR7: =SUM(HR8:HR10) -> 83941.479 | HS7: =SUM(HS8:HS10) -> 83747.799 | HT7: =SUM(HT8:HT10) -> 85548.827 | HU7: =SUM(HU8:HU10) -> 90951.911 | HV7: =SUM(HV8:HV10) -> 104459.62 | HW7: =SUM(HW8:HW10) -> 101758.08 | ... IA7: =SUM(IA8:IA10) -> 112564.25 | IB7: =SUM(HP7:IA7) -> 1080616.8 | IC7: =SUM(IC8:IC10) -> 94247.241 | ID7: =SUM(ID8:ID10) -> 104276.05 | IE7: =SUM(IE8:IE10) -> 115591.15 | IF7: =SUM(IF8:IF10) -> 115328.86 | IG7: =SUM(IG8:IG10) -> 117809.05 | IH7: =SUM(IH8:IH10) -> 125249.62 | II7: =SUM(II8:II10) -> 143851.05 | IJ7: =SUM(IJ8:IJ10) -> 140130.77 | ... IN7: =SUM(IN8:IN10) -> 155011.91 | IO7: =SUM(IC7:IN7) -> 1488114.3 | IP7: =SUM(IP8:IP10) -> 130915.55 | IQ7: =SUM(IQ8:IQ10) -> 144815.45 | IR7: =SUM(IR8:IR10) -> 160557.49 | IS7: =SUM(IS8:IS10) -> 160199.29 | IT7: =SUM(IT8:IT10) -> 163644.43 | IU7: =SUM(IU8:IU10) -> 173979.87 | IV7: =SUM(IV8:IV10) -> 199818.47 | IW7: =SUM(IW8:IW10) -> 194650.75 | ... JA7: =SUM(JA8:JA10) -> 215321.62 | JB7: =SUM(IP7:JA7) -> 2067087.6 | JE7: =O7-GB7 -> 0 | JF7: =AB7-GO7 -> 0 | JG7: =AO7+DM7-HB7 -> 0 | JH7: =BB7+DZ7-HO7 -> 0 | JI7: =BO7+EM7-IB7 -> 0 | JJ7: =CB7+EZ7-IO7 -> 0 | JK7: =CO7+FM7-JB7 -> 0
B8: Классика | C8: ='ОПУ БС'!$C8/12*'ОПУ БС'!L8 -> 13499.063 | D8: ='ОПУ БС'!$C8/12*'ОПУ БС'!M8 -> 14742.398 | E8: ='ОПУ БС'!$C8/12*'ОПУ БС'!N8 -> 16518.591 | F8: ='ОПУ БС'!$C8/12*'ОПУ БС'!O8 -> 16518.591 | G8: ='ОПУ БС'!$C8/12*'ОПУ БС'!P8 -> 16873.829 | H8: ='ОПУ БС'!$C8/12*'ОПУ БС'!Q8 -> 17939.545 | I8: ='ОПУ БС'!$C8/12*'ОПУ БС'!R8 -> 20603.834 | J8: ='ОПУ БС'!$C8/12*'ОПУ БС'!S8 -> 20070.976 | ... N8: ='ОПУ БС'!$C8/12*'ОПУ БС'!W8 -> 22202.407 | O8: =SUM(C8:N8) -> 213143.11 | P8: ='ОПУ БС'!$D8/12*'ОПУ БС'!L8 -> 15896.657 | Q8: ='ОПУ БС'!$D8/12*'ОПУ БС'!M8 -> 17360.823 | R8: ='ОПУ БС'!$D8/12*'ОПУ БС'!N8 -> 19452.488 | S8: ='ОПУ БС'!$D8/12*'ОПУ БС'!O8 -> 19452.488 | T8: ='ОПУ БС'!$D8/12*'ОПУ БС'!P8 -> 19870.822 | U8: ='ОПУ БС'!$D8/12*'ОПУ БС'!Q8 -> 21125.821 | V8: ='ОПУ БС'!$D8/12*'ОПУ БС'!R8 -> 24263.319 | W8: ='ОПУ БС'!$D8/12*'ОПУ БС'!S8 -> 23635.819 | ... AA8: ='ОПУ БС'!$D8/12*'ОПУ БС'!W8 -> 26145.818 | AB8: =SUM(P8:AA8) -> 250999.85 | AC8: ='ОПУ БС'!$E8/12*'ОПУ БС'!L8 -> 20010.13 | AD8: ='ОПУ БС'!$E8/12*'ОПУ БС'!M8 -> 21853.169 | AE8: ='ОПУ БС'!$E8/12*'ОПУ БС'!N8 -> 24486.08 | AF8: ='ОПУ БС'!$E8/12*'ОПУ БС'!O8 -> 24486.08 | AG8: ='ОПУ БС'!$E8/12*'ОПУ БС'!P8 -> 25012.663 | AH8: ='ОПУ БС'!$E8/12*'ОПУ БС'!Q8 -> 26592.41 | AI8: ='ОПУ БС'!$E8/12*'ОПУ БС'!R8 -> 30541.778 | AJ8: ='ОПУ БС'!$E8/12*'ОПУ БС'!S8 -> 29751.904 | ... AN8: ='ОПУ БС'!$E8/12*'ОПУ БС'!W8 -> 32911.398 | AO8: =SUM(AC8:AN8) -> 315949.42 | AP8: ='ОПУ БС'!$F8/12*'ОПУ БС'!L8 -> 26304.449 | AQ8: ='ОПУ БС'!$F8/12*'ОПУ БС'!M8 -> 28727.228 | AR8: ='ОПУ БС'!$F8/12*'ОПУ БС'!N8 -> 32188.339 | AS8: ='ОПУ БС'!$F8/12*'ОПУ БС'!O8 -> 32188.339 | AT8: ='ОПУ БС'!$F8/12*'ОПУ БС'!P8 -> 32880.562 | AU8: ='ОПУ БС'!$F8/12*'ОПУ БС'!Q8 -> 34957.229 | AV8: ='ОПУ БС'!$F8/12*'ОПУ БС'!R8 -> 40148.896 | AW8: ='ОПУ БС'!$F8/12*'ОПУ БС'!S8 -> 39110.563 | ... BA8: ='ОПУ БС'!$F8/12*'ОПУ БС'!W8 -> 43263.897 | BB8: =SUM(AP8:BA8) -> 415333.41 | BC8: ='ОПУ БС'!$G8/12*'ОПУ БС'!L8 -> 35878.576 | BD8: ='ОПУ БС'!$G8/12*'ОПУ БС'!M8 -> 39183.182 | BE8: ='ОПУ БС'!$G8/12*'ОПУ БС'!N8 -> 43904.047 | BF8: ='ОПУ БС'!$G8/12*'ОПУ БС'!O8 -> 43904.047 | BG8: ='ОПУ БС'!$G8/12*'ОПУ БС'!P8 -> 44848.22 | BH8: ='ОПУ БС'!$G8/12*'ОПУ БС'!Q8 -> 47680.739 | BI8: ='ОПУ БС'!$G8/12*'ОПУ БС'!R8 -> 54762.037 | BJ8: ='ОПУ БС'!$G8/12*'ОПУ БС'!S8 -> 53345.777 | ... BN8: ='ОПУ БС'!$G8/12*'ОПУ БС'!W8 -> 59010.816 | BO8: =SUM(BC8:BN8) -> 566503.83 | BP8: ='ОПУ БС'!$H8/12*'ОПУ БС'!L8 -> 50127.378 | BQ8: ='ОПУ БС'!$H8/12*'ОПУ БС'!M8 -> 54744.374 | BR8: ='ОПУ БС'!$H8/12*'ОПУ БС'!N8 -> 61340.081 | BS8: ='ОПУ БС'!$H8/12*'ОПУ БС'!O8 -> 61340.081 | BT8: ='ОПУ БС'!$H8/12*'ОПУ БС'!P8 -> 62659.223 | BU8: ='ОПУ БС'!$H8/12*'ОПУ БС'!Q8 -> 66616.647 | BV8: ='ОПУ БС'!$H8/12*'ОПУ БС'!R8 -> 76510.209 | BW8: ='ОПУ БС'!$H8/12*'ОПУ БС'!S8 -> 74531.497 | ... CA8: ='ОПУ БС'!$H8/12*'ОПУ БС'!W8 -> 82446.346 | CB8: =SUM(BP8:CA8) -> 791484.92 | CC8: ='ОПУ БС'!$I8/12*'ОПУ БС'!L8 -> 70642.367 | CD8: ='ОПУ БС'!$I8/12*'ОПУ БС'!M8 -> 77148.901 | CE8: ='ОПУ БС'!$I8/12*'ОПУ БС'!N8 -> 86443.949 | CF8: ='ОПУ БС'!$I8/12*'ОПУ БС'!O8 -> 86443.949 | CG8: ='ОПУ БС'!$I8/12*'ОПУ БС'!P8 -> 88302.958 | CH8: ='ОПУ БС'!$I8/12*'ОПУ БС'!Q8 -> 93879.987 | CI8: ='ОПУ БС'!$I8/12*'ОПУ БС'!R8 -> 107822.56 | CJ8: ='ОПУ БС'!$I8/12*'ОПУ БС'!S8 -> 105034.05 | ... CN8: ='ОПУ БС'!$I8/12*'ОПУ БС'!W8 -> 116188.1 | CO8: =SUM(CC8:CN8) -> 1115405.8 | CR8: =O8-'ОПУ БС'!C8 -> 0 | CS8: =AB8-'ОПУ БС'!D8 -> 0 | CT8: =AO8-'ОПУ БС'!E8 -> 0 | CU8: =BB8-'ОПУ БС'!F8 -> 0 | CV8: =BO8-'ОПУ БС'!G8 -> 0 | CW8: =CB8-'ОПУ БС'!H8 -> 0 | CX8: =CO8-'ОПУ БС'!I8 -> 0 | DM8: =SUM(DA8:DL8) -> 0 | DZ8: =SUM(DN8:DY8) -> 0 | EM8: =SUM(EA8:EL8) -> 0 | EZ8: =SUM(EN8:EY8) -> 0 | FM8: =SUM(FA8:FL8) -> 0 | FP8: =C8 -> 13499.063 | FQ8: =D8 -> 14742.398 | FR8: =E8 -> 16518.591 | FS8: =F8 -> 16518.591 | FT8: =G8 -> 16873.829 | FU8: =H8 -> 17939.545 | FV8: =I8 -> 20603.834 | FW8: =J8 -> 20070.976 | ... GA8: =N8 -> 22202.407 | GB8: =SUM(FP8:GA8) -> 213143.11 | GC8: =P8 -> 15896.657 | GD8: =Q8 -> 17360.823 | GE8: =R8 -> 19452.488 | GF8: =S8 -> 19452.488 | GG8: =T8 -> 19870.822 | GH8: =U8 -> 21125.821 | GI8: =V8 -> 24263.319 | GJ8: =W8 -> 23635.819 | ... GN8: =AA8 -> 26145.818 | GO8: =SUM(GC8:GN8) -> 250999.85 | GP8: =AC8+DA8 -> 20010.13 | GQ8: =AD8+DB8 -> 21853.169 | GR8: =AE8+DC8 -> 24486.08 | GS8: =AF8+DD8 -> 24486.08 | GT8: =AG8+DE8 -> 25012.663 | GU8: =AH8+DF8 -> 26592.41 | GV8: =AI8+DG8 -> 30541.778 | GW8: =AJ8+DH8 -> 29751.904 | ... HA8: =AN8+DL8 -> 32911.398 | HB8: =SUM(GP8:HA8) -> 315949.42 | HC8: =AP8+DN8 -> 26304.449 | HD8: =AQ8+DO8 -> 28727.228 | HE8: =AR8+DP8 -> 32188.339 | HF8: =AS8+DQ8 -> 32188.339 | HG8: =AT8+DR8 -> 32880.562 | HH8: =AU8+DS8 -> 34957.229 | HI8: =AV8+DT8 -> 40148.896 | HJ8: =AW8+DU8 -> 39110.563 | ... HN8: =BA8+DY8 -> 43263.897 | HO8: =SUM(HC8:HN8) -> 415333.41 | HP8: =BC8+EA8 -> 35878.576 | HQ8: =BD8+EB8 -> 39183.182 | HR8: =BE8+EC8 -> 43904.047 | HS8: =BF8+ED8 -> 43904.047 | HT8: =BG8+EE8 -> 44848.22 | HU8: =BH8+EF8 -> 47680.739 | HV8: =BI8+EG8 -> 54762.037 | HW8: =BJ8+EH8 -> 53345.777 | ... IA8: =BN8+EL8 -> 59010.816 | IB8: =SUM(HP8:IA8) -> 566503.83 | IC8: =BP8+EN8 -> 50127.378 | ID8: =BQ8+EO8 -> 54744.374 | IE8: =BR8+EP8 -> 61340.081 | IF8: =BS8+EQ8 -> 61340.081 | IG8: =BT8+ER8 -> 62659.223 | IH8: =BU8+ES8 -> 66616.647 | II8: =BV8+ET8 -> 76510.209 | IJ8: =BW8+EU8 -> 74531.497 | ... IN8: =CA8+EY8 -> 82446.346 | IO8: =SUM(IC8:IN8) -> 791484.92 | IP8: =CC8+FA8 -> 70642.367 | IQ8: =CD8+FB8 -> 77148.901 | IR8: =CE8+FC8 -> 86443.949 | IS8: =CF8+FD8 -> 86443.949 | IT8: =CG8+FE8 -> 88302.958 | IU8: =CH8+FF8 -> 93879.987 | IV8: =CI8+FG8 -> 107822.56 | IW8: =CJ8+FH8 -> 105034.05 | ... JA8: =CN8+FL8 -> 116188.1 | JB8: =SUM(IP8:JA8) -> 1115405.8 | JE8: =O8-GB8 -> 0 | JF8: =AB8-GO8 -> 0 | JG8: =AO8+DM8-HB8 -> 0 | JH8: =BB8+DZ8-HO8 -> 0 | JI8: =BO8+EM8-IB8 -> 0 | JJ8: =CB8+EZ8-IO8 -> 0 | JK8: =CO8+FM8-JB8 -> 0
B9: Острые | C9: ='ОПУ БС'!$C9/12*'ОПУ БС'!L9 -> 10674.219 | D9: ='ОПУ БС'!$C9/12*'ОПУ БС'!M9 -> 12078.722 | E9: ='ОПУ БС'!$C9/12*'ОПУ БС'!N9 -> 13061.873 | F9: ='ОПУ БС'!$C9/12*'ОПУ БС'!O9 -> 13061.873 | G9: ='ОПУ БС'!$C9/12*'ОПУ БС'!P9 -> 13342.774 | H9: ='ОПУ БС'!$C9/12*'ОПУ БС'!Q9 -> 14185.475 | I9: ='ОПУ БС'!$C9/12*'ОПУ БС'!R9 -> 16292.229 | J9: ='ОПУ БС'!$C9/12*'ОПУ БС'!S9 -> 15870.878 | ... N9: ='ОПУ БС'!$C9/12*'ОПУ БС'!W9 -> 17556.281 | O9: =SUM(C9:N9) -> 168540.3 | P9: ='ОПУ БС'!$D9/12*'ОПУ БС'!L9 -> 12189.277 | Q9: ='ОПУ БС'!$D9/12*'ОПУ БС'!M9 -> 13793.129 | R9: ='ОПУ БС'!$D9/12*'ОПУ БС'!N9 -> 14915.826 | S9: ='ОПУ БС'!$D9/12*'ОПУ БС'!O9 -> 14915.826 | T9: ='ОПУ БС'!$D9/12*'ОПУ БС'!P9 -> 15236.596 | U9: ='ОПУ БС'!$D9/12*'ОПУ БС'!Q9 -> 16198.908 | V9: ='ОПУ БС'!$D9/12*'ОПУ БС'!R9 -> 18604.686 | W9: ='ОПУ БС'!$D9/12*'ОПУ БС'!S9 -> 18123.53 | ... AA9: ='ОПУ БС'!$D9/12*'ОПУ БС'!W9 -> 20048.153 | AB9: =SUM(P9:AA9) -> 192462.27 | AC9: ='ОПУ БС'!$E9/12*'ОПУ БС'!L9 -> 14910.819 | AD9: ='ОПУ БС'!$E9/12*'ОПУ БС'!M9 -> 16872.769 | AE9: ='ОПУ БС'!$E9/12*'ОПУ БС'!N9 -> 18246.134 | AF9: ='ОПУ БС'!$E9/12*'ОПУ БС'!O9 -> 18246.134 | AG9: ='ОПУ БС'!$E9/12*'ОПУ БС'!P9 -> 18638.524 | AH9: ='ОПУ БС'!$E9/12*'ОПУ БС'!Q9 -> 19815.694 | AI9: ='ОПУ БС'!$E9/12*'ОПУ БС'!R9 -> 22758.619 | AJ9: ='ОПУ БС'!$E9/12*'ОПУ БС'!S9 -> 22170.034 | ... AN9: ='ОПУ БС'!$E9/12*'ОПУ БС'!W9 -> 24524.374 | AO9: =SUM(AC9:AN9) -> 235433.99 | AP9: ='ОПУ БС'!$F9/12*'ОПУ БС'!L9 -> 19036.084 | AQ9: ='ОПУ БС'!$F9/12*'ОПУ БС'!M9 -> 21540.832 | AR9: ='ОПУ БС'!$F9/12*'ОПУ БС'!N9 -> 23294.156 | AS9: ='ОПУ БС'!$F9/12*'ОПУ БС'!O9 -> 23294.156 | AT9: ='ОПУ БС'!$F9/12*'ОПУ БС'!P9 -> 23795.105 | AU9: ='ОПУ БС'!$F9/12*'ОПУ БС'!Q9 -> 25297.954 | AV9: ='ОПУ БС'!$F9/12*'ОПУ БС'!R9 -> 29055.076 | AW9: ='ОПУ БС'!$F9/12*'ОПУ БС'!S9 -> 28303.652 | ... BA9: ='ОПУ БС'!$F9/12*'ОПУ БС'!W9 -> 31309.349 | BB9: =SUM(AP9:BA9) -> 300569.75 | BC9: ='ОПУ БС'!$G9/12*'ОПУ БС'!L9 -> 25200.65 | BD9: ='ОПУ БС'!$G9/12*'ОПУ БС'!M9 -> 28516.525 | BE9: ='ОПУ БС'!$G9/12*'ОПУ БС'!N9 -> 30837.637 | BF9: ='ОПУ БС'!$G9/12*'ОПУ БС'!O9 -> 30837.637 | BG9: ='ОПУ БС'!$G9/12*'ОПУ БС'!P9 -> 31500.812 | BH9: ='ОПУ БС'!$G9/12*'ОПУ БС'!Q9 -> 33490.337 | BI9: ='ОПУ БС'!$G9/12*'ОПУ БС'!R9 -> 38464.149 | BJ9: ='ОПУ БС'!$G9/12*'ОПУ БС'!S9 -> 37469.387 | ... BN9: ='ОПУ БС'!$G9/12*'ОПУ БС'!W9 -> 41448.437 | BO9: =SUM(BC9:BN9) -> 397904.99 | BP9: ='ОПУ БС'!$H9/12*'ОПУ БС'!L9 -> 34152.822 | BQ9: ='ОПУ БС'!$H9/12*'ОПУ БС'!M9 -> 38646.614 | BR9: ='ОПУ БС'!$H9/12*'ОПУ БС'!N9 -> 41792.269 | BS9: ='ОПУ БС'!$H9/12*'ОПУ БС'!O9 -> 41792.269 | BT9: ='ОПУ БС'!$H9/12*'ОПУ БС'!P9 -> 42691.027 | BU9: ='ОПУ БС'!$H9/12*'ОПУ БС'!Q9 -> 45387.303 | BV9: ='ОПУ БС'!$H9/12*'ОПУ БС'!R9 -> 52127.991 | BW9: ='ОПУ БС'!$H9/12*'ОПУ БС'!S9 -> 50779.854 | ... CA9: ='ОПУ БС'!$H9/12*'ОПУ БС'!W9 -> 56172.404 | CB9: =SUM(BP9:CA9) -> 539255.08 | CC9: ='ОПУ БС'!$I9/12*'ОПУ БС'!L9 -> 46661.286 | CD9: ='ОПУ БС'!$I9/12*'ОПУ БС'!M9 -> 52800.929 | CE9: ='ОПУ БС'!$I9/12*'ОПУ БС'!N9 -> 57098.679 | CF9: ='ОПУ БС'!$I9/12*'ОПУ БС'!O9 -> 57098.679 | CG9: ='ОПУ БС'!$I9/12*'ОПУ БС'!P9 -> 58326.608 | CH9: ='ОПУ БС'!$I9/12*'ОПУ БС'!Q9 -> 62010.394 | CI9: ='ОПУ БС'!$I9/12*'ОПУ БС'!R9 -> 71219.858 | CJ9: ='ОПУ БС'!$I9/12*'ОПУ БС'!S9 -> 69377.965 | ... CN9: ='ОПУ БС'!$I9/12*'ОПУ БС'!W9 -> 76745.537 | CO9: =SUM(CC9:CN9) -> 736757.15 | CR9: =O9-'ОПУ БС'!C9 -> 0 | CS9: =AB9-'ОПУ БС'!D9 -> 0 | CT9: =AO9-'ОПУ БС'!E9 -> 0 | CU9: =BB9-'ОПУ БС'!F9 -> 0 | CV9: =BO9-'ОПУ БС'!G9 -> 0 | CW9: =CB9-'ОПУ БС'!H9 -> 0 | CX9: =CO9-'ОПУ БС'!I9 -> 0 | DM9: =SUM(DA9:DL9) -> 0 | DZ9: =SUM(DN9:DY9) -> 0 | EM9: =SUM(EA9:EL9) -> 0 | EZ9: =SUM(EN9:EY9) -> 0 | FM9: =SUM(FA9:FL9) -> 0 | FP9: =C9 -> 10674.219 | FQ9: =D9 -> 12078.722 | FR9: =E9 -> 13061.873 | FS9: =F9 -> 13061.873 | FT9: =G9 -> 13342.774 | FU9: =H9 -> 14185.475 | FV9: =I9 -> 16292.229 | FW9: =J9 -> 15870.878 | ... GA9: =N9 -> 17556.281 | GB9: =SUM(FP9:GA9) -> 168540.3 | GC9: =P9 -> 12189.277 | GD9: =Q9 -> 13793.129 | GE9: =R9 -> 14915.826 | GF9: =S9 -> 14915.826 | GG9: =T9 -> 15236.596 | GH9: =U9 -> 16198.908 | GI9: =V9 -> 18604.686 | GJ9: =W9 -> 18123.53 | ... GN9: =AA9 -> 20048.153 | GO9: =SUM(GC9:GN9) -> 192462.27 | GP9: =AC9+DA9 -> 14910.819 | GQ9: =AD9+DB9 -> 16872.769 | GR9: =AE9+DC9 -> 18246.134 | GS9: =AF9+DD9 -> 18246.134 | GT9: =AG9+DE9 -> 18638.524 | GU9: =AH9+DF9 -> 19815.694 | GV9: =AI9+DG9 -> 22758.619 | GW9: =AJ9+DH9 -> 22170.034 | ... HA9: =AN9+DL9 -> 24524.374 | HB9: =SUM(GP9:HA9) -> 235433.99 | HC9: =AP9+DN9 -> 19036.084 | HD9: =AQ9+DO9 -> 21540.832 | HE9: =AR9+DP9 -> 23294.156 | HF9: =AS9+DQ9 -> 23294.156 | HG9: =AT9+DR9 -> 23795.105 | HH9: =AU9+DS9 -> 25297.954 | HI9: =AV9+DT9 -> 29055.076 | HJ9: =AW9+DU9 -> 28303.652 | ... HN9: =BA9+DY9 -> 31309.349 | HO9: =SUM(HC9:HN9) -> 300569.75 | HP9: =BC9+EA9 -> 25200.65 | HQ9: =BD9+EB9 -> 28516.525 | HR9: =BE9+EC9 -> 30837.637 | HS9: =BF9+ED9 -> 30837.637 | HT9: =BG9+EE9 -> 31500.812 | HU9: =BH9+EF9 -> 33490.337 | HV9: =BI9+EG9 -> 38464.149 | HW9: =BJ9+EH9 -> 37469.387 | ... IA9: =BN9+EL9 -> 41448.437 | IB9: =SUM(HP9:IA9) -> 397904.99 | IC9: =BP9+EN9 -> 34152.822 | ID9: =BQ9+EO9 -> 38646.614 | IE9: =BR9+EP9 -> 41792.269 | IF9: =BS9+EQ9 -> 41792.269 | IG9: =BT9+ER9 -> 42691.027 | IH9: =BU9+ES9 -> 45387.303 | II9: =BV9+ET9 -> 52127.991 | IJ9: =BW9+EU9 -> 50779.854 | ... IN9: =CA9+EY9 -> 56172.404 | IO9: =SUM(IC9:IN9) -> 539255.08 | IP9: =CC9+FA9 -> 46661.286 | IQ9: =CD9+FB9 -> 52800.929 | IR9: =CE9+FC9 -> 57098.679 | IS9: =CF9+FD9 -> 57098.679 | IT9: =CG9+FE9 -> 58326.608 | IU9: =CH9+FF9 -> 62010.394 | IV9: =CI9+FG9 -> 71219.858 | IW9: =CJ9+FH9 -> 69377.965 | ... JA9: =CN9+FL9 -> 76745.537 | JB9: =SUM(IP9:JA9) -> 736757.15 | JE9: =O9-GB9 -> 0 | JF9: =AB9-GO9 -> 0 | JG9: =AO9+DM9-HB9 -> 0 | JH9: =BB9+DZ9-HO9 -> 0 | JI9: =BO9+EM9-IB9 -> 0 | JJ9: =CB9+EZ9-IO9 -> 0 | JK9: =CO9+FM9-JB9 -> 0
