Workbook

Sheet Последовательность расчётов
B2: Последовательность расчётов
B3: [1] | C3: На листе «План-Факт» рассчитайте отклонения фактических показателей от плановых в абсолютных и относительных значениях.
B4: [2] | C4: Проанализируйте, какие выводы можно сделать на данном этапе.
B5: [3] | C5: На листе «Свод факта» рассчитайте отклонения фактических показателей от плановых.
B6: [4] | C6: Проанализируйте, какие выводы можно сделать на данном этапе.
B7: [5] | C7: Сделайте свод данных на листах «Выгрузка персонал», «Выгрузка оборудование» и «Выгрузка лицензии» и сравните получившиеся результаты с данными на листе «Свод факта».
B8: [6] | C8: Добавьте недостающие данные из выгрузок на лист «Свод факта».
B9: [7] | C9: Сделайте выводы на листе «Свод факта» и «План-факт», добавьте предложения по доработке бюджетной модели для минимизации отклонений в будущем.
B10: [8] | C10: В отдельном pptx-файле сформируйте для руководства Kihi презентацию по результатам работы новых направлений. Дополнитеные таблицы / расчёты для презентации по необходимости формируйте на листе «Для презентации».

Sheet Для презентации
B2: Community | D2: Education | Q2: Подсказку? | U2: Да
B3: План | C3: Факт | D3: План | E3: Факт
A4: Расходы на персонал | B4: =Расчеты!O63 -> 6048 | C4: ='Свод факта'!O94 -> 6296 | D4: =Расчеты!O69 -> 11892 | E4: ='Свод факта'!O100 -> 13385.2 | Q4: Нет | R4: =IF(Q4="Нет", " ", "На первом слайде обычно показывают общую картину - заберите таблицу с результатами анализа с листа План-факт.") | U4: Нет
Q5: Нет
Q6: Нет | R6: =IF(Q6="Нет", " ", "Сделайте выводы и дайте рекомендации.")
B7: Education | Q7: Нет | R7: =IF(Q7="Нет", " ", "Подумайте, что может сделать подразделение маркетинга на основании отчета?")
B8: План | C8: Факт | Q8: Нет | R8: =IF(Q8="Нет", " ", "Подумайте, что могут сделать подразделения поддержки Community и Education на основании отчета?")
A9: Расходы на лицензии | B9: =Расчеты!O184 -> 960 | C9: ='Свод факта'!O247 -> 1704.2816 | Q9: Нет | R9: =IF(Q9="Нет", " ", "Подумайте, что может сделать подразделение, отвечающее за контент направления Education?")
Q10: Нет | R10: =IF(Q10="Нет", " ", "Если все вышеозвученные подразделения внесут свой вклад, нужно ли будет что-то ещё делать подразделению финансов?")
A11: Расходы на оборудование | Q11: Нет | R11: =IF(Q11="Нет", " ", "Не перегружайте презентацию ненужной для менеджмента информацией. Выводы о необходимости доработки бюджетной модели лучше оставить внутри подразделения финансов.")
B14: Итого новые проекты | E14: Community | H14: Education
A15: Тыс. Руб. | B15: Факт | C15: План | D15: Δ (±) | E15: Факт | F15: План | G15: Δ (±) | H15: Факт | I15: План | J15: Δ (±)
A16: Валовая прибыль | B16: -7878 | C16: -7012 | D16: -866 | E16: -7094 | F16: -6057 | G16: -1037 | H16: -784 | I16: -955 | J16: 171
A17: Операционные расходы | B17: 8663 | C17: 8974 | D17: -311 | E17: 3600 | F17: 3745 | G17: -145 | H17: 3600 | I17: 3802 | J17: -202
A18: Операционная прибыль | B18: -16541 | C18: -15987 | D18: -554 | E18: -10694 | F18: -9802 | G18: -892 | H18: -4384 | I18: -4757 | J18: 373
A19: Чистая прибыль | B19: -16541 | C19: -15987 | D19: -554 | E19: -10694 | F19: -9802 | G19: -892 | H19: -4384 | I19: -4757 | J19: 373

Sheet Факт-->

Sheet План-Факт
B2: Таблица 1. Отчёт о прибылях и убытках, тыс. руб. | R2: Подсказку? | V2: Да
C3: Итого новые проекты | H3: Community | M3: Education | V3: Нет
C4: Факт | D4: План | E4: Δ | F4: Δ, % | H4: Факт | I4: План | J4: Δ | K4: Δ, % | M4: Факт | N4: План | O4: Δ | P4: Δ, % | R4: Нет | S4: =IF(R4="Нет", " ", "Δ = Факт - План. Δ, % = (Факт - План) / План * 100% ")
B5: Выручка | C5: =H5+M5 -> 21796.6 | D5: =Бюджет!C5 -> 20487.56 | E5: =C5-D5 -> 1309.04 | F5: =(C5-D5)/D5*100% -> 0.06389438 | H5: ='Свод факта'!O10 -> 4057.4333 | I5: =Бюджет!F5 -> 4840.5369 | J5: =H5-I5 -> -783.10353 | K5: =(H5-I5)/I5*100% -> -0.1617803 | M5: ='Свод факта'!O16 -> 17739.167 | N5: =Бюджет!I5 -> 15647.023 | O5: =M5-N5 -> 2092.1435 | P5: =(M5-N5)/N5*100% -> 0.13370872
B6: Себестоимость | C6: =H6+M6 -> 29674.634 | D6: =Бюджет!C6 -> 27500 | E6: =C6-D6 -> 2174.6338 | F6: =(C6-D6)/D6*100% -> 0.079077592 | H6: ='Свод факта'!O88+'Свод факта'!O94+'Свод факта'!O235+'Свод факта'!O242 -> 11151.819 | I6: =Бюджет!F6 -> 10898 | J6: =H6-I6 -> 253.81885 | K6: =(H6-I6)/I6*100% -> 0.023290406 | M6: ='Свод факта'!O89+'Свод факта'!O100+'Свод факта'!O236+'Свод факта'!O247 -> 18522.815 | N6: =Бюджет!I6 -> 16602 | O6: =M6-N6 -> 1920.8149 | P6: =(M6-N6)/N6*100% -> 0.1156978
B7: Валовая прибыль | C7: =C5-C6 -> -7878.0338 | D7: =Бюджет!C7 -> -7012.44 | E7: =C7-D7 -> -865.59383 | F7: =(C7-D7)/D7*100% -> 0.1234369 | H7: =H5-H6 -> -7094.3855 | I7: =Бюджет!F7 -> -6057.4631 | J7: =H7-I7 -> -1036.9224 | K7: =(H7-I7)/I7*100% -> 0.17118096 | M7: =M5-M6 -> -783.64827 | N7: =Бюджет!I7 -> -954.97681 | O7: =M7-N7 -> 171.32855 | P7: =(M7-N7)/N7*100% -> -0.17940598
B8: Валовая прибыль, % | C8: =C7/C5 -> -0.36143407 | D8: =Бюджет!C8 -> -0.34227795 | E8: =C8-D8 -> -0.019156122 | F8: =C8-D8 -> -0.019156122 | H8: =H7/H5 -> -1.748491 | I8: =Бюджет!F8 -> -1.2514032 | K8: =H8-I8 -> -0.4970878 | M8: =M7/M5 -> -0.04417616 | N8: =Бюджет!I8 -> -0.061032492 | P8: =M8-N8 -> 0.016856332
B9: Операционные расходы | C9: =SUM(C10:C14) -> 8663.0022 | D9: =Бюджет!C9 -> 8974.13 | E9: =C9-D9 -> -311.12782 | F9: =(C9-D9)/D9*100% -> -0.034669413 | H9: =SUM(H10:H14) -> 3600 | I9: =Бюджет!F9 -> 3744.98 | J9: =H9-I9 -> -144.98 | K9: =(H9-I9)/I9*100% -> -0.038713157 | M9: =SUM(M10:M14) -> 3600 | N9: =Бюджет!I9 -> 3802.02 | O9: =M9-N9 -> -202.02 | P9: =(M9-N9)/N9*100% -> -0.053134912
B10: Расходы на персонал | C10: ='Свод факта'!O105 -> 697.6 | D10: =Бюджет!C10 -> 648 | E10: =C10-D10 -> 49.6 | F10: =(C10-D10)/D10*100% -> 0.07654321 | H10: 0 | I10: =Бюджет!F10 -> 0 | J10: =H10-I10 -> 0 | K10: 0 | M10: 0 | N10: =Бюджет!I10 -> 0 | O10: =M10-N10 -> 0 | P10: 0
B11: Аренда | C11: ='Свод факта'!O222 -> 675 | D11: =Бюджет!C11 -> 675 | E11: =C11-D11 -> 0 | F11: 0 | H11: 0 | I11: =Бюджет!F11 -> 0 | J11: =H11-I11 -> 0 | K11: 0 | M11: 0 | N11: =Бюджет!I11 -> 0 | O11: =M11-N11 -> 0 | P11: 0
B12: Реклама и маркетинг | C12: =H12+M12 -> 7200 | D12: =Бюджет!C12 -> 7200 | E12: =C12-D12 -> 0 | F12: 0 | H12: ='Свод факта'!O229 -> 3600 | I12: =Бюджет!F12 -> 3600 | J12: =H12-I12 -> 0 | K12: 0 | M12: ='Свод факта'!O230 -> 3600 | N12: =Бюджет!I12 -> 3600 | O12: =M12-N12 -> 0 | P12: 0
B13: Оборудование, лицензии и ПО | C13: =H13+M13+'Свод факта'!O237+'Свод факта'!O252 -> 90.40218 | D13: =Бюджет!C13 -> 90 | E13: =C13-D13 -> 0.40218 | F13: 0 | H13: 0 | I13: =Бюджет!F13 -> 0 | J13: =H13-I13 -> 0 | K13: 0 | M13: 0 | N13: =Бюджет!I13 -> 0 | O13: =M13-N13 -> 0 | P13: 0
B14: Прочие и непредвиденные расходы | C14: 0 | D14: =Бюджет!C14 -> 361.13 | E14: =C14-D14 -> -361.13 | F14: =(C14-D14)/D14*100% -> -1 | H14: 0 | I14: =Бюджет!F14 -> 144.98 | J14: =H14-I14 -> -144.98 | K14: =(H14-I14)/I14*100% -> -1 | M14: 0 | N14: =Бюджет!I14 -> 202.02 | O14: =M14-N14 -> -202.02 | P14: =(M14-N14)/N14*100% -> -1
B15: Операционная прибыль | C15: =C7-C9 -> -16541.036 | D15: =Бюджет!C15 -> -15986.57 | E15: =C15-D15 -> -554.46601 | F15: =(C15-D15)/D15*100% -> 0.034683238 | H15: =H7-H9 -> -10694.386 | I15: =Бюджет!F15 -> -9802.4431 | J15: =H15-I15 -> -891.94238 | K15: =(H15-I15)/I15*100% -> 0.090991844 | M15: =M7-M9 -> -4383.6483 | N15: =Бюджет!I15 -> -4756.9968 | O15: =M15-N15 -> 373.34855 | P15: =(M15-N15)/N15*100% -> -0.078484086
B16: Операционная прибыль, % | C16: =C15/C5 -> -0.75888148 | D16: =Бюджет!C16 -> -0.78030619 | F16: =C16-D16 -> 0.021424716 | H16: =H15/H5 -> -2.6357514 | I16: =Бюджет!F16 -> -2.0250735 | K16: =H16-I16 -> -0.61067784 | M16: =M15/M5 -> -0.24711692 | N16: =Бюджет!I16 -> -0.30401929 | P16: =M16-N16 -> 0.056902364
B17: Налог на прибыль | C17: =IF(C15>0, C15*25%, 0) -> 0 | D17: =Бюджет!C17 -> 0 | E17: =C17-D17 -> 0 | F17: 0 | H17: 0 | I17: =Бюджет!F17 -> 0 | J17: =H17-I17 -> 0 | K17: 0 | M17: 0 | N17: =Бюджет!I17 -> 0 | O17: 0 | P17: 0
B18: Чистая прибыль | C18: =C15-C17 -> -16541.036 | D18: =Бюджет!C18 -> -15986.57 | E18: =C18-D18 -> -554.46601 | F18: =(C18-D18)/D18*100% -> 0.034683238 | H18: =H15-H17 -> -10694.386 | I18: =Бюджет!F18 -> -9802.4431 | J18: =H18-I18 -> -891.94238 | K18: =(H18-I18)/I18*100% -> 0.090991844 | M18: =M15-M17 -> -4383.6483 | N18: =Бюджет!I18 -> -4756.9968 | O18: =M18-N18 -> 373.34855 | P18: =(M18-N18)/N18*100% -> -0.078484086
B19: Чистая прибыль, % | C19: =C18/C5 -> -0.75888148 | D19: =Бюджет!C19 -> -0.78030619 | F19: =C19-D19 -> 0.021424716 | H19: =H18/H5 -> -2.6357514 | I19: =Бюджет!F19 -> -2.0250735 | K19: =H19-I19 -> -0.61067784 | M19: =M18/M5 -> -0.24711692 | N19: =Бюджет!I19 -> -0.30401929 | P19: =M19-N19 -> 0.056902364
B21: Выводы | R21: Да | S21: =IF(R21="Нет", " ", "Для формирование полных выводов проведите детальный анализ отклонений на листе Свод факта.") -> Для формирование полных выводов проведите детальный анализ отклонений на листе Свод факта.
B22: План по чистой прибыли по новым направлениям в целом за 2026 год не выполнен, убытки выше плановых (в абсолютном отклонении -554, в относиельном на 3%) | R22: Да | S22: =IF(R22="Нет", " ", "Проверьте, выполнен ли план по чистой прибыли в по новым направлениям в целом за 2026 год? Сделайте вывод.") -> Проверьте, выполнен ли план по чистой прибыли в по новым направлениям в целом за 2026 год? Сделайте вывод.
B23: По направлению Education план перевыполнен - убыток меньше плана в относительном отклонении на 8% | R23: Да | S23: =IF(R23="Нет", " ", "Проверьте, выполнен ли план по чистой прибыли Community и Education за 2026 год? Сделайте вывод.") -> Проверьте, выполнен ли план по чистой прибыли Community и Education за 2026 год? Сделайте вывод.
B24: По направлению Community недовыполнение, убытки выше плановых в относительном отклонении на 9% | R24: Да | S24: =IF(R24="Нет", " ", "Выполнен ли план по количеству привлечённых пользователей? Сделай вывод о выполнении/невыполнении плана.") -> Выполнен ли план по количеству привлечённых пользователей? Сделай вывод о выполнении/невыполнении плана.
B25: Community: план по привлечению пользователей не выполнен по всем категориям. Наибольший разрыв — в «Подписке на месяц» и «Пакете на 3 месяца». Основная причина — более медленный рост фактического числа пользователей по сравнению с амбициозным планом. | R25: Да | S25: =IF(R25="Нет", " ", "Были ли учтены выбывающие клиенты в бюджетной модели? Сделай вывод.") -> Были ли учтены выбывающие клиенты в бюджетной модели? Сделай вывод.
B26: Education: план перевыполнен в большинстве категорий, кроме «Фритрек». Успех в привлечении пользователей с различными моделями оплаты. | R26: Да | S26: =IF(R26="Нет", " ", "Соответствует ли фактический уровень продаж плановому? Сделай вывод.") -> Соответствует ли фактический уровень продаж плановому? Сделай вывод.
B27: Выбывающие клиенты, вероятно, не были учтены в полной мере. План строился на предположении стабильного или растущего числа клиентов, без поправки на отток | R27: Да | S27: =IF(R27="Нет", " ", "Были ли учтены в плане компенсации по питанию в расходах на персонал? Сделай вывод.") -> Были ли учтены в плане компенсации по питанию в расходах на персонал? Сделай вывод.
B28: Фактический уровень продаж не соотвествует плановому, по табл Уровень Проникновения Продаж сделаны расчеты для наглядности | R28: Да | S28: =IF(R28="Нет", " ", "Было ли учтено в плане влияние курса доллара на стоимость лицензий? Сделай вывод.") -> Было ли учтено в плане влияние курса доллара на стоимость лицензий? Сделай вывод.
B29: В плане не была учтена такая статья расходов как компенсация по питанию, обязательно включить этот пункт в бюджетирование с учётом среднего чека и числа сотрудников | R29: Да | S29: =IF(R29="Нет", " ", "Оправдались ли ожидания по количеству сотрудников? Сделай вывод.") -> Оправдались ли ожидания по количеству сотрудников? Сделай вывод.
B30: Изменение курса доллара не было учтено при планировании при оплате за лицензии, что повлияло существенное повышение цены для новых кураторов | R30: Да | S30: =IF(R30="Нет", " ", "Был ли учтён при планировании период закупки оборудования по мере роста штата? Сделай вывод.") -> Был ли учтён при планировании период закупки оборудования по мере роста штата? Сделай вывод.
B31: Несогласованность темпов роста штата и закупок, когда новые сотрудники приходят, а необходимое оборудование (компьютеры, лицензии ПО, периферия) не готово, учтёно при планировании не было | R31: Да | S31: =IF(R31="Нет", " ", "Какие рекомендации на основе полученных выводов можно дать руководству компании?") -> Какие рекомендации на основе полученных выводов можно дать руководству компании?
B32: Рекомендации руководству улучшить синхронизацию отделов, организовать регулярные встречи (например, раз в неделю) между HR, IT-отделом и отделом закупок для согласования планов по росту штата и закупке оборудования | R32: Да | S32: =IF(R32="Нет", " ", "Из полученных выводов, как думаете, что нужно сделать для минимизации отклонений пана от факта в будущем?") -> Из полученных выводов, как думаете, что нужно сделать для минимизации отклонений пана от факта в будущем?
B33: Для каждой вакансии зафиксировать сроки закупки оборудования (например: ПК — за 3 недели до выхода сотрудника, лицензии ПО — за 1 неделю);
B34: Внедрить сценарное планирование, проводить регулярный анализ отклонений
B35: Для минимизации отклонений плана от факта нужно улучшить систему прогнозирования,
B36: Внедрить систему еженедельного/ежемесячного план-фактного анализа,
B37: Улучшить координацию между отделами, систему мотивации
B38: Анализировать причины отклонений, после каждого отчётного периода проводить 'разбор полётов'
B39: Учесть факторы риска и неопределённости

Sheet Свод факта
B2: Таблица 2. Количество дней в периоде, шт. | AP2: Выводы | AR2: Подсказку?
C3: янв.26 | D3: фев.26 | E3: мар.26 | F3: апр.26 | G3: 46143 | H3: июн.26 | I3: июл.26 | J3: авг.26 | K3: сент.26 | L3: окт.26 | M3: ноя.26 | N3: дек.26 | O3: 2026 | P3: янв.26 | Q3: фев.26 | R3: мар.26 | S3: апр.26 | T3: 46143 | U3: июн.26 | V3: июл.26 | W3: авг.26 | X3: сент.26 | Y3: окт.26 | Z3: ноя.26 | AA3: дек.26 | AB3: 2026
B4: всего | C4: 31 | D4: 28 | E4: 31 | F4: 30 | G4: 31 | H4: 30 | I4: 31 | J4: 31 | K4: 30 | L4: 31 | M4: 30 | N4: 31 | O4: =SUM(C4:N4) -> 365 | P4: 31 | Q4: 28 | R4: 31 | S4: 30 | T4: 31 | U4: 30 | V4: 31 | W4: 31 | X4: 30 | Y4: 31 | Z4: 30 | AA4: 31 | AB4: =SUM(P4:AA4) -> 365
B5: рабочих | C5: 15 | D5: 19 | E5: 21 | F5: 22 | G5: 19 | H5: 21 | I5: 23 | J5: 21 | K5: 22 | L5: 22 | M5: 20 | N5: 22 | O5: =SUM(C5:N5) -> 247 | P5: 15 | Q5: 19 | R5: 21 | S5: 22 | T5: 19 | U5: 21 | V5: 23 | W5: 21 | X5: 22 | Y5: 22 | Z5: 20 | AA5: 22 | AB5: =SUM(P5:AA5) -> 247
B7: Таблица 3. Выручка, тыс. руб. | I7: факт | P7: Δ (факт - план) | AR7: Нет | AS7: =IF(AR7="Нет", " ", "Δ факт/план = Факт - План. Плановые данные находятся на предпоследнем листе Расчёты")
C8: янв.26 | D8: фев.26 | E8: мар.26 | F8: апр.26 | G8: 46143 | H8: июн.26 | I8: июл.26 | J8: авг.26 | K8: сент.26 | L8: окт.26 | M8: ноя.26 | N8: дек.26 | O8: 2026 | P8: янв.26 | Q8: фев.26 | R8: мар.26 | S8: апр.26 | T8: 46143 | U8: июн.26 | V8: июл.26 | W8: авг.26 | X8: сент.26 | Y8: окт.26 | Z8: ноя.26 | AA8: дек.26 | AB8: 2026 | AR8: Нет | AS8: =IF(AR8="Нет", " ", "Для дальнейшего анализа рассчитайте план-факт отклонения по драйверам данного показателя.")
B10: Community | C10: =SUM(C11:C15) -> 0 | D10: =SUM(D11:D15) -> 70.516667 | E10: =SUM(E11:E15) -> 125.53333 | F10: =SUM(F11:F15) -> 183.53333 | G10: =SUM(G11:G15) -> 241.15 | H10: =SUM(H11:H15) -> 298.86667 | I10: =SUM(I11:I15) -> 361.25 | J10: =SUM(J11:J15) -> 427.53333 | ... N10: =SUM(N11:N15) -> 683.21667 | O10: =SUM(C10:N10) -> 4057.4333 | P10: =SUM(P11:P15) -> 0 | Q10: =SUM(Q11:Q15) -> 2.1833333 | R10: =SUM(R11:R15) -> -12.295 | S10: =SUM(S11:S15) -> -24.971415 | T10: =SUM(T11:T15) -> -39.232662 | U10: =SUM(U11:U15) -> -54.615834 | V10: =SUM(V11:V15) -> -68.805313 | W10: =SUM(W11:W15) -> -82.732766 | ... AA10: =SUM(AA11:AA15) -> -149.67825 | AB10: =SUM(P10:AA10) -> -783.10353
B11: Первый месяц | C11: 0 | D11: 0 | E11: 0 | F11: 0 | G11: 0 | H11: 0 | I11: 0 | J11: 0 | K11: 0 | L11: 0 | M11: 0 | N11: 0 | O11: =SUM(C11:N11) -> 0 | P11: =C11-Расчеты!C10 -> 0 | Q11: =D11-Расчеты!D10 -> 0 | R11: =E11-Расчеты!E10 -> 0 | S11: =F11-Расчеты!F10 -> 0 | T11: =G11-Расчеты!G10 -> 0 | U11: =H11-Расчеты!H10 -> 0 | V11: =I11-Расчеты!I10 -> 0 | W11: =J11-Расчеты!J10 -> 0 | ... AA11: =N11-Расчеты!N10 -> 0 | AB11: =SUM(P11:AA11) -> 0
B12: Подписка на месяц | C12: 0 | D12: 30.6 | E12: 54.9 | F12: 80.1 | G12: 105.9 | H12: 130.8 | I12: 158.1 | J12: 187.2 | K12: 216.9 | L12: 243.3 | M12: 270.9 | N12: 299.4 | O12: =SUM(C12:N12) -> 1778.1 | P12: =C12-Расчеты!C11 -> 0 | Q12: =D12-Расчеты!D11 -> 0.6 | R12: =E12-Расчеты!E11 -> -5.61 | S12: =F12-Расчеты!F11 -> -11.43867 | T12: =G12-Расчеты!G11 -> -17.194827 | U12: =H12-Расчеты!H11 -> -24.387439 | V12: =I12-Расчеты!I11 -> -30.704772 | W12: =J12-Расчеты!J11 -> -36.819263 | ... AA12: =N12-Расчеты!N11 -> -66.261182 | AB12: =SUM(P12:AA12) -> -347.01374
B13: Пакет на 3 месяца | C13: 0 | D13: 21.533333 | E13: 39.1 | F13: 56.666667 | G13: 74.8 | H13: 92.366667 | I13: 112.48333 | J13: 132.6 | K13: 153.56667 | L13: 171.98333 | M13: 192.38333 | N13: 212.21667 | O13: =SUM(C13:N13) -> 1259.7 | P13: =C13-Расчеты!C12 -> 0 | Q13: =D13-Расчеты!D12 -> 0.28333333 | R13: =E13-Расчеты!E12 -> -3.76125 | S13: =F13-Расчеты!F12 -> -8.1732246 | T13: =G13-Расчеты!G12 -> -12.392169 | U13: =H13-Расчеты!H12 -> -17.55777 | V13: =I13-Расчеты!I12 -> -21.25338 | W13: =J13-Расчеты!J12 -> -26.080311 | ... AA13: =N13-Расчеты!N12 -> -46.793338 | AB13: =SUM(P13:AA13) -> -245.5889
B14: Пакет на 6 месяцев | C14: 0 | D14: 14.133333 | E14: 24.533333 | F14: 36.266667 | G14: 47.2 | H14: 59.2 | I14: 70.666667 | J14: 83.733333 | K14: 96.8 | L14: 107.73333 | M14: 120.26667 | N14: 133.6 | O14: =SUM(C14:N14) -> 794.13333 | P14: =C14-Расчеты!C13 -> 0 | Q14: =D14-Расчеты!D13 -> 0.8 | R14: =E14-Расчеты!E13 -> -2.36 | S14: =F14-Расчеты!F13 -> -4.4171867 | T14: =G14-Расчеты!G13 -> -7.5088122 | U14: =H14-Расчеты!H13 -> -9.7721953 | V14: =I14-Расчеты!I13 -> -13.246565 | W14: =J14-Расчеты!J13 -> -15.830784 | ... AA14: =N14-Расчеты!N13 -> -28.916081 | AB14: =SUM(P14:AA14) -> -150.36166
B15: Пакет на 12 месяцев | C15: 0 | D15: 4.25 | E15: 7 | F15: 10.5 | G15: 13.25 | H15: 16.5 | I15: 20 | J15: 24 | K15: 27.5 | L15: 30.75 | M15: 33.75 | N15: 38 | O15: =SUM(C15:N15) -> 225.5 | P15: =C15-Расчеты!C14 -> 0 | Q15: =D15-Расчеты!D14 -> 0.5 | R15: =E15-Расчеты!E14 -> -0.56375 | S15: =F15-Расчеты!F14 -> -0.94233375 | T15: =G15-Расчеты!G14 -> -2.1368534 | U15: =H15-Расчеты!H14 -> -2.8984299 | V15: =I15-Расчеты!I14 -> -3.6005964 | W15: =J15-Расчеты!J14 -> -4.0024079 | ... AA15: =N15-Расчеты!N14 -> -7.7076478 | AB15: =SUM(P15:AA15) -> -40.139218
B16: Education | C16: =SUM(C17:C21) -> 246.83333 | D16: =SUM(D17:D21) -> 436.33333 | E16: =SUM(E17:E21) -> 674.5 | F16: =SUM(F17:F21) -> 912.66667 | G16: =SUM(G17:G21) -> 1093.3333 | H16: =SUM(H17:H21) -> 1294.5 | I16: =SUM(I17:I21) -> 1496.5 | J16: =SUM(J17:J21) -> 1771.1667 | ... N16: =SUM(N17:N21) -> 2846.1667 | O16: =SUM(C16:N16) -> 17739.167 | P16: =SUM(P17:P21) -> 63.166667 | Q16: =SUM(Q17:Q21) -> 65.326667 | R16: =SUM(R17:R21) -> 112.40653 | S16: =SUM(S17:S21) -> 155.66466 | T16: =SUM(T17:T21) -> 137.52462 | U16: =SUM(U17:U21) -> 129.82496 | V16: =SUM(V17:V21) -> 112.39 | W16: =SUM(W17:W21) -> 156.5183 | ... AA16: =SUM(AA17:AA21) -> 344.5698 | AB16: =SUM(P16:AA16) -> 2092.1435
B17: Фритрек | C17: 0 | D17: 0 | E17: 0 | F17: 0 | G17: 0 | H17: 0 | I17: 0 | J17: 0 | K17: 0 | L17: 0 | M17: 0 | N17: 0 | O17: =SUM(C17:N17) -> 0 | P17: =C17-Расчеты!C16 -> 0 | Q17: =D17-Расчеты!D16 -> 0 | R17: =E17-Расчеты!E16 -> 0 | S17: =F17-Расчеты!F16 -> 0 | T17: =G17-Расчеты!G16 -> 0 | U17: =H17-Расчеты!H16 -> 0 | V17: =I17-Расчеты!I16 -> 0 | W17: =J17-Расчеты!J16 -> 0 | ... AA17: =N17-Расчеты!N16 -> 0 | AB17: =SUM(P17:AA17) -> 0
B18: Полная оплата курса | C18: 25 | D18: 41.666667 | E18: 58.333333 | F18: 75 | G18: 83.333333 | H18: 100 | I18: 108.33333 | J18: 133.33333 | K18: 141.66667 | L18: 166.66667 | M18: 191.66667 | N18: 200 | O18: =SUM(C18:N18) -> 1325 | P18: =C18-Расчеты!C17 -> 15 | Q18: =D18-Расчеты!D17 -> 21.466667 | R18: =E18-Расчеты!E17 -> 27.729333 | S18: =F18-Расчеты!F17 -> 33.78392 | T18: =G18-Расчеты!G17 -> 31.292932 | U18: =H18-Расчеты!H17 -> 36.587566 | V18: =I18-Расчеты!I17 -> 32.973442 | W18: =J18-Расчеты!J17 -> 45.421444 | ... AA18: =N18-Расчеты!N17 -> 63.796904 | AB18: =SUM(P18:AA18) -> 473.07496
B19: Оплата курса 2 траншами | C19: 45.833333 | D19: 91.666667 | E19: 146.66667 | F19: 201.66667 | G19: 247.5 | H19: 275 | I19: 311.66667 | J19: 375.83333 | K19: 467.5 | L19: 531.66667 | M19: 577.5 | N19: 641.66667 | O19: =SUM(C19:N19) -> 3914.1667 | P19: =C19-Расчеты!C18 -> 9.1666667 | Q19: =D19-Расчеты!D18 -> 17.6 | R19: =E19-Расчеты!E18 -> 34.452 | S19: =F19-Расчеты!F18 -> 50.54104 | T19: =G19-Расчеты!G18 -> 56.685194 | U19: =H19-Расчеты!H18 -> 42.487742 | V19: =I19-Расчеты!I18 -> 35.347066 | W19: =J19-Расчеты!J18 -> 53.489739 | ... AA19: =N19-Расчеты!N18 -> 142.25531 | AB19: =SUM(P19:AA19) -> 790.44153
B20: Оплата курса 3 траншами | C20: 76 | D20: 133 | E20: 199.5 | F20: 266 | G20: 332.5 | H20: 389.5 | I20: 446.5 | J20: 532 | K20: 608 | L20: 703 | M20: 769.5 | N20: 864.5 | O20: =SUM(C20:N20) -> 5320 | P20: =C20-Расчеты!C19 -> 19 | Q20: =D20-Расчеты!D19 -> 17.86 | R20: =E20-Расчеты!E19 -> 25.0572 | S20: =F20-Расчеты!F19 -> 31.068344 | T20: =G20-Расчеты!G19 -> 35.869711 | U20: =H20-Расчеты!H19 -> 28.049127 | V20: =I20-Расчеты!I19 -> 16.948621 | W20: =J20-Расчеты!J19 -> 30.90223 | ... AA20: =N20-Расчеты!N19 -> 88.142352 | AB20: =SUM(P20:AA20) -> 464.02729
B21: Оплата курса помесячно | C21: 100 | D21: 170 | E21: 270 | F21: 370 | G21: 430 | H21: 530 | I21: 630 | J21: 730 | K21: 840 | L21: 950 | M21: 1020 | N21: 1140 | O21: =SUM(C21:N21) -> 7180 | P21: =C21-Расчеты!C20 -> 20 | Q21: =D21-Расчеты!D20 -> 8.4 | R21: =E21-Расчеты!E20 -> 25.168 | S21: =F21-Расчеты!F20 -> 40.27136 | T21: =G21-Расчеты!G20 -> 13.676787 | U21: =H21-Расчеты!H20 -> 22.700529 | V21: =I21-Расчеты!I20 -> 27.120872 | W21: =J21-Расчеты!J20 -> 26.704885 | ... AA21: =N21-Расчеты!N20 -> 50.37523 | AB21: =SUM(P21:AA21) -> 364.5997
B23: Таблица 3.1. Количество пользователей, чел. | I23: факт | P23: Δ (факт - план) | AP23: Допущение о 100% лояльности неверно. Это подтверждается данными из таблицы 3.1.2 («Количество продлений») и колонками с отклонениями (факт – план). Для минимизации отклонений в будующем можно разделить прогноз на новые клиенты и продления, анализируя их отдельно.Стимулирование бонусы за продление, отдельные предложения. Провести анализ причин оттока по сегментам (опросы, анализ поведения) | AR23: Нет | AS23: =IF(AR23="Нет", " ", "Ниже добавлены таблицы с дополнительными вводными, сформированными на основании фактических данных по оплатам. Проанализируйте их и сделайте выводы. При необходимости справа от таблиц, на пустом пространстве, сделайте дополнительные расчёты.")
C24: янв.26 | D24: фев.26 | E24: мар.26 | F24: апр.26 | G24: 46143 | H24: июн.26 | I24: июл.26 | J24: авг.26 | K24: сент.26 | L24: окт.26 | M24: ноя.26 | N24: дек.26 | O24: 2026 | P24: янв.26 | Q24: фев.26 | R24: мар.26 | S24: апр.26 | T24: 46143 | U24: июн.26 | V24: июл.26 | W24: авг.26 | X24: сент.26 | Y24: окт.26 | Z24: ноя.26 | AA24: дек.26 | AB24: 2026 | AR24: Нет | AS24: =IF(AR24="Нет", " ", "Было ли верно допущение о 100%-ой лояльности при выстраивании бюджетной модели? Сделайте вывод, что нужно сделать для минимизации отклонений в будущем?")
B26: Community
B27: Первый месяц | C27: 504 | D27: 507 | E27: 509 | F27: 514 | G27: 515 | H27: 525 | I27: 543 | J27: 567 | K27: 551 | L27: 561 | M27: 570 | N27: 580 | P27: =C27-Расчеты!C26 -> 4 | Q27: =D27-Расчеты!D26 -> -1.5 | R27: =E27-Расчеты!E26 -> -8.1445 | S27: =F27-Расчеты!F26 -> -11.935956 | T27: =G27-Расчеты!G26 -> -19.876868 | U27: =H27-Расчеты!H26 -> -35.288868 | V27: =I27-Расчеты!I26 -> -43.908192 | W27: =J27-Расчеты!J26 -> -47.7922 | ... AA27: =N27-Расчеты!N26 -> -21.866937 | AB27: =AA27 -> -21.866937
B28: Подписка на месяц | C28: 0 | D28: 102 | E28: 183 | F28: 267 | G28: 353 | H28: 436 | I28: 527 | J28: 624 | K28: 723 | L28: 811 | M28: 903 | N28: 998 | P28: =C28-Расчеты!C27 -> 0 | Q28: =D28-Расчеты!D27 -> 2 | R28: =E28-Расчеты!E27 -> -18.7 | S28: =F28-Расчеты!F27 -> -38.1289 | T28: =G28-Расчеты!G27 -> -57.316091 | U28: =H28-Расчеты!H27 -> -81.291465 | V28: =I28-Расчеты!I27 -> -102.34924 | W28: =J28-Расчеты!J27 -> -122.73088 | ... AA28: =N28-Расчеты!N27 -> -220.87061 | AB28: =AA28 -> -220.87061
B29: Пакет на 3 месяца | C29: 0 | D29: 76 | E29: 138 | F29: 200 | G29: 264 | H29: 326 | I29: 397 | J29: 468 | K29: 542 | L29: 607 | M29: 679 | N29: 749 | P29: =C29-Расчеты!C28 -> 0 | Q29: =D29-Расчеты!D28 -> 1 | R29: =E29-Расчеты!E28 -> -13.275 | S29: =F29-Расчеты!F28 -> -28.846675 | T29: =G29-Расчеты!G28 -> -43.737068 | U29: =H29-Расчеты!H28 -> -61.968599 | V29: =I29-Расчеты!I28 -> -75.011929 | W29: =J29-Расчеты!J28 -> -92.048158 | ... AA29: =N29-Расчеты!N28 -> -165.15296 | AB29: =AA29 -> -165.15296
B30: Пакет на 6 месяцев | C30: 0 | D30: 53 | E30: 92 | F30: 136 | G30: 177 | H30: 222 | I30: 265 | J30: 314 | K30: 363 | L30: 404 | M30: 451 | N30: 501 | P30: =C30-Расчеты!C29 -> 0 | Q30: =D30-Расчеты!D29 -> 3 | R30: =E30-Расчеты!E29 -> -8.85 | S30: =F30-Расчеты!F29 -> -16.56445 | T30: =G30-Расчеты!G29 -> -28.158046 | U30: =H30-Расчеты!H29 -> -36.645732 | V30: =I30-Расчеты!I29 -> -49.674619 | W30: =J30-Расчеты!J29 -> -59.365438 | ... AA30: =N30-Расчеты!N29 -> -108.4353 | AB30: =AA30 -> -108.4353
B31: Пакет на 12 месяцев | C31: 0 | D31: 17 | E31: 28 | F31: 42 | G31: 53 | H31: 66 | I31: 80 | J31: 96 | K31: 110 | L31: 123 | M31: 135 | N31: 152 | P31: =C31-Расчеты!C30 -> 0 | Q31: =D31-Расчеты!D30 -> 2 | R31: =E31-Расчеты!E30 -> -2.255 | S31: =F31-Расчеты!F30 -> -3.769335 | T31: =G31-Расчеты!G30 -> -8.5474137 | U31: =H31-Расчеты!H30 -> -11.59372 | V31: =I31-Расчеты!I30 -> -14.402386 | W31: =J31-Расчеты!J30 -> -16.009632 | ... AA31: =N31-Расчеты!N30 -> -30.830591 | AB31: =AA31 -> -30.830591
B32: Education
B33: Фритрек | C33: 97 | D33: 100 | E33: 103 | F33: 105 | G33: 106 | H33: 113 | I33: 115 | J33: 117 | K33: 111 | L33: 113 | M33: 104 | N33: 81 | P33: =C33-Расчеты!C32 -> 57 | Q33: =D33-Расчеты!D32 -> 59.2 | R33: =E33-Расчеты!E32 -> 61.384 | S33: =F33-Расчеты!F32 -> 62.55168 | T33: =G33-Расчеты!G32 -> 62.702714 | U33: =H33-Расчеты!H32 -> 67.511871 | V33: =I33-Расчеты!I32 -> 67.210172 | W33: =J33-Расчеты!J32 -> 66.792006 | ... AA33: =N33-Расчеты!N32 -> 31.265028 | AB33: =AA33 -> 31.265028
B34: Полная оплата курса | C34: 3 | D34: 5 | E34: 7 | F34: 9 | G34: 10 | H34: 12 | I34: 13 | J34: 16 | K34: 17 | L34: 20 | M34: 23 | N34: 24 | P34: =C34-Расчеты!C33 -> 1.8 | Q34: =D34-Расчеты!D33 -> 2.576 | R34: =E34-Расчеты!E33 -> 3.32752 | S34: =F34-Расчеты!F33 -> 4.0540704 | T34: =G34-Расчеты!G33 -> 3.7551518 | U34: =H34-Расчеты!H33 -> 4.3905079 | V34: =I34-Расчеты!I33 -> 3.9568131 | W34: =J34-Расчеты!J33 -> 5.4505733 | ... AA34: =N34-Расчеты!N33 -> 7.6556285 | AB34: =AA34 -> 7.6556285
B35: Оплата курса 2 траншами | C35: 5 | D35: 10 | E35: 16 | F35: 22 | G35: 27 | H35: 30 | I35: 34 | J35: 41 | K35: 51 | L35: 58 | M35: 63 | N35: 70 | P35: =C35-Расчеты!C34 -> 1 | Q35: =D35-Расчеты!D34 -> 1.92 | R35: =E35-Расчеты!E34 -> 3.7584 | S35: =F35-Расчеты!F34 -> 5.513568 | T35: =G35-Расчеты!G34 -> 6.1838394 | U35: =H35-Расчеты!H34 -> 4.6350265 | V35: =I35-Расчеты!I34 -> 3.8560436 | W35: =J35-Расчеты!J34 -> 5.8352442 | ... AA35: =N35-Расчеты!N34 -> 15.518762 | AB35: =AA35 -> 15.518762
B36: Оплата курса 3 траншами | C36: 8 | D36: 14 | E36: 21 | F36: 28 | G36: 35 | H36: 41 | I36: 47 | J36: 56 | K36: 64 | L36: 74 | M36: 81 | N36: 91 | P36: =C36-Расчеты!C35 -> 2 | Q36: =D36-Расчеты!D35 -> 1.88 | R36: =E36-Расчеты!E35 -> 2.6376 | S36: =F36-Расчеты!F35 -> 3.270352 | T36: =G36-Расчеты!G35 -> 3.775759 | U36: =H36-Расчеты!H35 -> 2.9525397 | V36: =I36-Расчеты!I35 -> 1.7840654 | W36: =J36-Расчеты!J35 -> 3.2528664 | ... AA36: =N36-Расчеты!N35 -> 9.2781423 | AB36: =AA36 -> 9.2781423
B37: Оплата курса помесячно | C37: 10 | D37: 17 | E37: 27 | F37: 37 | G37: 43 | H37: 53 | I37: 63 | J37: 73 | K37: 84 | L37: 95 | M37: 102 | N37: 114 | P37: =C37-Расчеты!C36 -> 2 | Q37: =D37-Расчеты!D36 -> 0.84 | R37: =E37-Расчеты!E36 -> 2.5168 | S37: =F37-Расчеты!F36 -> 4.027136 | T37: =G37-Расчеты!G36 -> 1.3676787 | U37: =H37-Расчеты!H36 -> 2.2700529 | V37: =I37-Расчеты!I36 -> 2.7120872 | W37: =J37-Расчеты!J36 -> 2.6704885 | ... AA37: =N37-Расчеты!N36 -> 5.037523 | AB37: =AA37 -> 5.037523
B39: Таблица 3.1.1. Количество новых пользователей, чел. | I39: факт | P39: Δ (факт - план) | AC39: уровень проникновения продаж факт | AP39: Уровень продаж проникновения для всех типов подписок Community демонстрирует стабильный и невысокий рост. Анализ кол-ва продлений показывает кумулятивный рост, но с явными отклонениями от плановых показателей. Рекомендация например включить Бонусы за продление (скидка 10–15% при оплате следующего периода). Система накопительных баллов (например, за активность, отзывы). 'Уровень проникновения продаж для всех типов подписок Education стабильно низкий, самый высокий рост показывает при помесячной форме оплаты.Эксклюзивный контент для продливших подписку. По продлению отклонения от плана: меньше, чем в Community. Сезонные колебания: незначительные, отток минимален (особенно в сравнении с Community). По ежемесячному приросту по Education Фритрек показывает спад сезонности ноябрь-декабрь. Для повышения точности планирования нужно учитывать в плане прогноза как сезонность, внедрить метрики удержания: LTV (жизненный цикл клиента); CAC (стоимость привлечения). Автоматизировать мониторинг отклонений (еженедельные отчёты по Δ = факт – план). Учитывать внешние факторы (конкуренция, экономические условия) при корректировке планов. | AR39: Нет | AS39: =IF(AR39="Нет", " ", "Сделайте расчёт фактического уровня проникновения продаж по новым клиентам как Количество платных клиентов / Количество бесплатных * 100%. Сравните с плановым уровнем.")
C40: янв.26 | D40: фев.26 | E40: мар.26 | F40: апр.26 | G40: 46143 | H40: июн.26 | I40: июл.26 | J40: авг.26 | K40: сент.26 | L40: окт.26 | M40: ноя.26 | N40: дек.26 | O40: 2026 | P40: янв.26 | Q40: фев.26 | R40: мар.26 | S40: апр.26 | T40: 46143 | U40: июн.26 | V40: июл.26 | W40: авг.26 | X40: сент.26 | Y40: окт.26 | Z40: ноя.26 | AA40: дек.26 | AB40: 2026 | AC40: янв.26 | AD40: фев.26 | AE40: мар.26 | AF40: апр.26 | AG40: 46143 | AH40: июн.26 | AI40: июл.26 | AJ40: авг.26 | AK40: сент.26 | AL40: окт.26 | AM40: ноя.26 | AN40: дек.26 | AR40: Нет | AS40: =IF(AR40="Нет", " ", "Проверьте, как соотносится уровень проникновения продаж и количество продлений у Community? Сделайте вывод, что можно рекомендовать для изменения ситуации?")
B42: Community | AC42: Community | AR42: Нет | AS42: =IF(AR42="Нет", " ", "Проверьте, как соотносится уровень проникновения продаж и количество продлений у Education? Сделайте вывод, что можно рекомендовать для изменения ситуации?")
B43: Первый месяц | C43: 504 | D43: 507 | E43: 509 | F43: 514 | G43: 515 | H43: 525 | I43: 543 | J43: 567 | K43: 551 | L43: 561 | M43: 570 | N43: 580 | AC43: 0 | AD43: 0 | AE43: 0 | AF43: 0 | AG43: 0 | AH43: 0 | AI43: 0 | AJ43: 0 | AK43: 0 | AL43: 0 | AM43: 0 | AN43: 0 | AR43: Нет | AS43: =IF(AR43="Нет", " ", "Рассчитайте ежемесячный темп прироста новых клиентов на бесплатных продуктах как Количество клиентов в текущем месяце / Количествоклиентов в предыдущем месяце - 1. Сравните с планом по сезонности.")
B44: Подписка на месяц | C44: 0 | D44: 102 | E44: 103 | F44: 105 | G44: 108 | H44: 107 | I44: 113 | J44: 120 | K44: 125 | L44: 115 | M44: 115 | N44: 117 | AC44: 0 | AD44: =D44/C43 -> 0.20238095 | AE44: =E44/D43 -> 0.20315582 | AF44: =F44/E43 -> 0.20628684 | AG44: =G44/F43 -> 0.21011673 | AH44: =H44/G43 -> 0.20776699 | AI44: =I44/H43 -> 0.2152381 | AJ44: =J44/I43 -> 0.22099448 | AK44: =K44/J43 -> 0.22045855 | ... AN44: =N44/M43 -> 0.20526316 | AR44: Нет | AS44: =IF(AR44="Нет", " ", "Сделайте вывод по предыдущему расчёту, что можно изменить в модели для повышения точности планирования?")
B45: Пакет на 3 месяца | C45: 0 | D45: 76 | E45: 78 | F45: 78 | G45: 80 | H45: 79 | I45: 86 | J45: 90 | K45: 93 | L45: 85 | M45: 88 | N45: 88 | AC45: 0 | AD45: =D45/C43 -> 0.15079365 | AE45: =E45/D43 -> 0.15384615 | AF45: =F45/E43 -> 0.15324165 | AG45: =G45/F43 -> 0.15564202 | AH45: =H45/G43 -> 0.15339806 | AI45: =I45/H43 -> 0.16380952 | AJ45: =J45/I43 -> 0.16574586 | AK45: =K45/J43 -> 0.16402116 | ... AN45: =N45/M43 -> 0.15438596
B46: Пакет на 6 месяцев | C46: 0 | D46: 53 | E46: 52 | F46: 55 | G46: 54 | H46: 57 | I46: 58 | J46: 62 | K46: 64 | L46: 56 | M46: 57 | N46: 60 | AC46: 0 | AD46: =D46/C43 -> 0.10515873 | AE46: =E46/D43 -> 0.1025641 | AF46: =F46/E43 -> 0.10805501 | AG46: =G46/F43 -> 0.10505837 | AH46: =H46/G43 -> 0.11067961 | AI46: =I46/H43 -> 0.11047619 | AJ46: =J46/I43 -> 0.11418048 | AK46: =K46/J43 -> 0.11287478 | ... AN46: =N46/M43 -> 0.10526316
B47: Пакет на 12 месяцев | C47: 0 | D47: 17 | E47: 16 | F47: 17 | G47: 16 | H47: 16 | I47: 17 | J47: 20 | K47: 20 | L47: 18 | M47: 16 | N47: 19 | AC47: 0 | AD47: =D47/C43 -> 0.033730159 | AE47: =E47/D43 -> 0.031558185 | AF47: =F47/E43 -> 0.033398821 | AG47: =G47/F43 -> 0.031128405 | AH47: =H47/G43 -> 0.031067961 | AI47: =I47/H43 -> 0.032380952 | AJ47: =J47/I43 -> 0.036832413 | AK47: =K47/J43 -> 0.035273369 | ... AN47: =N47/M43 -> 0.033333333
...

Sheet Выгрузка персонал
A1: Дата | B1: Назначение | C1: ID сотрудника | D1: Должность | E1: Направление | F1: Сумма, руб. | G1: Подсказку?
A2: 46027 | B2: аванс | C2: 100005001 | D2: Producr Owner | E2: Community | F2: 40000 | G2: Нет | H2: =IF(G2="Нет", " ", "Сформируйте сводную таблицу по представленному массиву данных.")
A3: 46027 | B3: аванс | C3: 100005002 | D3: Модератор | E3: Community | F3: 24000 | G3: Нет | H3: =IF(G3="Нет", " ", "В сводной таблице добавьте в поле Столбцы даты, в поле Строки назначение, направление и должность, в поле Значения сумму. Сравните получившиеся данные со значениями на листе Свод факта.")
A4: 46027 | B4: аванс | C4: 100005003 | D4: Инженер тех. поддержки | E4: Community | F4: 24000 | G4: Нет | H4: =IF(G4="Нет", " ", "На листе Свод факта заработная плата включает в себя основную выплату зп и аванс. Для сравнения суммируйте эти две части в сводной таблице.")
A5: 46027 | B5: аванс | C5: 100005004 | D5: Контент-мейкер | E5: Community | F5: 32000 | G5: Нет | H5: =IF(G5="Нет", " ", "Проверьте, были ли учтены в плане компенсации по питанию в расходах на персонал?")
A6: 46027 | B6: аванс | C6: 100005005 | D6: SMM | E6: Community | F6: 32000 | G6: Нет | H6: =IF(G6="Нет", " ", "Для сравнения ДМС со значениями на листе Свод факта приведите данные сводной таблицы по ДМС к месячному формату, разделив их на 12.")
A7: 46027 | B7: аванс | C7: 100005006 | D7: Producr Owner | E7: Education | F7: 40000
A8: 46027 | B8: аванс | C8: 100005009 | D8: Куратор | E8: Education | F8: 40000
A9: 46027 | B9: аванс | C9: 100005007 | D9: Инженер тех. поддержки | E9: Education | F9: 28000
A10: 46027 | B10: аванс | C10: 100005008 | D10: SMM | E10: Education | F10: 32000
A11: 46027 | B11: аванс | C11: 100005000 | D11: Бухгалтер | E11: Бухгалтерия | F11: 16000
A12: 46042 | B12: заработная плата | C12: 100005001 | D12: Producr Owner | E12: Community | F12: 60000 | H12: Сумма по полю Сумма, руб. | I12: Названия столбцов
A13: 46042 | B13: заработная плата | C13: 100005002 | D13: Модератор | E13: Community | F13: 36000 | I13: янв | J13: февр | K13: март | L13: апр | M13: май | N13: июнь | O13: июль | P13: авг | Q13: сент | R13: окт | S13: нояб | T13: дек | U13: Общий итог
A14: 46042 | B14: заработная плата | C14: 100005003 | D14: Инженер тех. поддержки | E14: Community | F14: 36000
A15: 46042 | B15: заработная плата | C15: 100005004 | D15: Контент-мейкер | E15: Community | F15: 48000 | H15: Названия строк | V15: Сумма зп+аванс
A16: 46042 | B16: заработная плата | C16: 100005005 | D16: SMM | E16: Community | F16: 48000 | H16: аванс | I16: 308000 | J16: 348000 | K16: 442193.55 | L16: 475600 | M16: 487612.9 | N16: 546400 | O16: 575741.94 | P16: 678064.52 | Q16: 666400 | R16: 736387.1 | S16: 712000 | T16: 765548.39 | U16: 6741948.4
A17: 46042 | B17: заработная плата | C17: 100005006 | D17: Producr Owner | E17: Education | F17: 60000 | H17: Бухгалтерия | I17: 16000 | J17: 16000 | K17: 26838.71 | L17: 16000 | M17: 16000 | N17: 16000 | O17: 16000 | P17: 26838.71 | Q17: 16000 | R17: 16000 | S17: 16000 | T17: 16000 | U17: 213677.42 | V17: =GETPIVOTDATA("Сумма, руб.",$H$12,"Назначение","аванс","Направление","Бухгалтерия")+GETPIVOTDATA("Сумма, руб.",$H$12,"Назначение","заработная плата","Направление","Бухгалтерия") -> 480000
A18: 46042 | B18: заработная плата | C18: 100005009 | D18: Куратор | E18: Education | F18: 60000 | H18: Бухгалтер | I18: 16000 | J18: 16000 | K18: 26838.71 | L18: 16000 | M18: 16000 | N18: 16000 | O18: 16000 | P18: 26838.71 | Q18: 16000 | R18: 16000 | S18: 16000 | T18: 16000 | U18: 213677.42 | V18: =GETPIVOTDATA("Сумма, руб.",$H$12,"Назначение","аванс","Направление","Community")+GETPIVOTDATA("Сумма, руб.",$H$12,"Назначение","заработная плата","Направление","Community") -> 4560000
A19: 46042 | B19: заработная плата | C19: 100005007 | D19: Инженер тех. поддержки | E19: Education | F19: 42000 | H19: Community | I19: 152000 | J19: 152000 | K19: 173677.42 | L19: 152000 | M19: 184516.13 | N19: 202400 | O19: 173677.42 | P19: 168258.06 | Q19: 202400 | R19: 152000 | S19: 152000 | T19: 168258.06 | U19: 2033187.1 | V19: =GETPIVOTDATA("Сумма, руб.",$H$12,"Назначение","аванс","Направление","Education")+GETPIVOTDATA("Сумма, руб.",$H$12,"Назначение","заработная плата","Направление","Education") -> 9800000
A20: 46042 | B20: заработная плата | C20: 100005008 | D20: SMM | E20: Education | F20: 48000 | H20: Инженер тех. поддержки | I20: 24000 | J20: 24000 | K20: 24000 | L20: 24000 | M20: 40258.065 | N20: 24000 | O20: 24000 | P20: 40258.065 | Q20: 24000 | R20: 24000 | S20: 24000 | T20: 24000 | U20: 320516.13
A21: 46042 | B21: заработная плата | C21: 100005000 | D21: Бухгалтер | E21: Бухгалтерия | F21: 24000 | H21: Контент-мейкер | I21: 32000 | J21: 32000 | K21: 53677.419 | L21: 32000 | M21: 32000 | N21: 54400 | O21: 32000 | P21: 32000 | Q21: 32000 | R21: 32000 | S21: 32000 | T21: 32000 | U21: 428077.42
A22: 46058 | B22: аванс | C22: 100005001 | D22: Producr Owner | E22: Community | F22: 40000 | H22: Модератор | I22: 24000 | J22: 24000 | K22: 24000 | L22: 24000 | M22: 40258.065 | N22: 24000 | O22: 24000 | P22: 24000 | Q22: 24000 | R22: 24000 | S22: 24000 | T22: 40258.065 | U22: 320516.13
A23: 46058 | B23: аванс | C23: 100005002 | D23: Модератор | E23: Community | F23: 24000 | H23: Producr Owner | I23: 40000 | J23: 40000 | K23: 40000 | L23: 40000 | M23: 40000 | N23: 68000 | O23: 40000 | P23: 40000 | Q23: 68000 | R23: 40000 | S23: 40000 | T23: 40000 | U23: 536000
A24: 46058 | B24: аванс | C24: 100005003 | D24: Инженер тех. поддержки | E24: Community | F24: 24000 | H24: SMM | I24: 32000 | J24: 32000 | K24: 32000 | L24: 32000 | M24: 32000 | N24: 32000 | O24: 53677.419 | P24: 32000 | Q24: 54400 | R24: 32000 | S24: 32000 | T24: 32000 | U24: 428077.42
A25: 46058 | B25: аванс | C25: 100005004 | D25: Контент-мейкер | E25: Community | F25: 32000 | H25: Education | I25: 140000 | J25: 180000 | K25: 241677.42 | L25: 307600 | M25: 287096.77 | N25: 328000 | O25: 386064.52 | P25: 482967.74 | Q25: 448000 | R25: 568387.1 | S25: 544000 | T25: 581290.32 | U25: 4495083.9
A26: 46058 | B26: аванс | C26: 100005005 | D26: SMM | E26: Community | F26: 32000 | H26: Инженер тех. поддержки | I26: 28000 | J26: 28000 | K26: 28000 | L26: 47600 | M26: 28000 | N26: 28000 | O26: 46967.742 | P26: 28000 | Q26: 28000 | R26: 28000 | S26: 28000 | T26: 28000 | U26: 374567.74
A27: 46058 | B27: аванс | C27: 100005006 | D27: Producr Owner | E27: Education | F27: 40000 | H27: Куратор | I27: 40000 | J27: 80000 | K27: 120000 | L27: 188000 | M27: 187096.77 | N27: 228000 | O27: 267096.77 | P27: 334193.55 | Q27: 348000 | R27: 441290.32 | S27: 444000 | T27: 481290.32 | U27: 3158967.7
A28: 46058 | B28: аванс | C28: 100005009 | D28: Куратор | E28: Education | F28: 40000 | H28: Producr Owner | I28: 40000 | J28: 40000 | K28: 40000 | L28: 40000 | M28: 40000 | N28: 40000 | O28: 40000 | P28: 67096.774 | Q28: 40000 | R28: 67096.774 | S28: 40000 | T28: 40000 | U28: 534193.55
A29: 46058 | B29: аванс | C29: 100005010 | D29: Куратор | E29: Education | F29: 40000 | H29: SMM | I29: 32000 | J29: 32000 | K29: 53677.419 | L29: 32000 | M29: 32000 | N29: 32000 | O29: 32000 | P29: 53677.419 | Q29: 32000 | R29: 32000 | S29: 32000 | T29: 32000 | U29: 427354.84
A30: 46058 | B30: аванс | C30: 100005007 | D30: Инженер тех. поддержки | E30: Education | F30: 28000 | H30: ДМС на год | I30: 240000 | J30: 24000 | K30: 24000 | L30: 24000 | N30: 24000 | O30: 24000 | P30: 24000 | Q30: 24000 | R30: 24000 | T30: 24000 | U30: 456000
A31: 46058 | B31: аванс | C31: 100005008 | D31: SMM | E31: Education | F31: 32000 | H31: Бухгалтерия | I31: 24000 | U31: 24000
A32: 46058 | B32: аванс | C32: 100005000 | D32: Бухгалтер | E32: Бухгалтерия | F32: 16000 | H32: Бухгалтер | I32: 24000 | U32: 24000
A33: 46073 | B33: заработная плата | C33: 100005001 | D33: Producr Owner | E33: Community | F33: 60000 | H33: Community | I33: 120000 | U33: 120000
A34: 46073 | B34: заработная плата | C34: 100005002 | D34: Модератор | E34: Community | F34: 36000 | H34: Инженер тех. поддержки | I34: 24000 | U34: 24000
A35: 46073 | B35: заработная плата | C35: 100005003 | D35: Инженер тех. поддержки | E35: Community | F35: 36000 | H35: Контент-мейкер | I35: 24000 | U35: 24000
A36: 46073 | B36: заработная плата | C36: 100005004 | D36: Контент-мейкер | E36: Community | F36: 48000 | H36: Модератор | I36: 24000 | U36: 24000
A37: 46073 | B37: заработная плата | C37: 100005005 | D37: SMM | E37: Community | F37: 48000 | H37: Producr Owner | I37: 24000 | U37: 24000
A38: 46073 | B38: заработная плата | C38: 100005006 | D38: Producr Owner | E38: Education | F38: 60000 | H38: SMM | I38: 24000 | U38: 24000
A39: 46073 | B39: заработная плата | C39: 100005009 | D39: Куратор | E39: Education | F39: 60000 | H39: Education | I39: 96000 | J39: 24000 | K39: 24000 | L39: 24000 | N39: 24000 | O39: 24000 | P39: 24000 | Q39: 24000 | R39: 24000 | T39: 24000 | U39: 312000
A40: 46073 | B40: заработная плата | C40: 100005010 | D40: Куратор | E40: Education | F40: 60000 | H40: Инженер тех. поддержки | I40: 24000 | U40: 24000
...

Sheet Выгрузка оборудование
A1: Дата | B1: Тип | C1: Срок полезного использования | D1: ID сотрудника | E1: Должность | F1: Направление | G1: Сумма, руб. | I1: Подсказку?
A2: 46023 | B2: Комплект оборудования "Стандартный" | C2: 2 года | D2: 100005000 | E2: Бухгалтер | F2: Бухгалтерия | G2: 100000 | I2: Нет | J2: =IF(I2="Нет", " ", "Сформируйте сводную таблицу по представленному массиву данных.")
A3: 46023 | B3: Комплект оборудования "Стандартный" | C3: 2 года | D3: 100005001 | E3: Producr Owner | F3: Community | G3: 100000 | I3: Нет | J3: =IF(I3="Нет", " ", "В сводной таблице добавьте в поле Столбцы даты, в поле Строки направление, в поле Значения сумму. Сравните получившиеся данные со значениями на листе Свод факта.")
A4: 46023 | B4: Комплект оборудования "Стандартный" | C4: 2 года | D4: 100005002 | E4: Модератор | F4: Community | G4: 100000 | I4: Нет | J4: =IF(I4="Нет", " ", "Для сравнения со значениями на листе Свод факта приведите данные сводной таблицы к месячному формату, разделив их на 24.")
A5: 46023 | B5: Комплект оборудования "Стандартный" | C5: 2 года | D5: 100005003 | E5: Инженер тех. поддержки | F5: Community | G5: 100000
A6: 46023 | B6: Комплект оборудования "Стандартный" | C6: 2 года | D6: 100005004 | E6: Контент-мейкер | F6: Community | G6: 100000
A7: 46023 | B7: Комплект оборудования "Стандартный" | C7: 2 года | D7: 100005005 | E7: SMM | F7: Community | G7: 100000
A8: 46023 | B8: Комплект оборудования "Стандартный" | C8: 2 года | D8: 100005006 | E8: Producr Owner | F8: Education | G8: 100000
A9: 46023 | B9: Комплект оборудования "Стандартный" | C9: 2 года | D9: 100005007 | E9: Инженер тех. поддержки | F9: Education | G9: 100000
A10: 46023 | B10: Комплект оборудования "Стандартный" | C10: 2 года | D10: 100005008 | E10: SMM | F10: Education | G10: 100000 | I10: Сумма по полю Сумма, руб. | J10: Названия столбцов
A11: 46023 | B11: Комплект оборудования "Стандартный" | C11: 2 года | D11: 100005009 | E11: Куратор | F11: Education | G11: 100000 | I11: Названия строк | J11: 46023 | K11: 46054 | L11: 46082 | M11: 46113 | N11: 46174 | O11: 46204 | P11: 46235 | Q11: 46266 | R11: 46296 | S11: 46357 | T11: Общий итог
A12: 46054 | B12: Комплект оборудования "Стандартный" | C12: 2 года | D12: 100005010 | E12: Куратор | F12: Education | G12: 100000 | I12: Бухгалтерия | J12: 100000 | T12: 100000
A13: 46082 | B13: Комплект оборудования "Стандартный" | C13: 2 года | D13: 100005011 | E13: Куратор | F13: Education | G13: 100000 | I13: Community | J13: 500000 | T13: 500000
A14: 46113 | B14: Комплект оборудования "Стандартный" | C14: 2 года | D14: 100005012 | E14: Куратор | F14: Education | G14: 100000 | I14: Education | J14: 400000 | K14: 100000 | L14: 100000 | M14: 100000 | N14: 100000 | O14: 100000 | P14: 100000 | Q14: 100000 | R14: 100000 | S14: 100000 | T14: 1300000
A15: 46174 | B15: Комплект оборудования "Стандартный" | C15: 2 года | D15: 100005013 | E15: Куратор | F15: Education | G15: 100000 | I15: Общий итог | J15: 1000000 | K15: 100000 | L15: 100000 | M15: 100000 | N15: 100000 | O15: 100000 | P15: 100000 | Q15: 100000 | R15: 100000 | S15: 100000 | T15: 1900000
A16: 46204 | B16: Комплект оборудования "Стандартный" | C16: 2 года | D16: 100005014 | E16: Куратор | F16: Education | G16: 100000
A17: 46235 | B17: Комплект оборудования "Стандартный" | C17: 2 года | D17: 100005015 | E17: Куратор | F17: Education | G17: 100000 | I17: Месячный формат
A18: 46266 | B18: Комплект оборудования "Стандартный" | C18: 2 года | D18: 100005016 | E18: Куратор | F18: Education | G18: 100000 | J18: 46023 | K18: 46054 | L18: 46082 | M18: 46113 | N18: 46174 | O18: 46204 | P18: 46235 | Q18: 46266 | R18: 46296 | S18: 46357
A19: 46296 | B19: Комплект оборудования "Стандартный" | C19: 2 года | D19: 100005017 | E19: Куратор | F19: Education | G19: 100000 | I19: Бухгалтерия | J19: =GETPIVOTDATA("Сумма, руб.",$I$10,"Дата",DATE(2026,1,1),"Направление","Бухгалтерия")/24 -> 4166.6667 | K19: 4166.6667 | L19: 4166.6667 | M19: 4166.6667 | N19: 4166.6667 | O19: 4166.6667 | P19: 4166.6667 | Q19: 4166.6667 | R19: 4166.6667 | S19: 4166.6667
A20: 46357 | B20: Комплект оборудования "Стандартный" | C20: 2 года | D20: 100005018 | E20: Куратор | F20: Education | G20: 100000 | I20: Community | J20: =GETPIVOTDATA("Сумма, руб.",$I$10,"Дата",DATE(2026,1,1),"Направление","Community")/24 -> 20833.333 | K20: 20833.333 | L20: 20833.333 | M20: 20833.333 | N20: 20833.333 | O20: 20833.333 | P20: 20833.333 | Q20: 20833.333 | R20: 20833.333 | S20: 20833.333
I21: Education | J21: =GETPIVOTDATA("Сумма, руб.",$I$10,"Дата",DATE(2026,1,1),"Направление","Education")/24 -> 16666.667 | K21: =SUM(J14:K14)/24 -> 20833.333 | L21: =SUM(J14:L14)/24 -> 25000 | M21: =SUM(J14:M14)/24 -> 29166.667 | N21: =SUM(J14:N14)/24 -> 33333.333 | O21: =SUM(J14:O14)/24 -> 37500 | P21: =SUM(J14:P14)/24 -> 41666.667 | Q21: =SUM(J14:Q14)/24 -> 45833.333 | R21: =SUM(J14:R14)/24 -> 50000 | S21: =SUM(J14:S14)/24 -> 54166.667

Sheet Выгрузка лицензии
A1: Дата | B1: Лицензия | C1: ID сотрудника | D1: Должность | E1: Направление | F1: Стоимость за годовой доступ, $ | G1: Курс доллара | H1: Сумма, руб. | J1: Подсказку?
A2: 46023 | B2: 1С | C2: 100005000 | D2: Бухгалтер | E2: Бухгалтерия | F2: 110.99 | G2: 91 | H2: =F2*G2 -> 10100.09 | J2: Нет | K2: =IF(J2="Нет", " ", "Сформируйте сводную таблицу по представленному массиву данных.")
A3: 46023 | B3: MS Office | C3: 100005000 | D3: Бухгалтер | E3: Бухгалтерия | F3: 332.99 | G3: 91 | H3: =F3*G3 -> 30302.09 | J3: Нет | K3: =IF(J3="Нет", " ", "В сводной таблице добавьте в поле Столбцы даты, в поле Строки направление и лицензия, в поле Значения сумму. Сравните получившиеся данные со значениями на листе Свод факта.")
A4: 46023 | B4: MS Office | C4: 100005001 | D4: Producr Owner | E4: Community | F4: 332.99 | G4: 91 | H4: =F4*G4 -> 30302.09 | J4: Нет | K4: =IF(J4="Нет", " ", "Сравните стоимость отдельной лицензии с плановой.")
A5: 46023 | B5: Miro | C5: 100005001 | D5: Producr Owner | E5: Community | F5: 154.99 | G5: 91 | H5: =F5*G5 -> 14104.09 | J5: Нет | K5: =IF(J5="Нет", " ", "Для сравнения со значениями на листе Свод факта приведите данные сводной таблицы к месячному формату, разделив их на 12.")
A6: 46023 | B6: Jira | C6: 100005001 | D6: Producr Owner | E6: Community | F6: 110.99 | G6: 91 | H6: =F6*G6 -> 10100.09 | J6: Нет | K6: =IF(J6="Нет", " ", "Проверьте, был ли заложен рост курса доллара в плановой стоимости лицензий?")
A7: 46023 | B7: Доп.софт для разработки комьюнити-платформы | C7: 100005001 | D7: Producr Owner | E7: Community | F7: 732.5 | G7: 91 | H7: =F7*G7 -> 66657.5
A8: 46023 | B8: MS Office | C8: 100005002 | D8: Модератор | E8: Community | F8: 332.99 | G8: 91 | H8: =F8*G8 -> 30302.09
A9: 46023 | B9: Miro | C9: 100005002 | D9: Модератор | E9: Community | F9: 154.99 | G9: 91 | H9: =F9*G9 -> 14104.09
A10: 46023 | B10: Jira | C10: 100005002 | D10: Модератор | E10: Community | F10: 110.99 | G10: 91 | H10: =F10*G10 -> 10100.09
A11: 46023 | B11: Доп.софт для разработки комьюнити-платформы | C11: 100005002 | D11: Модератор | E11: Community | F11: 732.5 | G11: 91 | H11: =F11*G11 -> 66657.5
A12: 46023 | B12: MS Office | C12: 100005003 | D12: Инженер тех. поддержки | E12: Community | F12: 332.99 | G12: 91 | H12: =F12*G12 -> 30302.09
A13: 46023 | B13: Miro | C13: 100005003 | D13: Инженер тех. поддержки | E13: Community | F13: 154.99 | G13: 91 | H13: =F13*G13 -> 14104.09
A14: 46023 | B14: Jira | C14: 100005003 | D14: Инженер тех. поддержки | E14: Community | F14: 110.99 | G14: 91 | H14: =F14*G14 -> 10100.09 | K14: Сумма по полю Сумма, руб. | L14: Названия столбцов
A15: 46023 | B15: Доп.софт для разработки комьюнити-платформы | C15: 100005003 | D15: Инженер тех. поддержки | E15: Community | F15: 732.5 | G15: 91 | H15: =F15*G15 -> 66657.5 | K15: Названия строк | L15: 46023 | M15: 46054 | N15: 46082 | O15: 46113 | P15: 46174 | Q15: 46204 | R15: 46235 | S15: 46266 | T15: 46296 | U15: 46357 | V15: Общий итог
A16: 46023 | B16: MS Office | C16: 100005004 | D16: Контент-мейкер | E16: Community | F16: 332.99 | G16: 91 | H16: =F16*G16 -> 30302.09 | K16: Бухгалтерия | L16: 40402.18 | V16: 40402.18
A17: 46023 | B17: Miro | C17: 100005004 | D17: Контент-мейкер | E17: Community | F17: 154.99 | G17: 91 | H17: =F17*G17 -> 14104.09 | K17: Community | L17: 605818.85 | V17: 605818.85
A18: 46023 | B18: Jira | C18: 100005004 | D18: Контент-мейкер | E18: Community | F18: 110.99 | G18: 91 | H18: =F18*G18 -> 10100.09 | K18: Education | L18: 484655.08 | M18: 121163.77 | N18: 125158.18 | O18: 130484.06 | P18: 133147 | Q18: 138472.88 | R18: 143798.76 | S18: 145130.23 | T18: 145130.23 | U18: 137141.41 | V18: 1704281.6
A19: 46023 | B19: Доп.софт для разработки комьюнити-платформы | C19: 100005004 | D19: Контент-мейкер | E19: Community | F19: 732.5 | G19: 91 | H19: =F19*G19 -> 66657.5 | K19: Общий итог | L19: 1130876.1 | M19: 121163.77 | N19: 125158.18 | O19: 130484.06 | P19: 133147 | Q19: 138472.88 | R19: 143798.76 | S19: 145130.23 | T19: 145130.23 | U19: 137141.41 | V19: 2350502.6
A20: 46023 | B20: MS Office | C20: 100005005 | D20: SMM | E20: Community | F20: 332.99 | G20: 91 | H20: =F20*G20 -> 30302.09
A21: 46023 | B21: Miro | C21: 100005005 | D21: SMM | E21: Community | F21: 154.99 | G21: 91 | H21: =F21*G21 -> 14104.09
A22: 46023 | B22: Jira | C22: 100005005 | D22: SMM | E22: Community | F22: 110.99 | G22: 91 | H22: =F22*G22 -> 10100.09
A23: 46023 | B23: Доп.софт для разработки комьюнити-платформы | C23: 100005005 | D23: SMM | E23: Community | F23: 732.5 | G23: 91 | H23: =F23*G23 -> 66657.5
A24: 46023 | B24: MS Office | C24: 100005006 | D24: Producr Owner | E24: Education | F24: 332.99 | G24: 91 | H24: =F24*G24 -> 30302.09
A25: 46023 | B25: Miro | C25: 100005006 | D25: Producr Owner | E25: Education | F25: 154.99 | G25: 91 | H25: =F25*G25 -> 14104.09
A26: 46023 | B26: Jira | C26: 100005006 | D26: Producr Owner | E26: Education | F26: 110.99 | G26: 91 | H26: =F26*G26 -> 10100.09
A27: 46023 | B27: Доп.софт для разработки обучающей платформы | C27: 100005006 | D27: Producr Owner | E27: Education | F27: 732.5 | G27: 91 | H27: =F27*G27 -> 66657.5
A28: 46023 | B28: MS Office | C28: 100005007 | D28: Инженер тех. поддержки | E28: Education | F28: 332.99 | G28: 91 | H28: =F28*G28 -> 30302.09
A29: 46023 | B29: Miro | C29: 100005007 | D29: Инженер тех. поддержки | E29: Education | F29: 154.99 | G29: 91 | H29: =F29*G29 -> 14104.09
A30: 46023 | B30: Jira | C30: 100005007 | D30: Инженер тех. поддержки | E30: Education | F30: 110.99 | G30: 91 | H30: =F30*G30 -> 10100.09
A31: 46023 | B31: Доп.софт для разработки обучающей платформы | C31: 100005007 | D31: Инженер тех. поддержки | E31: Education | F31: 732.5 | G31: 91 | H31: =F31*G31 -> 66657.5
... A75: 46357 | B75: Доп.софт для разработки обучающей платформы | C75: 100005018 | D75: Куратор | E75: Education | F75: 732.5 | G75: 103 | H75: =F75*G75 -> 75447.5

Sheet Бюджет-->

Sheet Цели
B2: Таблица 10. Цели 2026-2027
C3: Community | E3: Education | G3: Итого новые направления
C4: 2026 | D4: 2027 | E4: 2026 | F4: 2027 | G4: 2026 | H4: 2027 | V4: Да
B5: Неоцифрованные | C5: Создать базу квалифицированных разработчиков, которые потенциально смогут работать в Kihi | E5: Создать сообщество с большим количеством активных пользователей | V5: Нет
C6: Самоокупаемость к концу 2027 года
B7: Нефинансовые показатели
B8: Количество активных пользователей
B9: Sticky Factor
B10: Средний срок жизни одного пользователя
B11: Стоимость привлечения пользователя
B12: Коэффициент удержания
B13: Индекс удовлетворённости
B14: Индекс дохождения до финала
B15: Количество трудоустроенных студентов
B16: Финансовые показатели, тыс.руб.
B17: Выручка | C17: =Бюджет!F5 -> 4840.5369 | D17: =Бюджет!G5 -> 16907.573 | E17: =Бюджет!I5 -> 15647.023 | F17: =Бюджет!J5 -> 34216.348 | G17: =Бюджет!C5 -> 20487.56 | H17: =Бюджет!D5 -> 51123.921
B18: Прирост год к году, % | D18: =D17/C17-1 -> 2.4929128 | F18: =F17/E17-1 -> 1.1867641 | H18: =H17/G17-1 -> 1.4953641
B19: Чистая прибыль | C19: =Бюджет!F18 -> -9802.4431 | D19: =Бюджет!G18 -> 1488.6708 | E19: =Бюджет!I18 -> -4756.9968 | F19: =Бюджет!J18 -> 2338.93 | G19: =Бюджет!C18 -> -15986.57 | H19: =Бюджет!D18 -> 1728.6027
B20: Чистая прибыль, % | D20: =D19/D17 -> 0.088047572 | F20: =F19/F17 -> 0.06835709 | H20: =H19/H17 -> 0.033812012

Sheet Аналитика
B2: Таблица 11. Рыночная цена аналогов, руб. | G2: Таблица 15. Ожидаемое количество новых пользователей, чел. | L2: Таблица 17. Прочие вводные
B3: Community | D3: Education | H3: Community | I3: Education | L3: Ежегодная индексация ЗП | M3: 0.08
B4: Первый месяц | C4: 0 | D4: Фритрек (недельный) | E4: 0 | G4: В первый месяц | H4: 500 | I4: 40 | L4: Ожидаемая инфляция 27/26 | M4: 0.07
B5: Подписка на месяц | C5: 300 | D5: Полная оплата годового курса | E5: 100000 | G5: Ежемесячный прирост | H5: 0.017 | I5: 0.02 | L5: Аренда помещения под 20-25 человек, тыс. руб./мес. | M5: 50
B6: Пакет на 3 месяца | C6: 850 | D6: Оплата курса 2 траншами | E6: 110000 | G6: Ограничения | H6: нет | I6: Не более 30 человек на одного куратора (фритрек не сопровождается куратором) | L6: Закупка мебели, тыс. руб. | M6: 150
B7: Пакет на 6 месяцев | C7: 1600 | D7: Оплата курса 3 траншами | E7: 114000 | G7: Сезонность (дополнительный прирост в летние месяцы к ежемесячному приросту) | H7: 0.03 | I7: 0.03 | L7: Закупка оборудования (компьютеры, мыши, клавиатуры), тыс. руб./чел. | M7: 100
B8: Пакет на 12 месяцев | C8: 3000 | D8: Оплата курса помесячно | E8: 120000 | L8: Непредвиденные расходы | M8: 1% от всех расходов
G9: Таблица 16. Ожидаемый уровень проникновения продаж | L9: Стоимость ДМС на 1 чел./мес., тыс. руб. | M9: 2
B10: Таблица 12. Стоимость и время аутсорс-разработки под ключ, тыс. руб. | G10: Community | I10: Education | L10: Лицензия 1С для 1 ПК/год, тыс. руб. | M10: 10
C11: Стоимость | D11: Время | G11: Подписка на месяц | H11: 0.2 | I11: Полная оплата курса | J11: 0.03 | L11: Лицензия MS Office для 1 ПК/год, тыс. руб. | M11: 30
B12: Community | C12: 8000 | D12: релиз - 10.01.26, время на доработку - 6 мес. | G12: Пакет на 3 месяца | H12: 0.15 | I12: Оплата курса 2 траншами | J12: 0.1 | L12: Лицензия Miro для 1 ПК/год, тыс. руб. | M12: 14
B13: Education | C13: 6000 | D13: релиз - 15.01.26, время на доработку - 3 мес. | G13: Пакет на 6 месяцев | H13: 0.1 | I13: Оплата курса 3 траншами | J13: 0.15 | L13: Лицензия Jira для 1 ПК/год, тыс. руб. | M13: 10
G14: Пакет на 12 месяцев | H14: 0.03 | I14: Оплата курса помесячно | J14: 0.2 | L14: Софт для разработки комьюнити-платформы 1 ПК/год, тыс. руб. | M14: 66
B15: Таблица 13. Рыночные ежемесячные расходы на рекламу, тыс. руб. | L15: Софт для разработки обучающей платформы 1 ПК/год, тыс. руб. | M15: 66
C16: Community | D16: Education
B17: SEO | C17: 40 | D17: 40
B18: SMM | C18: 60 | D18: 60
B19: PPC | C19: 40 | D19: 40
B20: App ads | C20: 70 | D20: 70
B21: Email-рассылка | C21: 40 | D21: 40
B22: Контент-маркетинг | C22: 50 | D22: 50
B24: Таблица 14. Рыночная ЗП поддерживающего персонала в мес., тыс. руб.
B25: Community | D25: Education
B26: Producr Owner | C26: 100 | D26: Producr Owner | E26: 100
B27: Модератор | C27: 60 | D27: Куратор | E27: 100
B28: Инженер тех. поддержки | C28: 60 | D28: Инженер тех. поддержки | E28: 70
B29: Контент-мейкер | C29: 80 | D29: SMM | E29: 80
B30: SMM | C30: 80
B31: Бухгалтер (на два проекта) | E31: 40

Sheet Расчеты
B2: Таблица 18. Количество дней в периоде, шт. | AD2: Допущения
C3: янв.26 | D3: фев.26 | E3: мар.26 | F3: апр.26 | G3: 46143 | H3: июн.26 | I3: июл.26 | J3: авг.26 | K3: сент.26 | L3: окт.26 | M3: ноя.26 | N3: дек.26 | O3: 2026 | P3: янв.27 | Q3: фев.27 | R3: мар.27 | S3: апр.27 | T3: 46508 | U3: июн.27 | V3: июл.27 | W3: авг.27 | X3: сент.27 | Y3: окт.27 | Z3: ноя.27 | AA3: дек.27 | AB3: 2027
C4: 31 | D4: 28 | E4: 31 | F4: 30 | G4: 31 | H4: 30 | I4: 31 | J4: 31 | K4: 30 | L4: 31 | M4: 30 | N4: 31 | O4: =SUM(C4:N4) -> 365 | P4: 31 | Q4: 28 | R4: 31 | S4: 30 | T4: 31 | U4: 30 | V4: 31 | W4: 31 | X4: 30 | Y4: 31 | Z4: 30 | AA4: 31 | AB4: =SUM(P4:AA4) -> 365
B6: Таблица 19. Выручка, тыс. руб.
C7: янв.26 | D7: фев.26 | E7: мар.26 | F7: апр.26 | G7: 46143 | H7: июн.26 | I7: июл.26 | J7: авг.26 | K7: сент.26 | L7: окт.26 | M7: ноя.26 | N7: дек.26 | O7: 2026 | P7: янв.27 | Q7: фев.27 | R7: мар.27 | S7: апр.27 | T7: 46508 | U7: июн.27 | V7: июл.27 | W7: авг.27 | X7: сент.27 | Y7: окт.27 | Z7: ноя.27 | AA7: дек.27 | AB7: 2027
B9: Community | C9: =SUM(C10:C14) -> 0 | D9: =SUM(D10:D14) -> 68.333333 | E9: =SUM(E10:E14) -> 137.82833 | F9: =SUM(F10:F14) -> 208.50475 | G9: =SUM(G10:G14) -> 280.38266 | H9: =SUM(H10:H14) -> 353.4825 | I9: =SUM(I10:I14) -> 430.05531 | J9: =SUM(J10:J14) -> 510.2661 | ... N9: =SUM(N10:N14) -> 832.89492 | O9: =SUM(C9:N9) -> 4840.5369 | P9: =SUM(P10:P14) -> 915.15006 | Q9: =SUM(Q10:Q14) -> 998.80355 | R9: =SUM(R10:R14) -> 1083.8791 | S9: =SUM(S10:S14) -> 1170.401 | T9: =SUM(T10:T14) -> 1258.3938 | U9: =SUM(U10:U14) -> 1347.8824 | V9: =SUM(V10:V14) -> 1441.6226 | W9: =SUM(W10:W14) -> 1539.8165 | ... AA9: =SUM(AA10:AA14) -> 1934.7778 | AB9: =SUM(P9:AA9) -> 16907.573
