Workbook

Sheet Цели
B2: Таблица 1. Цели 2026–2027 | J2: Подсказку?
C3: Community | E3: Education | G3: Итого новые направления
C4: 2026 | D4: 2027 | E4: 2026 | F4: 2027 | G4: 2026 | H4: 2027 | V4: Да
B5: Неоцифрованные | C5: Создать сообщество с большим количеством активных пользователей | E5: Создать базу квалифицированных разработчиков, которые потенциально смогут работать в Kihi | V5: Нет
C6: Самоокупаемость к концу 2027 года
B7: Финансовые показатели, тыс. руб.
B8: Выручка | C8: ='Бюджет'!F5 -> 4840.5369 | D8: ='Бюджет'!G5 -> 16907.573 | E8: ='Бюджет'!I5 -> 15642.711 | F8: ='Бюджет'!J5 -> 34206.016 | G8: ='Бюджет'!C5 -> 20483.248 | H8: ='Бюджет'!D5 -> 51113.589 | J8: Нет | K8: =IF(J8="Нет", " ", "Цели по выручке заполните из листа Бюджет после всех расчётов")
B9: Прирост год к году, % | D9: =D8/C8-1 -> 2.4929128 | F9: =F8/E8-1 -> 1.1867064 | H9: =H8/G8-1 -> 1.495385 | J9: Нет | K9: =IF(J9="Нет", " ", "Рассчитывается как показатель 2027 / показатель 2026 - 1")
B10: Чистая прибыль | C10: ='Бюджет'!F18 -> -9802.4431 | D10: ='Бюджет'!G18 -> 1488.6708 | E10: ='Бюджет'!I18 -> -4761.309 | F10: ='Бюджет'!J18 -> 2328.598 | G10: ='Бюджет'!C18 -> -15990.882 | H10: ='Бюджет'!D18 -> 1720.8536 | J10: Нет | K10: =IF(J10="Нет", " ", "Цели по прибыли заполните из листа Бюджет после всех расчётов")
B11: Чистая прибыль, % | C11: =C10/C8 -> -2.0250735 | D11: =D10/D8 -> 0.088047572 | E11: =E10/E8 -> -0.30437876 | F11: =F10/F8 -> 0.068075685 | G11: =G10/G8 -> -0.78068099 | H11: =H10/H8 -> 0.033667243 | J11: Нет | K11: =IF(J11="Нет", " ", "Рассчитывается как Чистая прибыль / Выручку")

Sheet Аналитика
B2: Таблица 2. Рыночная цена аналогов, руб. | G2: Таблица 6. Ожидаемое количество новых пользователей, чел. | L2: Таблица 8. Прочие вводные
B3: Community | D3: Education | H3: Community | I3: Education | L3: Ежегодная индексация ЗП | M3: 0.08
B4: Первый месяц | C4: 0 | D4: Фритрек (недельный) | E4: 0 | G4: В первый месяц | H4: 500 | I4: 40 | L4: Ожидаемая инфляция 27/26 | M4: 0.07
B5: Подписка на месяц | C5: 300 | D5: Полная оплата годового курса | E5: 100000 | G5: Ежемесячный прирост | H5: 0.017 | I5: 0.02 | L5: Аренда помещения под 20–25 человек, тыс. руб./мес. | M5: 50
B6: Пакет на 3 месяца | C6: 850 | D6: Оплата курса 2 траншами | E6: 110000 | G6: Ограничения | H6: нет | I6: Не более 30 человек на одного куратора (фритрек не сопровождается куратором) | L6: Закупка мебели, тыс. руб. | M6: 150
B7: Пакет на 6 месяцев | C7: 1600 | D7: Оплата курса 3 траншами | E7: 114000 | G7: Сезонность (дополнительный прирост в летние месяцы к ежемесячному приросту) | H7: 0.03 | I7: 0.03 | L7: Закупка оборудования (компьютеры, мыши, клавиатуры), тыс. руб./чел. | M7: 100
B8: Пакет на 12 месяцев | C8: 3000 | D8: Оплата курса помесячно | E8: 120000 | L8: Непредвиденные расходы | M8: 1% от всех расходов
G9: Таблица 7. Ожидаемый уровень проникновения продаж | L9: Стоимость ДМС на 1 чел./мес., тыс. руб. | M9: 2
B10: Таблица 3. Стоимость и время аутсорс-разработки «под ключ», тыс. руб. | G10: Community | I10: Education | L10: Лицензия 1С для 1 ПК/год, тыс. руб. | M10: 10
C11: Стоимость | D11: Время | G11: Подписка на месяц | H11: 0.2 | I11: Полная оплата курса | J11: 0.03 | L11: Лицензия MS Office для 1 ПК/год, тыс. руб. | M11: 30
B12: Community | C12: 8000 | D12: релиз — 10.01.26 | G12: Пакет на 3 месяца | H12: 0.15 | I12: Оплата курса 2 траншами | J12: 0.1 | L12: Лицензия Miro для 1 ПК/год, тыс. руб. | M12: 14
B13: Education | C13: 6000 | D13: релиз — 15.01.26 | G13: Пакет на 6 месяцев | H13: 0.1 | I13: Оплата курса 3 траншами | J13: 0.15 | L13: Лицензия Jira для 1 ПК/год, тыс. руб. | M13: 10
G14: Пакет на 12 месяцев | H14: 0.03 | I14: Оплата курса помесячно | J14: 0.2 | L14: Софт для разработки комьюнити-платформы 1 ПК/год, тыс. руб. | M14: 66
B15: Таблица 4. Рыночные ежемесячные расходы на рекламу, тыс. руб. | L15: Софт для разработки обучающей платформы 1 ПК/год, тыс. руб. | M15: 66
C16: Community | D16: Education
B17: SEO | C17: 40 | D17: 40
B18: SMM | C18: 60 | D18: 60
B19: PPC | C19: 40 | D19: 40
B20: App ads | C20: 70 | D20: 70
B21: Email-рассылка | C21: 40 | D21: 40
B22: Контент-маркетинг | C22: 50 | D22: 50
B24: Таблица 5. Рыночная ЗП поддерживающего персонала в мес., тыс. руб.
B25: Community | D25: Education
B26: Producr Owner | C26: 100 | D26: Producr Owner | E26: 100
B27: Модератор | C27: 60 | D27: Куратор | E27: 100
B28: Инженер тех. поддержки | C28: 60 | D28: Инженер тех. поддержки | E28: 70
B29: Контент-мейкер | C29: 80 | D29: SMM | E29: 80
B30: SMM | C30: 80
B31: Бухгалтер (на два проекта) | E31: 40

Sheet Расчёты
B2: Таблица 9. Количество дней в периоде, шт. | AD2: Допущения | AF2: Подсказку?
C3: янв.26 | D3: фев.26 | E3: мар.26 | F3: апр.26 | G3: 46143 | H3: июн.26 | I3: июл.26 | J3: авг.26 | K3: сент.26 | L3: окт.26 | M3: ноя.26 | N3: дек.26 | O3: 2026 | P3: янв.27 | Q3: фев.27 | R3: мар.27 | S3: апр.27 | T3: 46508 | U3: июн.27 | V3: июл.27 | W3: авг.27 | X3: сент.27 | Y3: окт.27 | Z3: ноя.27 | AA3: дек.27 | AB3: 2027
C4: 31 | D4: 28 | E4: 31 | F4: 30 | G4: 31 | H4: 30 | I4: 31 | J4: 31 | K4: 30 | L4: 31 | M4: 30 | N4: 31 | O4: =SUM(C4:N4) -> 365 | P4: 31 | Q4: 28 | R4: 31 | S4: 30 | T4: 31 | U4: 30 | V4: 31 | W4: 31 | X4: 30 | Y4: 31 | Z4: 30 | AA4: 31 | AB4: =SUM(P4:AA4) -> 365
B6: Таблица 10. Выручка, тыс. руб. | AF6: Нет | AG6: =IF(AF6="Нет", " ", "Показатель рассчитывается по формуле Количество пользователей * Стоимость подписки")
C7: янв.26 | D7: фев.26 | E7: мар.26 | F7: апр.26 | G7: 46143 | H7: июн.26 | I7: июл.26 | J7: авг.26 | K7: сент.26 | L7: окт.26 | M7: ноя.26 | N7: дек.26 | O7: 2026 | P7: янв.27 | Q7: фев.27 | R7: мар.27 | S7: апр.27 | T7: 46508 | U7: июн.27 | V7: июл.27 | W7: авг.27 | X7: сент.27 | Y7: окт.27 | Z7: ноя.27 | AA7: дек.27 | AB7: 2027
B9: Community | C9: =SUM(C10:C14) -> 0 | D9: =SUM(D10:D14) -> 68.333333 | E9: =SUM(E10:E14) -> 137.82833 | F9: =SUM(F10:F14) -> 208.50475 | G9: =SUM(G10:G14) -> 280.38266 | H9: =SUM(H10:H14) -> 353.4825 | I9: =SUM(I10:I14) -> 430.05531 | J9: =SUM(J10:J14) -> 510.2661 | ... N9: =SUM(N10:N14) -> 832.89492 | O9: =SUM(C9:N9) -> 4840.5369 | P9: =SUM(P10:P14) -> 915.15006 | Q9: =SUM(Q10:Q14) -> 998.80355 | R9: =SUM(R10:R14) -> 1083.8791 | S9: =SUM(S10:S14) -> 1170.401 | T9: =SUM(T10:T14) -> 1258.3938 | U9: =SUM(U10:U14) -> 1347.8824 | V9: =SUM(V10:V14) -> 1441.6226 | W9: =SUM(W10:W14) -> 1539.8165 | ... AA9: =SUM(AA10:AA14) -> 1934.7778 | AB9: =SUM(P9:AA9) -> 16907.573
B10: Первый месяц | C10: =C26*C42/1000 -> 0 | D10: 0 | E10: 0 | F10: 0 | G10: 0 | H10: 0 | I10: 0 | J10: 0 | K10: 0 | L10: 0 | M10: 0 | N10: 0 | O10: =SUM(C10:N10) -> 0 | P10: =P26*P42/1000 -> 0 | Q10: =Q26*Q42/1000 -> 0 | R10: =R26*R42/1000 -> 0 | S10: =S26*S42/1000 -> 0 | T10: =T26*T42/1000 -> 0 | U10: =U26*U42/1000 -> 0 | V10: =V26*V42/1000 -> 0 | W10: =W26*W42/1000 -> 0 | ... AA10: =AA26*AA42/1000 -> 0 | AB10: =SUM(P10:AA10) -> 0
B11: Подписка на месяц | C11: =C27*C43/1000 -> 0 | D11: =D27*D43/1000 -> 30 | E11: =E27*E43/1000 -> 60.51 | F11: =F27*F43/1000 -> 91.53867 | G11: =G27*G43/1000 -> 123.09483 | H11: =H27*H43/1000 -> 155.18744 | I11: =I27*I43/1000 -> 188.80477 | J11: =J27*J43/1000 -> 224.01926 | ... N11: =N27*N43/1000 -> 365.66118 | O11: =SUM(C11:N11) -> 2125.1137 | P11: =P27*P43/1000 -> 401.7732 | Q11: =Q27*Q43/1000 -> 438.49912 | R11: =R27*R43/1000 -> 475.84938 | S11: =S27*S43/1000 -> 513.8346 | T11: =T27*T43/1000 -> 552.46556 | U11: =U27*U43/1000 -> 591.75325 | V11: =V27*V43/1000 -> 632.9075 | W11: =W27*W43/1000 -> 676.01699 | ... AA11: =AA27*AA43/1000 -> 849.41465 | AB11: =SUM(P11:AA11) -> 7422.837
B12: Пакет на 3 месяца | C12: =C28*C44/1000 -> 0 | D12: =D28*D44/1000 -> 21.25 | E12: =E28*E44/1000 -> 42.86125 | F12: =F28*F44/1000 -> 64.839891 | G12: =G28*G44/1000 -> 87.192169 | H12: =H28*H44/1000 -> 109.92444 | I12: =I28*I44/1000 -> 133.73671 | J12: =J28*J44/1000 -> 158.68031 | ... N12: =N28*N44/1000 -> 259.01 | O12: =SUM(C12:N12) -> 1505.2889 | P12: =P28*P44/1000 -> 284.58935 | Q12: =Q28*Q44/1000 -> 310.60354 | R12: =R28*R44/1000 -> 337.05998 | S12: =S28*S44/1000 -> 363.96617 | T12: =T28*T44/1000 -> 391.32977 | U12: =U28*U44/1000 -> 419.15855 | V12: =V28*V44/1000 -> 448.30948 | W12: =W28*W44/1000 -> 478.84537 | ... AA12: =AA28*AA44/1000 -> 601.66871 | AB12: =SUM(P12:AA12) -> 5257.8429
B13: Пакет на 6 месяцев | C13: =C29*C45/1000 -> 0 | D13: =D29*D45/1000 -> 13.333333 | E13: =E29*E45/1000 -> 26.893333 | F13: =F29*F45/1000 -> 40.683853 | G13: =G29*G45/1000 -> 54.708812 | H13: =H29*H45/1000 -> 68.972195 | I13: =I29*I45/1000 -> 83.913232 | J13: =J29*J45/1000 -> 99.564117 | ... N13: =N29*N45/1000 -> 162.51608 | O13: =SUM(C13:N13) -> 944.495 | P13: =P29*P45/1000 -> 178.56587 | Q13: =Q29*Q45/1000 -> 194.8885 | R13: =R29*R45/1000 -> 211.48861 | S13: =S29*S45/1000 -> 228.37093 | T13: =T29*T45/1000 -> 245.54025 | U13: =U29*U45/1000 -> 263.00144 | V13: =V29*V45/1000 -> 281.29222 | W13: =W29*W45/1000 -> 300.45199 | ... AA13: =AA29*AA45/1000 -> 377.51762 | AB13: =SUM(P13:AA13) -> 3299.0387
B14: Пакет на 12 месяцев | C14: =C30*C46/1000 -> 0 | D14: =D30*D46/1000 -> 3.75 | E14: =E30*E46/1000 -> 7.56375 | F14: =F30*F46/1000 -> 11.442334 | G14: =G30*G46/1000 -> 15.386853 | H14: =H30*H46/1000 -> 19.39843 | I14: =I30*I46/1000 -> 23.600596 | J14: =J30*J46/1000 -> 28.002408 | ... N14: =N30*N46/1000 -> 45.707648 | O14: =SUM(C14:N14) -> 265.63922 | P14: =P30*P46/1000 -> 50.22165 | Q14: =Q30*Q46/1000 -> 54.81239 | R14: =R30*R46/1000 -> 59.481173 | S14: =S30*S46/1000 -> 64.229324 | T14: =T30*T46/1000 -> 69.058195 | U14: =U30*U46/1000 -> 73.969156 | V14: =V30*V46/1000 -> 79.113437 | W14: =W30*W46/1000 -> 84.502123 | ... AA14: =AA30*AA46/1000 -> 106.17683 | AB14: =SUM(P14:AA14) -> 927.85462
B15: Education | C15: =SUM(C16:C20) -> 183.66667 | D15: =SUM(D16:D20) -> 371.00667 | E15: =SUM(E16:E20) -> 562.09347 | F15: =SUM(F16:F20) -> 757.002 | G15: =SUM(G16:G20) -> 955.80871 | H15: =SUM(H16:H20) -> 1164.5558 | I15: =SUM(I16:I20) -> 1383.7401 | J15: =SUM(J16:J20) -> 1613.8838 | ... N15: =SUM(N16:N20) -> 2500.8323 | O15: =SUM(C15:N15) -> 15642.711 | P15: =SUM(P16:P20) -> 2550.0993 | Q15: =SUM(Q16:Q20) -> 2600.3518 | R15: =SUM(R16:R20) -> 2651.6092 | S15: =SUM(S16:S20) -> 2703.8918 | T15: =SUM(T16:T20) -> 2757.2201 | U15: =SUM(U16:U20) -> 2813.2148 | V15: =SUM(V16:V20) -> 2872.0092 | W15: =SUM(W16:W20) -> 2933.7433 | ... AA15: =SUM(AA16:AA20) -> 3171.66 | AB15: =SUM(P15:AA15) -> 34206.016
B16: Фритрек | C16: =C32*C48/1000 -> 0 | D16: 0 | E16: 0 | F16: 0 | G16: 0 | H16: 0 | I16: 0 | J16: 0 | K16: 0 | L16: 0 | M16: 0 | N16: 0 | O16: =SUM(C16:N16) -> 0 | P16: =P32*P48/1000 -> 0 | Q16: =Q32*Q48/1000 -> 0 | R16: =R32*R48/1000 -> 0 | S16: =S32*S48/1000 -> 0 | T16: =T32*T48/1000 -> 0 | U16: =U32*U48/1000 -> 0 | V16: =V32*V48/1000 -> 0 | W16: =W32*W48/1000 -> 0 | ... AA16: =AA32*AA48/1000 -> 0 | AB16: =SUM(P16:AA16) -> 0
B17: Полная оплата курса | C17: =C33*C49/1000 -> 10 | D17: =D33*D49/1000 -> 20.2 | E17: =E33*E49/1000 -> 30.604 | F17: =F33*F49/1000 -> 41.21608 | G17: =G33*G49/1000 -> 52.040402 | H17: =H33*H49/1000 -> 63.405939 | I17: =I33*I49/1000 -> 75.339754 | J17: =J33*J49/1000 -> 87.870259 | ... N17: =N33*N49/1000 -> 136.16147 | O17: =SUM(C17:N17) -> 851.69025 | P17: =P33*P49/1000 -> 138.84388 | Q17: =Q33*Q49/1000 -> 141.57995 | R17: =R33*R49/1000 -> 144.37074 | S17: =S33*S49/1000 -> 147.21734 | T17: =T33*T49/1000 -> 150.12088 | U17: =U33*U49/1000 -> 153.16959 | V17: =V33*V49/1000 -> 156.37074 | W17: =W33*W49/1000 -> 159.73194 | ... AA17: =AA33*AA49/1000 -> 172.68566 | AB17: =SUM(P17:AA17) -> 1862.3965
B18: Оплата курса 2 траншами | C18: =C34*C50/1000 -> 36.666667 | D18: =D34*D50/1000 -> 74.066667 | E18: =E34*E50/1000 -> 112.21467 | F18: =F34*F50/1000 -> 151.12563 | G18: =G34*G50/1000 -> 190.81481 | H18: =H34*H50/1000 -> 232.48844 | I18: =I34*I50/1000 -> 276.24576 | J18: =J34*J50/1000 -> 322.19095 | ... N18: =N34*N50/1000 -> 499.25871 | O18: =SUM(C18:N18) -> 3122.8643 | P18: =P34*P50/1000 -> 509.09424 | Q18: =Q34*Q50/1000 -> 519.12648 | R18: =R34*R50/1000 -> 529.35937 | S18: =S34*S50/1000 -> 539.79692 | T18: =T34*T50/1000 -> 550.44321 | U18: =U34*U50/1000 -> 561.62183 | V18: =V34*V50/1000 -> 573.35937 | W18: =W34*W50/1000 -> 585.68379 | ... AA18: =AA34*AA50/1000 -> 633.18076 | AB18: =SUM(P18:AA18) -> 6828.7872
B19: Оплата курса 3 траншами | C19: =C35*C51/1000 -> 57 | D19: =D35*D51/1000 -> 115.14 | E19: =E35*E51/1000 -> 174.4428 | F19: =F35*F51/1000 -> 234.93166 | G19: =G35*G51/1000 -> 296.63029 | H19: =H35*H51/1000 -> 361.41385 | I19: =I35*I51/1000 -> 429.4366 | J19: =J35*J51/1000 -> 500.86048 | ... N19: =N35*N51/1000 -> 776.12036 | O19: =SUM(C19:N19) -> 4854.6344 | P19: =P35*P51/1000 -> 791.41014 | Q19: =Q35*Q51/1000 -> 807.00572 | R19: =R35*R51/1000 -> 822.91321 | S19: =S35*S51/1000 -> 839.13884 | T19: =T35*T51/1000 -> 855.689 | U19: =U35*U51/1000 -> 873.06666 | V19: =V35*V51/1000 -> 891.3132 | W19: =W35*W51/1000 -> 910.47207 | ... AA19: =AA35*AA51/1000 -> 984.30827 | AB19: =SUM(P19:AA19) -> 10615.66
B20: Оплата курса помесячно | C20: =C36*C52/1000 -> 80 | D20: =D36*D52/1000 -> 161.6 | E20: =E36*E52/1000 -> 244.832 | F20: =F36*F52/1000 -> 329.72864 | G20: =G36*G52/1000 -> 416.32321 | H20: =H36*H52/1000 -> 507.24751 | I20: =I36*I52/1000 -> 602.71803 | J20: =J36*J52/1000 -> 702.96207 | ... N20: =N36*N52/1000 -> 1089.2917 | O20: =SUM(C20:N20) -> 6813.522 | P20: =P36*P52/1000 -> 1110.7511 | Q20: =Q36*Q52/1000 -> 1132.6396 | R20: =R36*R52/1000 -> 1154.9659 | S20: =S36*S52/1000 -> 1177.7387 | T20: =T36*T52/1000 -> 1200.967 | U20: =U36*U52/1000 -> 1225.3567 | V20: =V36*V52/1000 -> 1250.9659 | W20: =W36*W52/1000 -> 1277.8555 | ... AA20: =AA36*AA52/1000 -> 1381.4853 | AB20: =SUM(P20:AA20) -> 14899.172
B22: Таблица 10.1. Количество пользователей, чел. | AD22: - Лояльность клиентов 100% (купленные подписки всегда продлеваются, все студенты проходят полный курс обучения) - Стоимость подписки ближайшие два года без повышения | AF22: Нет | AG22: =IF(AF22="Нет", " ", "Начните с заполнения информации о количестве новых пользователей в первый месяц - новые пользователи начнут с бесплатных версий продуктов: первого месяца подписки на комьюнити и фритрека в обучении")
C23: янв.26 | D23: фев.26 | E23: мар.26 | F23: апр.26 | G23: 46143 | H23: июн.26 | I23: июл.26 | J23: авг.26 | K23: сент.26 | L23: окт.26 | M23: ноя.26 | N23: дек.26 | O23: 2026 | P23: янв.27 | Q23: фев.27 | R23: мар.27 | S23: апр.27 | T23: 46508 | U23: июн.27 | V23: июл.27 | W23: авг.27 | X23: сент.27 | Y23: окт.27 | Z23: ноя.27 | AA23: дек.27 | AB23: 2027 | AF23: Нет | AG23: =IF(AF23="Нет", " ", "Посчитайте прогнозное количество пользователей по бесплатным продуктам с учётом коэффициента ежемесячного прироста и сезонного прироста в летние месяцы")
B25: Community | AF25: Нет | AG25: =IF(AF25="Нет", " ", "Посчитайте прогнозное количество пользователей по платным продуктам с учётом уровня проникновения продаж")
B26: Первый месяц | C26: 500 | D26: =C26*(1+'Аналитика'!$H$5) -> 508.5 | E26: =D26*(1+'Аналитика'!$H$5) -> 517.1445 | F26: =E26*(1+'Аналитика'!$H$5) -> 525.93596 | G26: =F26*(1+'Аналитика'!$H$5) -> 534.87687 | H26: =G26*(1+'Аналитика'!$H$5)*(1+'Аналитика'!$H$7) -> 560.28887 | I26: =H26*(1+'Аналитика'!$H$5)*(1+'Аналитика'!$H$7) -> 586.90819 | J26: =I26*(1+'Аналитика'!$H$5)*(1+'Аналитика'!$H$7) -> 614.7922 | K26: =G26*(1+'Аналитика'!$H$5)^4 -> 572.18653 | L26: =K26*(1+'Аналитика'!$H$5) -> 581.9137 | M26: =L26*(1+'Аналитика'!$H$5) -> 591.80623 | N26: =M26*(1+'Аналитика'!$H$5) -> 601.86694 | O26: =N26 -> 601.86694 | P26: =N26*(1+'Аналитика'!H5) -> 612.09867 | Q26: =P26*(1+'Аналитика'!$H$5) -> 622.50435 | R26: =Q26*(1+'Аналитика'!$H$5) -> 633.08693 | S26: =R26*(1+'Аналитика'!$H$5) -> 643.8494 | T26: =S26*(1+'Аналитика'!$H$5) -> 654.79484 | U26: =T26*(1+'Аналитика'!$H$5)*(1+'Аналитика'!$H$7) -> 685.90415 | V26: =U26*(1+'Аналитика'!$H$5)*(1+'Аналитика'!$H$7) -> 718.49145 | W26: =V26*(1+'Аналитика'!$H$5)*(1+'Аналитика'!$H$7) -> 752.62698 | X26: =T26*(1+'Аналитика'!$H$5)^4 -> 700.46923 | Y26: =X26*(1+'Аналитика'!$H$5) -> 712.37721 | Z26: =Y26*(1+'Аналитика'!$H$5) -> 724.48762 | AA26: =Z26*(1+'Аналитика'!$H$5) -> 736.80391 | AB26: =AA26 -> 736.80391 | AF26: Нет | AG26: =IF(AF26="Нет", " ", "Уровень проникновения продаж необходимо применять к количеству пользователей на бесплатных продуктах")
B27: Подписка на месяц | C27: 0 | D27: =C26*'Аналитика'!$H$11 -> 100 | E27: =D26*'Аналитика'!$H$11+D27 -> 201.7 | F27: =E26*'Аналитика'!$H$11+E27 -> 305.1289 | G27: =F26*'Аналитика'!$H$11+F27 -> 410.31609 | H27: =G26*'Аналитика'!$H$11+G27 -> 517.29146 | I27: =H26*'Аналитика'!$H$11+H27 -> 629.34924 | J27: =I26*'Аналитика'!$H$11+I27 -> 746.73088 | K27: =J26*'Аналитика'!$H$11+J27 -> 869.68932 | L27: =K26*'Аналитика'!$H$11+K27 -> 984.12662 | ... N27: =M26*'Аналитика'!$H$11+M27 -> 1218.8706 | O27: =N27 -> 1218.8706 | P27: =N26*'Аналитика'!$H$11+'Расчёты'!N27 -> 1339.244 | Q27: =P26*'Аналитика'!$H$11+'Расчёты'!P27 -> 1461.6637 | R27: =Q26*'Аналитика'!$H$11+'Расчёты'!Q27 -> 1586.1646 | S27: =R26*'Аналитика'!$H$11+'Расчёты'!R27 -> 1712.782 | T27: =S26*'Аналитика'!$H$11+'Расчёты'!S27 -> 1841.5519 | U27: =T26*'Аналитика'!$H$11+'Расчёты'!T27 -> 1972.5108 | V27: =U26*'Аналитика'!$H$11+'Расчёты'!U27 -> 2109.6917 | W27: =V26*'Аналитика'!$H$11+'Расчёты'!V27 -> 2253.39 | X27: =W26*'Аналитика'!$H$11+'Расчёты'!W27 -> 2403.9154 | ... AA27: =Z26*'Аналитика'!$H$11+'Расчёты'!Z27 -> 2831.3822 | AB27: =AA27 -> 2831.3822 | AF27: Нет | AG27: =IF(AF27="Нет", " ", "При расчёте участников сообщества учтите лаг в 1 месяц бесплатного пользования (пример: пользователи в феврале=пользоватали на пакете первого месяца в январе * уровень проникновения продаж)")
B28: Пакет на 3 месяца | C28: 0 | D28: =C26*'Аналитика'!$H$12 -> 75 | E28: =D26*'Аналитика'!$H$12+'Расчёты'!D28 -> 151.275 | F28: =E26*'Аналитика'!$H$12+'Расчёты'!E28 -> 228.84668 | G28: =F26*'Аналитика'!$H$12+'Расчёты'!F28 -> 307.73707 | H28: =G26*'Аналитика'!$H$12+'Расчёты'!G28 -> 387.9686 | I28: =H26*'Аналитика'!$H$12+'Расчёты'!H28 -> 472.01193 | J28: =I26*'Аналитика'!$H$12+'Расчёты'!I28 -> 560.04816 | K28: =J26*'Аналитика'!$H$12+'Расчёты'!J28 -> 652.26699 | L28: =K26*'Аналитика'!$H$12+'Расчёты'!K28 -> 738.09497 | ... N28: =M26*'Аналитика'!$H$12+'Расчёты'!M28 -> 914.15296 | O28: =N28 -> 914.15296 | P28: =N26*'Аналитика'!$H$12+'Расчёты'!N28 -> 1004.433 | Q28: =P26*'Аналитика'!$H$12+'Расчёты'!P28 -> 1096.2478 | R28: =Q26*'Аналитика'!$H$12+'Расчёты'!Q28 -> 1189.6235 | S28: =R26*'Аналитика'!$H$12+'Расчёты'!R28 -> 1284.5865 | T28: =S26*'Аналитика'!$H$12+'Расчёты'!S28 -> 1381.1639 | U28: =T26*'Аналитика'!$H$12+'Расчёты'!T28 -> 1479.3831 | V28: =U26*'Аналитика'!$H$12+'Расчёты'!U28 -> 1582.2687 | W28: =V26*'Аналитика'!$H$12+'Расчёты'!V28 -> 1690.0425 | X28: =W26*'Аналитика'!$H$12+'Расчёты'!W28 -> 1802.9365 | ... AA28: =Z26*'Аналитика'!$H$12+'Расчёты'!Z28 -> 2123.5366 | AB28: =AA28 -> 2123.5366 | AF28: Нет | AG28: =IF(AF28="Нет", " ", "Поскольку мы сделали допущение, что клиенты лояльны 100% - к клиентам текущего месяца необходимо прибавлять клиентов предыдущего месяца")
B29: Пакет на 6 месяцев | C29: 0 | D29: =C26*'Аналитика'!H13 -> 50 | E29: =D26*'Аналитика'!$H$13+'Расчёты'!D29 -> 100.85 | F29: =E26*'Аналитика'!$H$13+'Расчёты'!E29 -> 152.56445 | G29: =F26*'Аналитика'!$H$13+'Расчёты'!F29 -> 205.15805 | H29: =G26*'Аналитика'!$H$13+'Расчёты'!G29 -> 258.64573 | I29: =H26*'Аналитика'!$H$13+'Расчёты'!H29 -> 314.67462 | J29: =I26*'Аналитика'!$H$13+'Расчёты'!I29 -> 373.36544 | K29: =J26*'Аналитика'!$H$13+'Расчёты'!J29 -> 434.84466 | L29: =K26*'Аналитика'!$H$13+'Расчёты'!K29 -> 492.06331 | ... N29: =M26*'Аналитика'!$H$13+'Расчёты'!M29 -> 609.4353 | O29: =N29 -> 609.4353 | P29: =N26*'Аналитика'!$H$13+'Расчёты'!N29 -> 669.622 | Q29: =P26*'Аналитика'!$H$13+'Расчёты'!P29 -> 730.83187 | R29: =Q26*'Аналитика'!$H$13+'Расчёты'!Q29 -> 793.0823 | S29: =R26*'Аналитика'!$H$13+'Расчёты'!R29 -> 856.39099 | T29: =S26*'Аналитика'!$H$13+'Расчёты'!S29 -> 920.77593 | U29: =T26*'Аналитика'!$H$13+'Расчёты'!T29 -> 986.25542 | V29: =U26*'Аналитика'!$H$13+'Расчёты'!U29 -> 1054.8458 | W29: =V26*'Аналитика'!$H$13+'Расчёты'!V29 -> 1126.695 | X29: =W26*'Аналитика'!$H$13+'Расчёты'!W29 -> 1201.9577 | ... AA29: =Z26*'Аналитика'!$H$13+'Расчёты'!Z29 -> 1415.6911 | AB29: =AA29 -> 1415.6911 | AF29: Нет | AG29: =IF(AF29="Нет", " ", "Не забывайте, что образовательный курс длится 12 мес., а значит с января 2027 нужно будет вычитать выпускников, окончивших обучение (например, в январе 2027 нужно вычесть студентов января 2026)")
B30: Пакет на 12 месяцев | C30: 0 | D30: =C26*'Аналитика'!H14 -> 15 | E30: =D26*'Аналитика'!$H$14+'Расчёты'!D30 -> 30.255 | F30: =E26*'Аналитика'!$H$14+'Расчёты'!E30 -> 45.769335 | G30: =F26*'Аналитика'!$H$14+'Расчёты'!F30 -> 61.547414 | H30: =G26*'Аналитика'!$H$14+'Расчёты'!G30 -> 77.59372 | I30: =H26*'Аналитика'!$H$14+'Расчёты'!H30 -> 94.402386 | J30: =I26*'Аналитика'!$H$14+'Расчёты'!I30 -> 112.00963 | K30: =J26*'Аналитика'!$H$14+'Расчёты'!J30 -> 130.4534 | L30: =K26*'Аналитика'!$H$14+'Расчёты'!K30 -> 147.61899 | ... N30: =M26*'Аналитика'!$H$14+'Расчёты'!M30 -> 182.83059 | O30: =N30 -> 182.83059 | P30: =N26*'Аналитика'!$H$14+'Расчёты'!N30 -> 200.8866 | Q30: =P26*'Аналитика'!$H$14+'Расчёты'!P30 -> 219.24956 | R30: =Q26*'Аналитика'!$H$14+'Расчёты'!Q30 -> 237.92469 | S30: =R26*'Аналитика'!$H$14+'Расчёты'!R30 -> 256.9173 | T30: =S26*'Аналитика'!$H$14+'Расчёты'!S30 -> 276.23278 | U30: =T26*'Аналитика'!$H$14+'Расчёты'!T30 -> 295.87663 | V30: =U26*'Аналитика'!$H$14+'Расчёты'!U30 -> 316.45375 | W30: =V26*'Аналитика'!$H$14+'Расчёты'!V30 -> 338.00849 | X30: =W26*'Аналитика'!$H$14+'Расчёты'!W30 -> 360.5873 | ... AA30: =Z26*'Аналитика'!$H$14+'Расчёты'!Z30 -> 424.70732 | AB30: =AA30 -> 424.70732
B31: Education
B32: Фритрек | C32: 40 | D32: =C32*(1+'Аналитика'!$I$5) -> 40.8 | E32: =D32*(1+'Аналитика'!$I$5) -> 41.616 | F32: =E32*(1+'Аналитика'!$I$5) -> 42.44832 | G32: =F32*(1+'Аналитика'!$I$5) -> 43.297286 | H32: =G32*(1+'Аналитика'!$I$5+'Аналитика'!$I$7) -> 45.462151 | I32: =H32*(1+'Аналитика'!$I$5+'Аналитика'!$I$7) -> 47.735258 | J32: =I32*(1+'Аналитика'!$I$5+'Аналитика'!$I$7) -> 50.122021 | K32: =G32*(1+'Аналитика'!$I$5)^4 -> 46.866375 | L32: =K32*(1+'Аналитика'!$I$5) -> 47.803703 | M32: =L32*(1+'Аналитика'!$I$5) -> 48.759777 | N32: =M32*(1+'Аналитика'!$I$5) -> 49.734972 | O32: =N32 -> 49.734972 | P32: =N32*(1+'Аналитика'!$I$5) -> 50.729672 | Q32: =P32*(1+'Аналитика'!$I$5) -> 51.744265 | R32: =Q32*(1+'Аналитика'!$I$5) -> 52.779151 | S32: =R32*(1+'Аналитика'!$I$5) -> 53.834734 | T32: =S32*(1+'Аналитика'!$I$5) -> 54.911428 | U32: =T32*(1+'Аналитика'!$I$5+'Аналитика'!$I$7) -> 57.657 | V32: =U32*(1+'Аналитика'!$I$5+'Аналитика'!$I$7) -> 60.53985 | W32: =V32*(1+'Аналитика'!$I$5+'Аналитика'!$I$7) -> 63.566842 | X32: =T32*(1+'Аналитика'!I5)^4 -> 59.437896 | Y32: =X32*(1+'Аналитика'!$I$5) -> 60.626654 | Z32: =Y32*(1+'Аналитика'!$I$5) -> 61.839187 | AA32: =Z32*(1+'Аналитика'!$I$5) -> 63.075971 | AB32: =AA32 -> 63.075971
B33: Полная оплата курса | C33: =C32*'Аналитика'!$J$11 -> 1.2 | D33: =C33+D32*'Аналитика'!$J$11 -> 2.424 | E33: =D33+E32*'Аналитика'!$J$11 -> 3.67248 | F33: =E33+F32*'Аналитика'!$J$11 -> 4.9459296 | G33: =F33+G32*'Аналитика'!$J$11 -> 6.2448482 | H33: =G33+H32*'Аналитика'!$J$11 -> 7.6087127 | I33: =H33+I32*'Аналитика'!$J$11 -> 9.0407705 | J33: =I33+J32*'Аналитика'!$J$11 -> 10.544431 | K33: =J33+K32*'Аналитика'!$J$11 -> 11.950422 | ... N33: =M33+N32*'Аналитика'!$J$11 -> 16.339376 | O33: =N33 -> 16.339376 | P33: =N33+P32*'Аналитика'!$J$11-C33 -> 16.661266 | Q33: =P33+Q32*'Аналитика'!$J$11-('Расчёты'!D33-'Расчёты'!C33) -> 16.989594 | R33: =Q33+R32*'Аналитика'!$J$11-('Расчёты'!E33-'Расчёты'!D33) -> 17.324489 | S33: =R33+S32*'Аналитика'!$J$11-('Расчёты'!F33-'Расчёты'!E33) -> 17.666081 | T33: =S33+T32*'Аналитика'!$J$11-('Расчёты'!G33-'Расчёты'!F33) -> 18.014505 | U33: =T33+U32*'Аналитика'!$J$11-('Расчёты'!H33-'Расчёты'!G33) -> 18.380351 | V33: =U33+V32*'Аналитика'!$J$11-('Расчёты'!I33-'Расчёты'!H33) -> 18.764488 | W33: =V33+W32*'Аналитика'!$J$11-('Расчёты'!J33-'Расчёты'!I33) -> 19.167833 | X33: =W33+X32*'Аналитика'!$J$11-('Расчёты'!K33-'Расчёты'!J33) -> 19.544979 | ... AA33: =Z33+AA32*'Аналитика'!$J$11-('Расчёты'!N33-'Расчёты'!M33) -> 20.722279 | AB33: =AA33 -> 20.722279
B34: Оплата курса 2 траншами | C34: =C32*'Аналитика'!J12 -> 4 | D34: =C34+D32*'Аналитика'!$J$12 -> 8.08 | E34: =D34+E32*'Аналитика'!$J$12 -> 12.2416 | F34: =E34+F32*'Аналитика'!$J$12 -> 16.486432 | G34: =F34+G32*'Аналитика'!$J$12 -> 20.816161 | H34: =G34+H32*'Аналитика'!$J$12 -> 25.362376 | I34: =H34+I32*'Аналитика'!$J$12 -> 30.135902 | J34: =I34+J32*'Аналитика'!$J$12 -> 35.148104 | K34: =J34+K32*'Аналитика'!$J$12 -> 39.834741 | ... N34: =M34+N32*'Аналитика'!$J$12 -> 54.464586 | O34: =N34 -> 54.464586 | P34: =N34+P32*'Аналитика'!$J$12-C34 -> 55.537554 | Q34: =P34+Q32*'Аналитика'!$J$12-('Расчёты'!D34-'Расчёты'!C34) -> 56.63198 | R34: =Q34+R32*'Аналитика'!$J$12-('Расчёты'!E34-'Расчёты'!D34) -> 57.748295 | S34: =R34+S32*'Аналитика'!$J$12-('Расчёты'!F34-'Расчёты'!E34) -> 58.886936 | T34: =S34+T32*'Аналитика'!$J$12-('Расчёты'!G34-'Расчёты'!F34) -> 60.048351 | U34: =T34+U32*'Аналитика'!$J$12-('Расчёты'!H34-'Расчёты'!G34) -> 61.267836 | V34: =U34+V32*'Аналитика'!$J$12-('Расчёты'!I34-'Расчёты'!H34) -> 62.548295 | W34: =V34+W32*'Аналитика'!$J$12-('Расчёты'!J34-'Расчёты'!I34) -> 63.892777 | X34: =W34+X32*'Аналитика'!$J$12-('Расчёты'!K34-'Расчёты'!J34) -> 65.149929 | ... AA34: =Z34+AA32*'Аналитика'!$J$12-('Расчёты'!N34-'Расчёты'!M34) -> 69.074265 | AB34: =AA34 -> 69.074265
B35: Оплата курса 3 траншами | C35: =C32*'Аналитика'!J13 -> 6 | D35: =C35+D32*'Аналитика'!$J$13 -> 12.12 | E35: =D35+E32*'Аналитика'!$J$13 -> 18.3624 | F35: =E35+F32*'Аналитика'!$J$13 -> 24.729648 | G35: =F35+G32*'Аналитика'!$J$13 -> 31.224241 | H35: =G35+H32*'Аналитика'!$J$13 -> 38.043564 | I35: =H35+I32*'Аналитика'!$J$13 -> 45.203852 | J35: =I35+J32*'Аналитика'!$J$13 -> 52.722155 | K35: =J35+K32*'Аналитика'!$J$13 -> 59.752112 | ... N35: =M35+N32*'Аналитика'!$J$13 -> 81.69688 | O35: =N35 -> 81.69688 | P35: =N35+P32*'Аналитика'!$J$13-'Расчёты'!C35 -> 83.30633 | Q35: =P35+Q32*'Аналитика'!$J$13-('Расчёты'!D35-'Расчёты'!C35) -> 84.94797 | R35: =Q35+R32*'Аналитика'!$J$13-('Расчёты'!E35-'Расчёты'!D35) -> 86.622443 | S35: =R35+S32*'Аналитика'!$J$13-('Расчёты'!F35-'Расчёты'!E35) -> 88.330405 | T35: =S35+T32*'Аналитика'!$J$13-('Расчёты'!G35-'Расчёты'!F35) -> 90.072526 | U35: =T35+U32*'Аналитика'!$J$13-('Расчёты'!H35-'Расчёты'!G35) -> 91.901753 | V35: =U35+V32*'Аналитика'!$J$13-('Расчёты'!I35-'Расчёты'!H35) -> 93.822442 | W35: =V35+W32*'Аналитика'!$J$13-('Расчёты'!J35-'Расчёты'!I35) -> 95.839165 | X35: =W35+X32*'Аналитика'!$J$13-('Расчёты'!K35-'Расчёты'!J35) -> 97.724893 | ... AA35: =Z35+AA32*'Аналитика'!$J$13-('Расчёты'!N35-'Расчёты'!M35) -> 103.6114 | AB35: =AA35 -> 103.6114
B36: Оплата курса помесячно | C36: =C32*'Аналитика'!J14 -> 8 | D36: =C36+D32*'Аналитика'!$J$14 -> 16.16 | E36: =D36+E32*'Аналитика'!$J$14 -> 24.4832 | F36: =E36+F32*'Аналитика'!$J$14 -> 32.972864 | G36: =F36+G32*'Аналитика'!$J$14 -> 41.632321 | H36: =G36+H32*'Аналитика'!$J$14 -> 50.724751 | I36: =H36+I32*'Аналитика'!$J$14 -> 60.271803 | J36: =I36+J32*'Аналитика'!$J$14 -> 70.296207 | K36: =J36+K32*'Аналитика'!$J$14 -> 79.669482 | ... N36: =M36+N32*'Аналитика'!$J$14 -> 108.92917 | O36: =N36 -> 108.92917 | P36: =N36+P32*'Аналитика'!$J$14-C36 -> 111.07511 | Q36: =P36+Q32*'Аналитика'!$J$14-('Расчёты'!D36-'Расчёты'!C36) -> 113.26396 | R36: =Q36+R32*'Аналитика'!$J$14-('Расчёты'!E36-'Расчёты'!D36) -> 115.49659 | S36: =R36+S32*'Аналитика'!$J$14-('Расчёты'!F36-'Расчёты'!E36) -> 117.77387 | T36: =S36+T32*'Аналитика'!$J$14-('Расчёты'!G36-'Расчёты'!F36) -> 120.0967 | U36: =T36+U32*'Аналитика'!$J$14-('Расчёты'!H36-'Расчёты'!G36) -> 122.53567 | V36: =U36+V32*'Аналитика'!$J$14-('Расчёты'!I36-'Расчёты'!H36) -> 125.09659 | W36: =V36+W32*'Аналитика'!$J$14-('Расчёты'!J36-'Расчёты'!I36) -> 127.78555 | X36: =W36+X32*'Аналитика'!$J$14-('Расчёты'!K36-'Расчёты'!J36) -> 130.29986 | ... AA36: =Z36+AA32*'Аналитика'!$J$14-('Расчёты'!N36-'Расчёты'!M36) -> 138.14853 | AB36: =AA36 -> 138.14853
B38: Таблица 10.2. Стоимость подписки в мес., руб. | AF38: Нет | AG38: =IF(AF38="Нет", " ", "Для каждого вида оплаты нужно рассчитать месячную стоимость (например, стоимость пакета на 3 месяца нужно разделить на 3, а оплату курса 2 траншами - на 12)")
C39: янв.26 | D39: фев.26 | E39: мар.26 | F39: апр.26 | G39: 46143 | H39: июн.26 | I39: июл.26 | J39: авг.26 | K39: сент.26 | L39: окт.26 | M39: ноя.26 | N39: дек.26 | O39: 2026 | P39: янв.27 | Q39: фев.27 | R39: мар.27 | S39: апр.27 | T39: 46508 | U39: июн.27 | V39: июл.27 | W39: авг.27 | X39: сент.27 | Y39: окт.27 | Z39: ноя.27 | AA39: дек.27 | AB39: 2027
B41: Community
B42: Первый месяц | C42: 0 | D42: 0 | E42: 0 | F42: 0 | G42: 0 | H42: 0 | I42: 0 | J42: 0 | K42: 0 | L42: 0 | M42: 0 | N42: 0 | O42: 0 | P42: 0 | Q42: 0 | R42: 0 | S42: 0 | T42: 0 | U42: 0 | V42: 0 | W42: 0 | X42: 0 | Y42: 0 | Z42: 0 | AA42: 0 | AB42: =AA42 -> 0
B43: Подписка на месяц | C43: ='Аналитика'!C5 -> 300 | D43: 300 | E43: 300 | F43: 300 | G43: 300 | H43: 300 | I43: 300 | J43: 300 | K43: 300 | L43: 300 | M43: 300 | N43: 300 | O43: 300 | P43: 300 | Q43: 300 | R43: 300 | S43: 300 | T43: 300 | U43: 300 | V43: 300 | W43: 300 | X43: 300 | Y43: 300 | Z43: 300 | AA43: 300 | AB43: 300
B44: Пакет на 3 месяца | C44: ='Аналитика'!$C$6/3 -> 283.33333 | D44: 283.33333 | E44: 283.33333 | F44: 283.33333 | G44: 283.33333 | H44: 283.33333 | I44: 283.33333 | J44: 283.33333 | K44: 283.33333 | L44: 283.33333 | M44: 283.33333 | N44: 283.33333 | O44: 283.33333 | P44: 283.33333 | Q44: 283.33333 | R44: 283.33333 | S44: 283.33333 | T44: 283.33333 | U44: 283.33333 | V44: 283.33333 | W44: 283.33333 | X44: 283.33333 | Y44: 283.33333 | Z44: 283.33333 | AA44: 283.33333 | AB44: 283
B45: Пакет на 6 месяцев | C45: ='Аналитика'!$C$7/6 -> 266.66667 | D45: 266.66667 | E45: 266.66667 | F45: 266.66667 | G45: 266.66667 | H45: 266.66667 | I45: 266.66667 | J45: 266.66667 | K45: 266.66667 | L45: 266.66667 | M45: 266.66667 | N45: 266.66667 | O45: 266.66667 | P45: 266.66667 | Q45: 266.66667 | R45: 266.66667 | S45: 266.66667 | T45: 266.66667 | U45: 266.66667 | V45: 266.66667 | W45: 266.66667 | X45: 266.66667 | Y45: 266.66667 | Z45: 266.66667 | AA45: 266.66667 | AB45: 266.66667
B46: Пакет на 12 месяцев | C46: ='Аналитика'!$C$8/12 -> 250 | D46: 250 | E46: 250 | F46: 250 | G46: 250 | H46: 250 | I46: 250 | J46: 250 | K46: 250 | L46: 250 | M46: 250 | N46: 250 | O46: 250 | P46: 250 | Q46: 250 | R46: 250 | S46: 250 | T46: 250 | U46: 250 | V46: 250 | W46: 250 | X46: 250 | Y46: 250 | Z46: 250 | AA46: 250 | AB46: 250
B47: Education
...

Sheet Бюджет
B2: Таблица 17. Бюджет доходов и расходов 2026–2027, тыс. руб. | L2: Подсказку?
C3: Итого новые проекты | F3: Community | I3: Education
C4: 2026 | D4: 2027 | F4: 2026 | G4: 2027 | I4: 2026 | J4: 2027
B5: Выручка | C5: =F5+I5 -> 20483.248 | D5: =G5+J5 -> 51113.589 | F5: ='Расчёты'!O9 -> 4840.5369 | G5: ='Расчёты'!AB9 -> 16907.573 | I5: ='Расчёты'!O15 -> 15642.711 | J5: ='Расчёты'!AB15 -> 34206.016 | L5: Нет | M5: =IF(L5="Нет", " ", "Для Community и Education выручку заберите с листа Расчёты из таблицы 10. Выручка Итого рассчитывается путём сложения выручки Community и Education")
B6: Себестоимость | C6: =F6+I6 -> 27500 | D6: =G6+J6 -> 39124.04 | F6: ='Расчёты'!O57+'Расчёты'!O63+'Расчёты'!O172+'Расчёты'!O179 -> 10898 | G6: ='Расчёты'!AB57+'Расчёты'!AB63+'Расчёты'!AB172+'Расчёты'!AB179 -> 11414.24 | I6: ='Расчёты'!O58+'Расчёты'!O69+'Расчёты'!O173+'Расчёты'!O184 -> 16602 | J6: ='Расчёты'!AB58+'Расчёты'!AB69+'Расчёты'!AB173+'Расчёты'!AB184 -> 27709.8 | L6: Нет | M6: =IF(L6="Нет", " ", "Для Community и Education в себестоимость заберите расходы на аутсорс-разработку под ключ (таб.11), расходы на поддерж.персонал (таб.12), расходы на оборуд. (таб.15) и расходы на софт (таб.16) с листа Расчёты. Итого = Community + Education")
B7: Валовая прибыль | C7: =C5-C6 -> -7016.7521 | D7: =D5-D6 -> 11989.549 | F7: =F5-F6 -> -6057.4631 | G7: =G5-G6 -> 5493.3332 | I7: =I5-I6 -> -959.289 | J7: =J5-J6 -> 6496.216 | L7: Нет | M7: =IF(L7="Нет", " ", "Показатель рассчитывается по формуле Выручка - Себестоимость")
B8: Валовая прибыль, % | C8: =C7/C5 -> -0.34256052 | D8: =D7/D5 -> 0.23456676 | F8: =F7/F5 -> -1.2514032 | G8: =G7/G5 -> 0.3249037 | I8: =I7/I5 -> -0.061324984 | J8: =J7/J5 -> 0.18991443 | L8: Нет | M8: =IF(L8="Нет", " ", "Показатель рассчитывается по формуле Валовая прибыль / Выручка")
B9: Операционные расходы | C9: =SUM(C10:C14) -> 8974.13 | D9: =SUM(D10:D14) -> 9695.0776 | F9: =SUM(F10:F14) -> 3744.98 | G9: =SUM(G10:G14) -> 4004.6624 | I9: =SUM(I10:I14) -> 3802.02 | J9: =SUM(J10:J14) -> 4167.618 | L9: Нет | M9: =IF(L9="Нет", " ", "Показатель рассчитывается по формуле Расходы на персонал + Аренда + Реклама и маркетинг + Оборудование и сфот + Прочие и непредвиденные расходы")
B10: Расходы на персонал | C10: ='Расчёты'!O74 -> 648 | D10: ='Расчёты'!AB74 -> 697.92 | F10: 0 | G10: 0 | I10: 0 | J10: 0 | L10: Нет | M10: =IF(L10="Нет", " ", "Для Community и Education расходов на персонал в опер.расходах нет, т.к.они все в себестоимости. В Расходы на персонал Итого заберите расходы на бухгалтера из таблицы 12 с листа Расчёты")
B11: Аренда | C11: ='Расчёты'!O160+'Расчёты'!O161 -> 675 | D11: ='Расчёты'!AB160+'Расчёты'!AB161 -> 717 | F11: 0 | G11: 0 | I11: 0 | J11: 0 | L11: Нет | M11: =IF(L11="Нет", " ", "Расходы на аренду не распределены на Community и Education. Поэтому все расходы на аренду из таблицы 13 с листа Расчёты заберите в Расходы на аренду Итого ")
B12: Реклама и маркетинг | C12: =F12+I12 -> 7200 | D12: =G12+J12 -> 7704 | F12: ='Расчёты'!O166 -> 3600 | G12: ='Расчёты'!AB166 -> 3852 | I12: ='Расчёты'!O167 -> 3600 | J12: ='Расчёты'!AB167 -> 3852 | L12: Нет | M12: =IF(L12="Нет", " ", "Для Community и Education расходы на рекламу заберите с листа Расчёты из таблицы 14. Расходы на рекламу и маркетинг Итого рассчитывается путём сложения расходов на рекламу и маркетинг Community и Education")
B13: Оборудование, лицензии и ПО | C13: ='Расчёты'!O174+'Расчёты'!O189 -> 90 | D13: ='Расчёты'!AB174+'Расчёты'!AB189 -> 92.8 | F13: 0 | G13: 0 | I13: 0 | J13: 0 | L13: Нет | M13: =IF(L13="Нет", " ", "Расходы включают в себя расходы Бухгалтерии, указанные в таблицах 15 и 16. Расходы Community и Education должны быть отражены в себестоимости.")
B14: Прочие и непредвиденные расходы | C14: =(C6+C10+C11+C12+C13)*1% -> 361.13 | D14: =(D6+D10+D11+D12+D13)*1% -> 483.3576 | F14: =(F6+F10+F11+F12+F13)*1% -> 144.98 | G14: =(G6+G10+G11+G12+G13)*1% -> 152.6624 | I14: =(I6+I10+I11+I12+I13)*1% -> 202.02 | J14: =(J6+J10+J11+J12+J13)*1% -> 315.618 | L14: Нет | M14: =IF(L14="Нет", " ", "Показатель рассчитывается по формуле (Себестоимость + Расходы на персонал + Аренда + Реклама и маркетинг + Оборудование и софт) * 1%")
B15: Операционная прибыль | C15: =C7-C9 -> -15990.882 | D15: =D7-D9 -> 2294.4715 | F15: =F7-F9 -> -9802.4431 | G15: =G7-G9 -> 1488.6708 | I15: =I7-I9 -> -4761.309 | J15: =J7-J9 -> 2328.598 | L15: Нет | M15: =IF(L15="Нет", " ", "Показатель рассчитывается по формуле Валовая прибыль - Операционные расходы")
B16: Операционная прибыль, % | C16: =C15/C5 -> -0.78068099 | D16: =D15/D5 -> 0.044889658 | F16: =F15/F5 -> -2.0250735 | G16: =G15/G5 -> 0.088047572 | I16: =I15/I5 -> -0.30437876 | J16: =J15/J5 -> 0.068075685 | L16: Нет | M16: =IF(L16="Нет", " ", "Показатель рассчитывается по формуле Операционная прибыль / Выручка")
B17: Налог на прибыль | D17: =D15*25% -> 573.61788 | F17: 0 | G17: 0 | I17: 0 | J17: 0 | L17: Нет | M17: =IF(L17="Нет", " ", "Для Community и Education показатель не рассчитывается. Налог Итого рассчитывается по формуле Операционная прибыль * 25%")
B18: Чистая прибыль | C18: =C15-C17 -> -15990.882 | D18: =D15-D17 -> 1720.8536 | F18: =F15-F17 -> -9802.4431 | G18: =G15-G17 -> 1488.6708 | I18: =I15-I17 -> -4761.309 | J18: =J15-J17 -> 2328.598 | L18: Нет | M18: =IF(L18="Нет", " ", "Показатель рассчитывается по формуле Операционная прибыль - Налог на прибыль")
B19: Чистая прибыль, % | C19: =C18/C5 -> -0.78068099 | D19: =D18/D5 -> 0.033667243 | F19: =F18/F5 -> -2.0250735 | G19: =G18/G5 -> 0.088047572 | I19: =I18/I5 -> -0.30437876 | J19: =J18/J5 -> 0.068075685 | L19: Нет | M19: =IF(L19="Нет", " ", "Показатель рассчитывается по формуле Чистая прибыль / Выручка")

Sheet Последовательность расчётов
B2: Последовательность расчётов
C3: Лист «Расчёты»
B4: [1] | C4: Рассчитать ожидаемое количество пользователей — таблица 10.1
B5: [2] | C5: Рассчитать стоимость подписки — таблица 10.2
B6: [3] | C6: Рассчитать выручку — таблица 10
B7: [4] | C7: Рассчитать расходы на аутсорс-разработку «под ключ» — таблица 11
B8: [5] | C8: Рассчитать оклады штатных единиц — таблица 12.1
B9: [6] | C9: Рассчитать количество штатных единиц — таблица 12.2
B10: [7] | C10: Рассчитать ДМС - таблица 12.3
B11: [8] | C11: Рассчитать отпускные - таблица 12.4
B12: [9] | C12: Рассчитать страховые взносы - таблица 12.5
B13: [10] | C13: Рассчитать расходы на поддерживающий персонал — таблица 12
B14: [11] | C14: Рассчитать расходы на аренду — таблица 13
B15: [12] | C15: Рассчитать расходы на маркетинг и рекламу — таблица 14
... B17: [14] | C17: Рассчитать расходы на лицензии и софт — таблица 16
C18: Лист «Бюджет»
B19: [15] | C19: Заполнить последовательно все показатели БДР — таблица 17
C20: Лист «Цели»
B21: [16] | C21: Заполнить последовательно все финансовые показатели — таблица 1

Sheet Решение
A1: Таблица 1: Отчёт о прибылях и убытках за год, тыс.руб. | E1: Таблица 2: Управленческий баланс, тыс.руб. | I1: Показатель | J1: Значение | K1: Значение | L1: Вывод | M1: Формула
B2: 2023 | C2: 2022 | F2: 31.12.23 | G2: 31.12.22 | J2: 2023 | K2: 2022
A3: Выручка | B3: 1.8798537e+08 | C3: 85447896 | E3: АКТИВЫ | F3: 39722350 | G3: 20510095 | I3: Показатели рентабельности
A4: реклама | B4: 56395611 | C4: 25634369 | E4: Внеоборотные активы: | F4: 11975600 | G4: 7998000 | I4: Рентабельность продаж по валовой прибыли | J4: =B11/B3 -> 0.53 | K4: =C11/C3 -> 0.56 | L4: Показатели рентабельности Kihi в 2023 году немного снизились по сравнению с 2022 годом. Однако сохраняются на достаточно хоршем уровне. | M4: Валовая прибыль / Выручка * 100%
A5: внутриигровые транзакции | B5: 28197806 | C5: 12817184 | E5: Основные средства | F5: 3592680 | G5: 3199200 | I5: Рентабельность продаж по EBITDA | J5: =B18/B3 -> 0.23 | K5: =C18/C3 -> 0.26 | M5: EBITDA / Выручка * 100%
A6: процент с продаж | B6: 37597074 | C6: 17089579 | E6: Нематериальные активы | F6: 8382920 | G6: 4798800 | I6: Рентабельность продаж по чистой прибыли | J6: =B20/B3 -> 0.184 | K6: =C20/C3 -> 0.208 | M6: Чистая прибыль / Выручка * 100%
A7: разработка под ключ | B7: 65794880 | C7: 29906764 | E7: Долгосрочные финансовые вложения | F7: 0 | G7: 0 | I7: Рентабельность затрат (ROCS) | J7: =B20/B12 -> 0.61333333 | K7: =C20/C12 -> 0.69333333 | M7: Чистая прибыль / Расходы * 100%
A8: Себестоимость | B8: 88353124 | C8: 37597074 | I8: Рентабельность собственного капитала (ROE) | J8: =B20/F17 -> 1.3127793 | K8: =C20/G17 -> 1.2057703 | L8: Рентабельность капитала выросла - это хорошо, доходность бизнеса растёт. | M8: Чистая прибыль / Собственный капитал
A9: разработка | B9: 88176418 | C9: 37521880 | E9: Оборотные активы: | F9: 27746750 | G9: 12512095 | I9: Рентабельность активов (ROA) | J9: =B20/F3 -> 0.870777 | K9: =C20/G3 -> 0.8665568 | L9: Рентабельность активов растёт - отлично, значит, Kihi эффективно использует ресурсы в своих процессах. | M9: Чистая прибыль / Стоимость активов * 100%
A10: комиссии плаёжных систем | B10: 176706.25 | C10: 75194.148 | E10: Запасы | F10: 1181166.8 | G10: 536894 | I10: Показатели деловой активности
A11: Валовая прибыль (маржинальный доход) | B11: 99632247 | C11: 47850822 | E11: Дебиторская задолженность | F11: 3352800 | G11: 1524000 | I11: Оборачиваемость кредиторской задолженности | J11: =(((G25+F25)/2)/B8)*365 -> 23.086968 | L11: В среднем Kihi оплачивал счета поставщикам через 23 дня | M11: (Среднее арифметическое значение кредиторской задолженности / Себестоимость продукции в августе) * Количество дней в периоде
A12: Операционные расходы | B12: 56395611 | C12: 25634369 | E12: Краткосрочные финансовые вложения | F12: 14563560 | G12: 6619800 | I12: Оборачиваемость запасов | J12: =(((G10+F10)/2)/B8)*365 -> 3.5487833 | L12: В среднем в 2023 году запасы в Kihi обновлялись каждые 4 дня | M12: (Среднее арифметическое значение запасов / Себестоимость) * Количество дней в периоде
A13: Расходы на персонал | B13: 20040095 | C13: 8527700 | E13: Авансы выданные | F13: 3586000 | G13: 1630000 | I13: Показатели ликвидности и платежеспособности
A14: Аренда | B14: 3383736.7 | C14: 1538062.1 | E14: Денежные средства | F14: 5063222.8 | G14: 2201401.2 | I14: Коэффициент текущей ликвидности | J14: =F9/F25 -> 3.6961108 | K14: =G9/G25 -> 3.409285 | L14: Показатель больше 2 - это говорит о том, что текущие обязательства обеспечены оборотными активами в достаточной мере | M14: Оборотные активы / Краткосрочные обязательства
A15: Реклама и маркетинг | B15: 29889674 | C15: 14098903 | I15: Коэффициент срочной ликвидности | J15: =(F9-F10)/F25 -> 3.538769 | K15: =(G9-G10)/G25 -> 3.2629926 | L15: Показатель больше 1, значит в ближайшей перспективе при любых обстоятельствах компания способна расплатиться по своим долгам | M15: (Денежные Средства + Финансовые вложения + Дебиторская задолженность) / Краткосрочные обязательства
A16: Оборудование и софт | B16: 2255824.5 | C16: 1025374.8 | E16: ПАССИВЫ | F16: 33855165 | G16: 18410095 | I16: Коэффициент мгновенной ликвидности | J16: =F14/F25 -> 0.67446576 | K16: =G14/G25 -> 0.59983592 | L16: Показатель больше 0.2 - это хороший показатель, говорит о том, что компания может погасить большую часть долгов прямо сейчас | M16: Денежные средства / Краткосрочные обязательства
A17: Прочие расходы | B17: 826281.15 | C17: 444329.06 | E17: Капитал и резервы | F17: 26348152 | G17: 14740090 | I17: Показатели финансовой устойчивости компании
A18: EBITDA | B18: 43236635 | C18: 22216453 | E18: Уставный капитал | F18: 132000 | G18: 60000 | I18: Коэффициент финансовой независимости | J18: =F17/F3 -> 0.663308 | K18: =G17/G3 -> 0.71867485 | L18: Показатель больше 0.6 - это хорошо, компания не особо зависит от сторонних кредитов | M18: Собственный Капитал / Активы
A19: Налог на прибыль | B19: 8647327.1 | C19: 4443290.6 | E19: Резервный капитал | F19: 5544000 | G19: 2520000 | I19: Коэффициент финансовой устойчивости | J19: =(F17+F22)/F3 -> 0.663308 | K19: =(G17+G22)/G3 -> 0.71867485 | L19: Показатель говорит о том, что большая часть активов компании сформирована за счёт долгосрочных источников финансирования, а это хорошо. | M19: (Собственный Капитал + Долгосрочные Обязательства) / Активы
A20: Чистая прибыль | B20: 34589308 | C20: 17773162 | E20: Нераспределенная прибыль | F20: 20672152 | G20: 12160090 | I20: Коэффициент обеспеченности собственными оборотными средствами | J20: =(F9-F25)/F9 -> 0.72944534 | K20: =(G9-G25)/G9 -> 0.70668337 | L20: Показатель больше 0.1 - это хорошо. У Kihi достаточно собственных оборотных средств, необходимых для финансовой устойчивости. | M20: (Оборотные активы – Краткосрочные обязательства) / Оборотные активы
I21: Коэффициент маневренности собственного капитала | J21: =(F9-F25)/F17 -> 0.76816533 | K21: =(G9-G25)/G17 -> 0.59986675 | L21: Показатель больше 0.2 - хороший результат, большая часть собственного капитала используется для финансирования текущей деятельности | M21: (Оборотные активы – Краткосрочные обязательства) / Собственный Капитал
E22: Долгосрочные обязательства | F22: 0 | G22: 0 | I22: Общий вывод
E23: Долгосрочные кредиты и займы | F23: 0 | G23: 0 | I23: В целом у Kihi отличные показатели рентабельности, деловой активности, ликвидности, платежеспособности и финансовой устойчивости. Всё говорит о том, что бизнес развивается и готов к расширению.
E25: Краткосрочные обязательства | F25: 7507012.3 | G25: 3670005.6
E26: Кредиторская задолженность по расчётам с бюджетом | F26: 1837012.3 | G26: 835005.6
E27: Кредиторская задолженность по расчётам с персоналом | F27: 5670000 | G27: 2835000
